Workbook
Name ActualNumberOfPayments: IFERROR(IF('HOA Savings'!LoanIsGood,IF('HOA Savings'!PaymentsPerYear=1,1,MATCH(0.01,'HOA Savings'!End_Bal,-1)+1)),"")
Name ActualNumberOfPayments: IFERROR(IF(LoanIsGood,IF(PaymentsPerYear=1,1,MATCH(0.01,End_Bal,-1)+1)),"")
Name ColumnTitle1: #REF!
Name End_Bal: #REF!
Name ExtraPayments: #REF!
Name InterestRate: #REF!
Name IQ_CH: 110000
Name IQ_CQ: 5000
Name IQ_CY: 10000
Name IQ_DAILY: 500000
Name IQ_FH: 100000
Name IQ_FQ: 500
Name IQ_FY: 1000
Name IQ_LTM: 2000
Name IQ_MONTH: 15000
Name IQ_NTM: 6000
Name IQ_WEEK: 50000
Name IQ_YTD: 3000
Name LastCol: MATCH(REPT("z",255),#REF!)
Name LastRow: MATCH(9.99E+307,#REF!)
Name LenderName: #REF!
Name LoanAmount: #REF!
Name LoanIsGood: (#REF!*#REF!*#REF!*#REF!)>0
Name LoanPeriod: #REF!
Name LoanStartDate: #REF!
Name PaymentsPerYear: #REF!
Name PrintArea_SET: OFFSET(#REF!,,,'HOA Savings'!LastRow,'HOA Savings'!LastCol)
Name roundOpt: #REF!
Name RowTitleRegion1..E9: #REF!
Name RowTitleRegion2..I7: #REF!
Name RowTitleRegion3..E9: #REF!
Name RowTitleRegion4..H9: #REF!
Name ScheduledNumberOfPayments: #REF!
Name ScheduledPayment: #REF!
Name TotalEarlyPayments: SUM(#REF!)
Name TotalInterest: SUM(#REF!)
Name valuevx: 42.314159

Sheet Dashboard
B2: Jon Kemp Budget Dashboard
B4: INCOME
B5: Income Source | C5: Gross (Per Pay) | D5: Net (Per Pay) | E5: Pay Date | F5: Monthly Gross | G5: Monthly Net
B6: Bi-Weekly #1 - Regular Pay | E6: 15th | F6: =C6 -> 0 | G6: =D6 -> 0
B7: Bi-Weekly #2 - Income | E7: Last Day | F7: =C7 -> 0 | G7: =D7 -> 0
B8: TOTAL MONTHLY INCOME | F8: =SUM(F6:F7) -> 0 | G8: =SUM(G6:G7) -> 0
B10: Expense/Income Item | C10: Base Value | D10: Period | E10: Monthly Amount | F10: Account | G10: Payment Day
B11: BILLS CHECKING EXPENSES | I11: Expenses by Account
B12: Cell Phone Service | D12: Monthly | E12: =C12 -> 0 | F12: USAA Bills Checking | I12: Bills Checking | J12: =E15 -> 0
B13: Gym Membership | D13: Monthly | E13: =C13/2 -> 0 | F13: USAA Bills Checking | I13: Mortgage Checking | J13: =E25 -> 0
B14: Vehicle Insurance | D14: Semi-Annual | E14: =C14/6 -> 0 | F14: USAA Bills Checking | I14: HOA Savings | J14: =E31 -> 0
B15: Bills Checking Subtotal | E15: =SUM(E12:E14) -> 0
I16: Per Paycheck Allocation (Jon)
B17: MORTGAGE CHECKING EXPENSES | I17: Bills Checking | J17: =D37 -> 0
B18: Mortgage - Regular Payment | D18: Monthly | E18: =C18 -> 0 | F18: USAA Mortgage Checking | I18: Mortgage Checking | J18: =D38 -> 0
B19: Mortgage - Extra Payment | D19: Monthly | E19: =C19 -> 0 | F19: USAA Mortgage Checking | I19: HOA Savings | J19: =D39 -> 0
B20: YouTube TV (Zack) | D20: Monthly | E20: =C20 -> 0 | F20: USAA Mortgage Checking
B21: Water/Sewer | D21: Monthly | E21: =C21 -> 0 | F21: USAA Mortgage Checking
B22: Georgia Power - Electricity | D22: Monthly | E22: =C22 -> 0 | F22: USAA Mortgage Checking
B23: Natural Gas | D23: Monthly | E23: =C23 -> 0 | F23: USAA Mortgage Checking
B24: Comcast Cable | D24: Monthly | E24: =C24 -> 0 | F24: USAA Mortgage Checking
B25: Mortgage Checking Subtotal | E25: =SUM(E18:E24) -> 0
B27: HOA SAVINGS EXPENSES
B28: HOA Semi-Annual Assessment | D28: Semi-Annual | E28: =C28/6 -> 0 | F28: USAA HOA Savings | G28: N/A
B29: HOA Payment Fee | D29: Semi-Annual | E29: =C29/6 -> 0 | F29: USAA HOA Savings | G29: N/A
B30: HOA - Extra Payments | D30: Monthly | E30: =C30 -> 0 | F30: USAA HOA Savings
B31: HOA Savings Subtotal | E31: =SUM(E28:E30) -> 0
B33: TOTAL MONTHLY EXPENSES | E33: =E15+E25+E31 -> 0
B35: ACCOUNT SUMMARY
B36: Account | C36: Monthly Expenses | D36: Per Paycheck (Jon) | E36: Ronnie Monthly | F36: Jon Monthly | G36: Notes
B37: USAA Bills Checking - 7071 | C37: =E15 -> 0 | D37: =C37/2 -> 0 | F37: =C37 -> 0 | G37: Personal expenses
B38: USAA Mortgage Checking - 3223 | C38: =E25 -> 0 | D38: =F38/2 -> 0 | E38: =C38/2 -> 0 | F38: =C38/2 -> 0 | G38: Split 50/50
B39: USAA HOA Savings - 9575 | C39: =E31 -> 0 | D39: =F39/2 -> 0 | E39: =C39/2 -> 0 | F39: =C39/2 -> 0 | G39: Split 50/50
B40: TOTALS | C40: =SUM(C37:C39) -> 0 | D40: =SUM(D37:D39) -> 0 | E40: =SUM(E37:E39) -> 0 | F40: =SUM(F37:F39) -> 0
B42: KEY METRICS & INSIGHTS
B44: Monthly Savings Rate | C44: Net Monthly Cash Flow | D44: Total Cash on Hand
B45: =(G8-E33)/G8 -> #DIV/0! | C45: =G8-E33 -> 0 | D45: =C52 -> 457.5
B47: Current Account Balances (Live) | F47: Next 5 Upcoming Payments
B48: Account | C48: Balance Today | D48: As Of | F48: Bill | G48: Amount | H48: Days Until Due
B49: USAA Bills Checking - 7071 | C49: =_xlfn.XLOOKUP(TODAY(),'Bills Checking'!A:A,'Bills Checking'!J:J,"N/A",0) -> 257.5 | D49: =TODAY() -> 46232 | F49: {=_xlfn.LET(_xlpm.items, _xlfn._xlws.FILTER(B12:B32, ISNUMBER(G12:G32)), _xlpm.amt, _xlfn._xlws.FILTER(E12:E32, ISNUMBER(G12:G32)), _xlpm.pday, _xlfn._xlws.FILTER(G12:G32, ISNUMBER(G12:G32)), _xlpm.nextd, IF(DAY(TODAY())<=_xlpm.pday, DATE(YEAR(TODAY()),MONTH(TODAY()),_xlpm.pday), DATE(YEAR(TODAY()),MONTH(TODAY())+1,_xlpm.pday)), _xlpm.dleft, _xlpm.nextd-TODAY(), _xlpm.srt, _xlfn._xlws.SORT(_xlfn.HSTACK(_xlpm.items,_xlpm.amt,_xlpm.dleft),3,1), _xlfn.TAKE(_xlpm.srt,5))} -> #VALUE!
...

Sheet Main Budget
B1: Jon Kemp Personal Budget Plan: Bi-weekly
B4: INCOME
B5: Income Source | C5: Gross (Per Pay) | D5: Net (Per Pay) | E5: Pay Date | F5: Monthly Gross | G5: Monthly Net
B6: Bi-Weekly #1 | E6: 15th
B7: Bi-Weekly #2 | E7: Last Day
B8: TOTAL MONTHLY INCOME | F8: =SUM(F6:F7) -> 0 | G8: =SUM(G6:G7) -> 0
B10: BILLS CHECKING EXPENSES
B11: Bill Name | G11: Monthly | H11: Per Pay Check | I11: Account | J11: Payment Date | K11: Payment Source | L11: Notes
B12: Cell Phone Service | G12: =-Dashboard!C12 -> 0 | H12: =G12/2 -> 0 | I12: USAA Bills | K12: Wells Fargo Credit | L12: Auto Pay set for 17th of each month.
B13: Gym Membership | G13: =-Dashboard!E13 -> 0 | H13: =G13/2 -> 0 | I13: USAA Bills | K13: Bank of America VISA | L13: Auto Pay set for 18th of each month.
B14: Insurance (Vehicle) | G14: =-Dashboard!E14 -> 0 | H14: =G14/2 -> 0 | I14: USAA Bills
B15: Bills Checking Subtotal | G15: =SUM(G12:G14) -> 0 | H15: =SUM(H12:H14) -> 0
B17: HOA SAVINGS EXPENSES
B18: Bill Name | E18: Monthly | F18: Ronnie Portion | G18: Jon Portion | H18: Jon Per Pay Check | I18: Account | J18: Payment Date | K18: Payment Source | L18: Notes
B19: HOA Semi-Annual Dues | E19: =-Dashboard!E28-Dashboard!E29 -> 0 | F19: =E19/2 -> 0 | G19: =E19/2 -> 0 | H19: =G19/2 -> 0 | I19: USAA HOA Savings | J19: N/A
B20: HOA - Extra Payments | E20: =-Dashboard!E30 -> 0 | F20: =E20/2 -> 0 | G20: =E20/2 -> 0 | H20: =G20/2 -> 0 | I20: USAA HOA Savings
B21: HOA Savings Subtotal | E21: =SUM(E19:E20) -> 0 | F21: =SUM(F19:F20) -> 0 | G21: =SUM(G19:G20) -> 0
B23: MORTGAGE CHECKING EXPENSES
B24: Bill Name | E24: Monthly | F24: Ronnie Portion | G24: Jon Portion | H24: Jon Per Pay Check | I24: Account | J24: Payment Date | K24: Payment Source | L24: Notes
B25: Mortgage - Extra Payment | E25: =-Dashboard!E19 -> 0 | F25: =E25/2 -> 0 | G25: =E25/2 -> 0 | H25: =G25/2 -> 0 | I25: USAA Mortgage
B26: Mortgage - Regular Payment | E26: =-Dashboard!E18 -> 0 | F26: =E26/2 -> 0 | G26: =E26/2 -> 0 | H26: =G26/2 -> 0 | I26: USAA Mortgage | K26: Auto Pay Mortgage Checking
B27: Youtube TV Zack | E27: =-Dashboard!E20 -> 0 | F27: =E27/2 -> 0 | G27: =E27/2 -> 0 | H27: =G27/2 -> 0 | I27: USAA Mortgage | K27: Mortgage Checking | L27: Pay via ZELLE to Zack
B28: Water/Sewer | E28: =-Dashboard!E21 -> 0 | F28: =E28/2 -> 0 | G28: =E28/2 -> 0 | H28: =G28/2 -> 0 | I28: USAA Mortgage | K28: Mortgage Checking | L28: Auto Pay From Checking
B29: Georgia Power - Electricity | E29: =-Dashboard!E22 -> 0 | F29: =E29/2 -> 0 | G29: =E29/2 -> 0 | H29: =G29/2 -> 0 | I29: USAA Mortgage | K29: Mortgage Checking | L29: Auto Pay From Checking
B30: Natural Gas | E30: =-Dashboard!E23 -> 0 | F30: =E30/2 -> 0 | G30: =E30/2 -> 0 | H30: =G30/2 -> 0 | I30: USAA Mortgage | K30: Mortgage Checking | L30: Auto Pay From Checking
B31: Comcast Cable | E31: =-Dashboard!E24 -> 0 | F31: =E31/2 -> 0 | G31: =E31/2 -> 0 | H31: =G31/2 -> 0 | I31: USAA Mortgage | K31: Mortgage Checking | L31: Auto Pay From Checking
B32: Mortgage Checking Subtotal | E32: =SUM(E25:E31) -> 0 | F32: =SUM(F25:F31) -> 0 | G32: =SUM(G25:G31) -> 0 | H32: =SUM(H25:H31) -> 0
B34: TOTAL EXPENSES | E34: Monthly | F34: Ronnie Portion | G34: Jon Portion | H34: Jon Per Pay Check
E35: =E21+E32+G15 -> 0 | F35: =F21+F32 -> 0 | G35: =G21+G32+G15 -> 0 | H35: =G35/2 -> 0
F38: Ronnie Portion (Monthly) | G38: Jon Portion (Per Paycheck) | H38: Current Regular Balance | I38: Extra Balance | J38: Total Current Balance | K38: Status
B39: Amount To USAA Bill Checking - 7071 | F39: =0 -> 0 | G39: =Dashboard!D37 -> 0 | H39: =VLOOKUP(TODAY(),'Bills Checking'!A1:J709,10,FALSE) -> 257.5 | J39: =H39+I39 -> 257.5 | K39: =IF(J39<0,"⚠️ NEGATIVE",IF(J39<500,"⚠️ LOW","✅ OK")) -> ⚠️ LOW
B40: Amount to USAA Mortgage Checking - 3223 | F40: =Dashboard!E38 -> 0 | G40: =Dashboard!D38 -> 0 | H40: =VLOOKUP(TODAY(),'Mortgage Checking'!A1:Q1374,15,FALSE) -> 100 | I40: =VLOOKUP(TODAY(),'Mortgage Checking'!A1:Q1374,16,FALSE) -> 100 | J40: =H40+I40 -> 200 | K40: =IF(J40<0,"⚠️ NEGATIVE",IF(J40<500,"⚠️ LOW","✅ OK")) -> ⚠️ LOW
B41: Amount To USAA HOA Savings - 9575 | F41: =Dashboard!E39 -> 0 | G41: =Dashboard!D39 -> 0 | H41: =VLOOKUP(TODAY(),'HOA Savings'!A1:M101,11,FALSE) -> #N/A | I41: =VLOOKUP(TODAY(),'HOA Savings'!A1:P101,12,FALSE) -> #N/A | J41: =H41+I41 -> #N/A | K41: =IF(J41<0,"⚠️ NEGATIVE",IF(J41<500,"⚠️ LOW","✅ OK")) -> #N/A
B42: TOTAL ALL ACCOUNTS | J42: =SUM(J39:J41) -> #N/A | K42: =IF(J42<0,"⚠️ NEGATIVE",IF(J42<1500,"⚠️ LOW","✅ OK")) -> #N/A

Sheet Mortgage Checking
A1: Date | B1: Beg Balance | C1: Extra Beg Balance | D1: Jon Credit | E1: Ronnie Credit | F1: Jon Extra Credit | G1: Ronnie Extra Credit | H1: Mortgage | I1: Water (GA Utility) | J1: Electric: Georgia Power | K1: Natural Gas (Energy Inc Geo) | L1: Comcast (AutoPay Checking) | M1: YouTube TV (Zelle to Zack) | N1: Other | O1: Regular Ending Balance | P1: Extra Ending Balance | Q1: Total End Balance | T1: Other Description | U1: Costco Furniture Payback | V1: Actual End Balance
A2: 46023 | B2: 100 | C2: 100 | D2: =IF(OR(DAY(A2+2)=1,DAY(A2+2)=15),-SUM('Main Budget'!$H$26:$H$31),0) -> 0 | E2: =IF(DAY(A2+2)=22,-SUM('Main Budget'!$F$26:$F$31),0) -> 0 | F2: =IF(D2>0,-'Main Budget'!$H$25+0.15,0) -> 0 | G2: =IF(E2>0,-'Main Budget'!$F$25+0.81,0) -> 0 | H2: =IF(DAY(A2)='Main Budget'!$J$26,'Main Budget'!$E$26,0) -> 0 | I2: =IF(DAY(A2)='Main Budget'!$J$28,'Main Budget'!$E$28,0) -> 0 | J2: =IF(DAY(A2)='Main Budget'!$J$29,'Main Budget'!$E$29,0) -> 0 | K2: =IF(DAY(A2)='Main Budget'!$J$30,'Main Budget'!$E$30,0) -> 0 | L2: =IF(DAY(A2)='Main Budget'!$J$31,'Main Budget'!$E$31,0) -> 0 | M2: =IF(DAY(A2)='Main Budget'!$J$27,'Main Budget'!$E$27,0) -> 0 | O2: =B2+(SUM(H2:M2)+(SUM(D2:E2))) -> 100 | P2: =C2+F2+G2+N2 -> 100 | Q2: =O2+P2 -> 200 | S2: =TEXT(A2,"dddd") -> Thursday
A3: 46024 | B3: =O2 -> 100 | C3: =P2 -> 100 | D3: =IF(OR(DAY(A3+2)=1,DAY(A3+2)=15),-SUM('Main Budget'!$H$26:$H$31),0) -> 0 | E3: =IF(DAY(A3+2)=22,-SUM('Main Budget'!$F$26:$F$31),0) -> 0 | F3: =IF(D3>0,-'Main Budget'!$H$25+0.15,0) -> 0 | G3: =IF(E3>0,-'Main Budget'!$F$25+0.81,0) -> 0 | H3: =IF(DAY(A3)='Main Budget'!$J$26,'Main Budget'!$E$26,0) -> 0 | I3: =IF(DAY(A3)='Main Budget'!$J$28,'Main Budget'!$E$28,0) -> 0 | J3: =IF(DAY(A3)='Main Budget'!$J$29,'Main Budget'!$E$29,0) -> 0 | K3: =IF(DAY(A3)='Main Budget'!$J$30,'Main Budget'!$E$30,0) -> 0 | L3: =IF(DAY(A3)='Main Budget'!$J$31,'Main Budget'!$E$31,0) -> 0 | M3: =IF(DAY(A3)='Main Budget'!$J$27,'Main Budget'!$E$27,0) -> 0 | O3: =B3+(SUM(H3:M3)+(SUM(D3:E3))) -> 100 | P3: =C3+F3+G3+N3 -> 100 | Q3: =O3+P3 -> 200 | S3: =TEXT(A3,"dddd") -> Friday
A4: 46025 | B4: =O3 -> 100 | C4: =P3 -> 100 | D4: =IF(OR(DAY(A4+2)=1,DAY(A4+2)=15),-SUM('Main Budget'!$H$26:$H$31),0) -> 0 | E4: =IF(DAY(A4+2)=22,-SUM('Main Budget'!$F$26:$F$31),0) -> 0 | F4: =IF(D4>0,-'Main Budget'!$H$25+0.15,0) -> 0 | G4: =IF(E4>0,-'Main Budget'!$F$25+0.81,0) -> 0 | H4: =IF(DAY(A4)='Main Budget'!$J$26,'Main Budget'!$E$26,0) -> 0 | I4: =IF(DAY(A4)='Main Budget'!$J$28,'Main Budget'!$E$28,0) -> 0 | J4: =IF(DAY(A4)='Main Budget'!$J$29,'Main Budget'!$E$29,0) -> 0 | K4: =IF(DAY(A4)='Main Budget'!$J$30,'Main Budget'!$E$30,0) -> 0 | L4: =IF(DAY(A4)='Main Budget'!$J$31,'Main Budget'!$E$31,0) -> 0 | M4: =IF(DAY(A4)='Main Budget'!$J$27,'Main Budget'!$E$27,0) -> 0 | O4: =B4+(SUM(H4:M4)+(SUM(D4:E4))) -> 100 | P4: =C4+F4+G4+N4 -> 100 | Q4: =O4+P4 -> 200 | S4: =TEXT(A4,"dddd") -> Saturday
A5: 46026 | B5: =O4 -> 100 | C5: =P4 -> 100 | D5: =IF(OR(DAY(A5+2)=1,DAY(A5+2)=15),-SUM('Main Budget'!$H$26:$H$31),0) -> 0 | E5: =IF(DAY(A5+2)=22,-SUM('Main Budget'!$F$26:$F$31),0) -> 0 | F5: =IF(D5>0,-'Main Budget'!$H$25+0.15,0) -> 0 | G5: =IF(E5>0,-'Main Budget'!$F$25+0.81,0) -> 0 | H5: =IF(DAY(A5)='Main Budget'!$J$26,'Main Budget'!$E$26,0) -> 0 | I5: =IF(DAY(A5)='Main Budget'!$J$28,'Main Budget'!$E$28,0) -> 0 | J5: =IF(DAY(A5)='Main Budget'!$J$29,'Main Budget'!$E$29,0) -> 0 | K5: =IF(DAY(A5)='Main Budget'!$J$30,'Main Budget'!$E$30,0) -> 0 | L5: =IF(DAY(A5)='Main Budget'!$J$31,'Main Budget'!$E$31,0) -> 0 | M5: =IF(DAY(A5)='Main Budget'!$J$27,'Main Budget'!$E$27,0) -> 0 | O5: =B5+(SUM(H5:M5)+(SUM(D5:E5))) -> 100 | P5: =C5+F5+G5+N5 -> 100 | Q5: =O5+P5 -> 200 | S5: =TEXT(A5,"dddd") -> Sunday
A6: 46027 | B6: =O5 -> 100 | C6: =P5 -> 100 | D6: =IF(OR(DAY(A6+2)=1,DAY(A6+2)=15),-SUM('Main Budget'!$H$26:$H$31),0) -> 0 | E6: =IF(DAY(A6+2)=22,-SUM('Main Budget'!$F$26:$F$31),0) -> 0 | F6: =IF(D6>0,-'Main Budget'!$H$25+0.15,0) -> 0 | G6: =IF(E6>0,-'Main Budget'!$F$25+0.81,0) -> 0 | H6: =IF(DAY(A6)='Main Budget'!$J$26,'Main Budget'!$E$26,0) -> 0 | I6: =IF(DAY(A6)='Main Budget'!$J$28,'Main Budget'!$E$28,0) -> 0 | J6: =IF(DAY(A6)='Main Budget'!$J$29,'Main Budget'!$E$29,0) -> 0 | K6: =IF(DAY(A6)='Main Budget'!$J$30,'Main Budget'!$E$30,0) -> 0 | L6: =IF(DAY(A6)='Main Budget'!$J$31,'Main Budget'!$E$31,0) -> 0 | M6: =IF(DAY(A6)='Main Budget'!$J$27,'Main Budget'!$E$27,0) -> 0 | O6: =B6+(SUM(H6:M6)+(SUM(D6:E6))) -> 100 | P6: =C6+F6+G6+N6 -> 100 | Q6: =O6+P6 -> 200 | S6: =TEXT(A6,"dddd") -> Monday
A7: 46028 | B7: =O6 -> 100 | C7: =P6 -> 100 | D7: =IF(OR(DAY(A7+2)=1,DAY(A7+2)=15),-SUM('Main Budget'!$H$26:$H$31),0) -> 0 | E7: =IF(DAY(A7+2)=22,-SUM('Main Budget'!$F$26:$F$31),0) -> 0 | F7: =IF(D7>0,-'Main Budget'!$H$25+0.15,0) -> 0 | G7: =IF(E7>0,-'Main Budget'!$F$25+0.81,0) -> 0 | H7: =IF(DAY(A7)='Main Budget'!$J$26,'Main Budget'!$E$26,0) -> 0 | I7: =IF(DAY(A7)='Main Budget'!$J$28,'Main Budget'!$E$28,0) -> 0 | J7: =IF(DAY(A7)='Main Budget'!$J$29,'Main Budget'!$E$29,0) -> 0 | K7: =IF(DAY(A7)='Main Budget'!$J$30,'Main Budget'!$E$30,0) -> 0 | L7: =IF(DAY(A7)='Main Budget'!$J$31,'Main Budget'!$E$31,0) -> 0 | M7: =IF(DAY(A7)='Main Budget'!$J$27,'Main Budget'!$E$27,0) -> 0 | O7: =B7+(SUM(H7:M7)+(SUM(D7:E7))) -> 100 | P7: =C7+F7+G7+N7 -> 100 | Q7: =O7+P7 -> 200 | S7: =TEXT(A7,"dddd") -> Tuesday
A8: 46029 | B8: =O7 -> 100 | C8: =P7 -> 100 | D8: =IF(OR(DAY(A8+2)=1,DAY(A8+2)=15),-SUM('Main Budget'!$H$26:$H$31),0) -> 0 | E8: =IF(DAY(A8+2)=22,-SUM('Main Budget'!$F$26:$F$31),0) -> 0 | F8: =IF(D8>0,-'Main Budget'!$H$25+0.15,0) -> 0 | G8: =IF(E8>0,-'Main Budget'!$F$25+0.81,0) -> 0 | H8: =IF(DAY(A8)='Main Budget'!$J$26,'Main Budget'!$E$26,0) -> 0 | I8: =IF(DAY(A8)='Main Budget'!$J$28,'Main Budget'!$E$28,0) -> 0 | J8: =IF(DAY(A8)='Main Budget'!$J$29,'Main Budget'!$E$29,0) -> 0 | K8: =IF(DAY(A8)='Main Budget'!$J$30,'Main Budget'!$E$30,0) -> 0 | L8: =IF(DAY(A8)='Main Budget'!$J$31,'Main Budget'!$E$31,0) -> 0 | M8: =IF(DAY(A8)='Main Budget'!$J$27,'Main Budget'!$E$27,0) -> 0 | O8: =B8+(SUM(H8:M8)+(SUM(D8:E8))) -> 100 | P8: =C8+F8+G8+N8 -> 100 | Q8: =O8+P8 -> 200 | S8: =TEXT(A8,"dddd") -> Wednesday
A9: 46030 | B9: =O8 -> 100 | C9: =P8 -> 100 | D9: =IF(OR(DAY(A9+2)=1,DAY(A9+2)=15),-SUM('Main Budget'!$H$26:$H$31),0) -> 0 | E9: =IF(DAY(A9+2)=22,-SUM('Main Budget'!$F$26:$F$31),0) -> 0 | F9: =IF(D9>0,-'Main Budget'!$H$25+0.15,0) -> 0 | G9: =IF(E9>0,-'Main Budget'!$F$25+0.81,0) -> 0 | H9: =IF(DAY(A9)='Main Budget'!$J$26,'Main Budget'!$E$26,0) -> 0 | I9: =IF(DAY(A9)='Main Budget'!$J$28,'Main Budget'!$E$28,0) -> 0 | J9: =IF(DAY(A9)='Main Budget'!$J$29,'Main Budget'!$E$29,0) -> 0 | K9: =IF(DAY(A9)='Main Budget'!$J$30,'Main Budget'!$E$30,0) -> 0 | L9: =IF(DAY(A9)='Main Budget'!$J$31,'Main Budget'!$E$31,0) -> 0 | M9: =IF(DAY(A9)='Main Budget'!$J$27,'Main Budget'!$E$27,0) -> 0 | O9: =B9+(SUM(H9:M9)+(SUM(D9:E9))) -> 100 | P9: =C9+F9+G9+N9 -> 100 | Q9: =O9+P9 -> 200 | S9: =TEXT(A9,"dddd") -> Thursday
A10: 46031 | B10: =O9 -> 100 | C10: =P9 -> 100 | D10: =IF(OR(DAY(A10+2)=1,DAY(A10+2)=15),-SUM('Main Budget'!$H$26:$H$31),0) -> 0 | E10: =IF(DAY(A10+2)=22,-SUM('Main Budget'!$F$26:$F$31),0) -> 0 | F10: =IF(D10>0,-'Main Budget'!$H$25+0.15,0) -> 0 | G10: =IF(E10>0,-'Main Budget'!$F$25+0.81,0) -> 0 | H10: =IF(DAY(A10)='Main Budget'!$J$26,'Main Budget'!$E$26,0) -> 0 | I10: =IF(DAY(A10)='Main Budget'!$J$28,'Main Budget'!$E$28,0) -> 0 | J10: =IF(DAY(A10)='Main Budget'!$J$29,'Main Budget'!$E$29,0) -> 0 | K10: =IF(DAY(A10)='Main Budget'!$J$30,'Main Budget'!$E$30,0) -> 0 | L10: =IF(DAY(A10)='Main Budget'!$J$31,'Main Budget'!$E$31,0) -> 0 | M10: =IF(DAY(A10)='Main Budget'!$J$27,'Main Budget'!$E$27,0) -> 0 | O10: =B10+(SUM(H10:M10)+(SUM(D10:E10))) -> 100 | P10: =C10+F10+G10+N10 -> 100 | Q10: =O10+P10 -> 200 | S10: =TEXT(A10,"dddd") -> Friday
A11: 46032 | B11: =O10 -> 100 | C11: =P10 -> 100 | D11: =IF(OR(DAY(A11+2)=1,DAY(A11+2)=15),-SUM('Main Budget'!$H$26:$H$31),0) -> 0 | E11: =IF(DAY(A11+2)=22,-SUM('Main Budget'!$F$26:$F$31),0) -> 0 | F11: =IF(D11>0,-'Main Budget'!$H$25+0.15,0) -> 0 | G11: =IF(E11>0,-'Main Budget'!$F$25+0.81,0) -> 0 | H11: =IF(DAY(A11)='Main Budget'!$J$26,'Main Budget'!$E$26,0) -> 0 | I11: =IF(DAY(A11)='Main Budget'!$J$28,'Main Budget'!$E$28,0) -> 0 | J11: =IF(DAY(A11)='Main Budget'!$J$29,'Main Budget'!$E$29,0) -> 0 | K11: =IF(DAY(A11)='Main Budget'!$J$30,'Main Budget'!$E$30,0) -> 0 | L11: =IF(DAY(A11)='Main Budget'!$J$31,'Main Budget'!$E$31,0) -> 0 | M11: =IF(DAY(A11)='Main Budget'!$J$27,'Main Budget'!$E$27,0) -> 0 | O11: =B11+(SUM(H11:M11)+(SUM(D11:E11))) -> 100 | P11: =C11+F11+G11+N11 -> 100 | Q11: =O11+P11 -> 200 | S11: =TEXT(A11,"dddd") -> Saturday
A12: 46033 | B12: =O11 -> 100 | C12: =P11 -> 100 | D12: =IF(OR(DAY(A12+2)=1,DAY(A12+2)=15),-SUM('Main Budget'!$H$26:$H$31),0) -> 0 | E12: =IF(DAY(A12+2)=22,-SUM('Main Budget'!$F$26:$F$31),0) -> 0 | F12: =IF(D12>0,-'Main Budget'!$H$25+0.15,0) -> 0 | G12: =IF(E12>0,-'Main Budget'!$F$25+0.81,0) -> 0 | H12: =IF(DAY(A12)='Main Budget'!$J$26,'Main Budget'!$E$26,0) -> 0 | I12: =IF(DAY(A12)='Main Budget'!$J$28,'Main Budget'!$E$28,0) -> 0 | J12: =IF(DAY(A12)='Main Budget'!$J$29,'Main Budget'!$E$29,0) -> 0 | K12: =IF(DAY(A12)='Main Budget'!$J$30,'Main Budget'!$E$30,0) -> 0 | L12: =IF(DAY(A12)='Main Budget'!$J$31,'Main Budget'!$E$31,0) -> 0 | M12: =IF(DAY(A12)='Main Budget'!$J$27,'Main Budget'!$E$27,0) -> 0 | O12: =B12+(SUM(H12:M12)+(SUM(D12:E12))) -> 100 | P12: =C12+F12+G12+N12 -> 100 | Q12: =O12+P12 -> 200 | S12: =TEXT(A12,"dddd") -> Sunday
A13: 46034 | B13: =O12 -> 100 | C13: =P12 -> 100 | D13: =IF(OR(DAY(A13+2)=1,DAY(A13+2)=15),-SUM('Main Budget'!$H$26:$H$31),0) -> 0 | E13: =IF(DAY(A13+2)=22,-SUM('Main Budget'!$F$26:$F$31),0) -> 0 | F13: =IF(D13>0,-'Main Budget'!$H$25+0.15,0) -> 0 | G13: =IF(E13>0,-'Main Budget'!$F$25+0.81,0) -> 0 | H13: =IF(DAY(A13)='Main Budget'!$J$26,'Main Budget'!$E$26,0) -> 0 | I13: =IF(DAY(A13)='Main Budget'!$J$28,'Main Budget'!$E$28,0) -> 0 | J13: =IF(DAY(A13)='Main Budget'!$J$29,'Main Budget'!$E$29,0) -> 0 | K13: =IF(DAY(A13)='Main Budget'!$J$30,'Main Budget'!$E$30,0) -> 0 | L13: =IF(DAY(A13)='Main Budget'!$J$31,'Main Budget'!$E$31,0) -> 0 | M13: =IF(DAY(A13)='Main Budget'!$J$27,'Main Budget'!$E$27,0) -> 0 | O13: =B13+(SUM(H13:M13)+(SUM(D13:E13))) -> 100 | P13: =C13+F13+G13+N13 -> 100 | Q13: =O13+P13 -> 200 | S13: =TEXT(A13,"dddd") -> Monday
A14: 46035 | B14: =O13 -> 100 | C14: =P13 -> 100 | D14: =IF(OR(DAY(A14+2)=1,DAY(A14+2)=15),-SUM('Main Budget'!$H$26:$H$31),0) -> 0 | E14: =IF(DAY(A14+2)=22,-SUM('Main Budget'!$F$26:$F$31),0) -> 0 | F14: =IF(D14>0,-'Main Budget'!$H$25+0.15,0) -> 0 | G14: =IF(E14>0,-'Main Budget'!$F$25+0.81,0) -> 0 | H14: =IF(DAY(A14)='Main Budget'!$J$26,'Main Budget'!$E$26,0) -> 0 | I14: =IF(DAY(A14)='Main Budget'!$J$28,'Main Budget'!$E$28,0) -> 0 | J14: =IF(DAY(A14)='Main Budget'!$J$29,'Main Budget'!$E$29,0) -> 0 | K14: =IF(DAY(A14)='Main Budget'!$J$30,'Main Budget'!$E$30,0) -> 0 | L14: =IF(DAY(A14)='Main Budget'!$J$31,'Main Budget'!$E$31,0) -> 0 | M14: =IF(DAY(A14)='Main Budget'!$J$27,'Main Budget'!$E$27,0) -> 0 | O14: =B14+(SUM(H14:M14)+(SUM(D14:E14))) -> 100 | P14: =C14+F14+G14+N14 -> 100 | Q14: =O14+P14 -> 200 | S14: =TEXT(A14,"dddd") -> Tuesday
... A1374: 47395 | B1374: =O1373 -> 100 | C1374: =P1373 -> 100 | D1374: =IF(OR(DAY(A1374+2)=1,DAY(A1374+2)=15),-SUM('Main Budget'!$H$26:$H$31),0) -> 0 | E1374: =IF(DAY(A1374+2)=22,-SUM('Main Budget'!$F$26:$F$31),0) -> 0 | F1374: =IF(D1374>0,-'Main Budget'!$H$25+0.15,0) -> 0 | G1374: =IF(E1374>0,-'Main Budget'!$F$25+0.81,0) -> 0 | H1374: =IF(DAY(A1374)='Main Budget'!$J$26,'Main Budget'!$E$26,0) -> 0 | I1374: =IF(DAY(A1374)='Main Budget'!$J$28,'Main Budget'!$E$28,0) -> 0 | J1374: =IF(DAY(A1374)='Main Budget'!$J$29,'Main Budget'!$E$29,0) -> 0 | K1374: =IF(DAY(A1374)='Main Budget'!$J$30,'Main Budget'!$E$30,0) -> 0 | L1374: =IF(DAY(A1374)='Main Budget'!$J$31,'Main Budget'!$E$31,0) -> 0 | M1374: =IF(DAY(A1374)='Main Budget'!$J$27,'Main Budget'!$E$27,0) -> 0 | O1374: =B1374+(SUM(H1374:M1374)+(SUM(D1374:E1374))) -> 100 | P1374: =C1374+F1374+G1374+N1374 -> 100 | Q1374: =O1374+P1374 -> 200 | S1374: =TEXT(A1374,"dddd") -> Thursday

Sheet HOA Savings
A1: Date | B1: Regular Beg Balance | C1: Extra Beg Balance | D1: Total Beg Balance | E1: Jon Credit | F1: Ronnie Credit | G1: Jon Extra Credit | H1: Ronnie Extra Credit | I1: HOA Payment | J1: Other | K1: Regular Ending Balance | L1: Extra Payment Balance | M1: Total Balance | N1: Extra Patment Withdrawl | O1: Other Explination | P1: Day of week
A2: 46023 | B2: 100 | C2: 100 | D2: =B2+C2 -> 200 | E2: =-(IF(DAY(A2+2)=1,'Main Budget'!$H$19,IF(DAY(A2+1)=15,'Main Budget'!$H$19,0))) -> 0 | F2: =-(IF(DAY(A2)=20,'Main Budget'!$F$19,0)) -> 0 | G2: =-(IF(DAY(A2+2)=1,'Main Budget'!$H$20,IF(DAY(A2+1)=15,'Main Budget'!$H$20,0))) -> 0 | H2: =-(IF(DAY(A2)=20,'Main Budget'!$F$20,0)) -> 0 | K2: =MAX((B2+E2+F2+J2)+I2,0) -> 100 | L2: =ROUND(C2+G2+H2+N2,2) -> 100 | M2: =K2+L2 -> 200 | P2: =TEXT(A2,"dddd") -> Thursday
A3: 46024 | B3: =K2 -> 100 | C3: =ROUND(L2+N2,2) -> 100 | D3: =B3+C3 -> 200 | E3: =-(IF(DAY(A3+2)=1,'Main Budget'!$H$19,IF(DAY(A3+1)=15,'Main Budget'!$H$19,0))) -> 0 | F3: =-(IF(DAY(A3)=20,'Main Budget'!$F$19,0)) -> 0 | G3: =-(IF(DAY(A3+2)=1,'Main Budget'!$H$20,IF(DAY(A3+1)=15,'Main Budget'!$H$20,0))) -> 0 | H3: =-(IF(DAY(A3)=20,'Main Budget'!$F$20,0)) -> 0 | K3: =MAX((B3+E3+F3+J3)+I3,0) -> 100 | L3: =ROUND(IF((B3+E3+F3+J3)+I3<0,(L2+G3+H3)+(B3+E3+F3+J3)+I3,(L2+G3+H3))+N2,2) -> 100 | M3: =K3+L3 -> 200 | P3: =TEXT(A3,"dddd") -> Friday
A4: 46025 | B4: =K3 -> 100 | C4: =ROUND(L3+N3,2) -> 100 | D4: =B4+C4 -> 200 | E4: =-(IF(DAY(A4+2)=1,'Main Budget'!$H$19,IF(DAY(A4+1)=15,'Main Budget'!$H$19,0))) -> 0 | F4: =-(IF(DAY(A4)=20,'Main Budget'!$F$19,0)) -> 0 | G4: =-(IF(DAY(A4+2)=1,'Main Budget'!$H$20,IF(DAY(A4+1)=15,'Main Budget'!$H$20,0))) -> 0 | H4: =-(IF(DAY(A4)=20,'Main Budget'!$F$20,0)) -> 0 | K4: =MAX((B4+E4+F4+J4)+I4,0) -> 100 | L4: =ROUND(IF((B4+E4+F4+J4)+I4<0,(L3+G4+H4)+(B4+E4+F4+J4)+I4,(L3+G4+H4))+N3,2) -> 100 | M4: =K4+L4 -> 200 | P4: =TEXT(A4,"dddd") -> Saturday
A5: 46026 | B5: =K4 -> 100 | C5: =ROUND(L4+N4,2) -> 100 | D5: =B5+C5 -> 200 | E5: =-(IF(DAY(A5+2)=1,'Main Budget'!$H$19,IF(DAY(A5+1)=15,'Main Budget'!$H$19,0))) -> 0 | F5: =-(IF(DAY(A5)=20,'Main Budget'!$F$19,0)) -> 0 | G5: =-(IF(DAY(A5+2)=1,'Main Budget'!$H$20,IF(DAY(A5+1)=15,'Main Budget'!$H$20,0))) -> 0 | H5: =-(IF(DAY(A5)=20,'Main Budget'!$F$20,0)) -> 0 | K5: =MAX((B5+E5+F5+J5)+I5,0) -> 100 | L5: =ROUND(IF((B5+E5+F5+J5)+I5<0,(L4+G5+H5)+(B5+E5+F5+J5)+I5,(L4+G5+H5))+N4,2) -> 100 | M5: =K5+L5 -> 200 | P5: =TEXT(A5,"dddd") -> Sunday
A6: 46027 | B6: =K5 -> 100 | C6: =ROUND(L5+N5,2) -> 100 | D6: =B6+C6 -> 200 | E6: =-(IF(DAY(A6+2)=1,'Main Budget'!$H$19,IF(DAY(A6+1)=15,'Main Budget'!$H$19,0))) -> 0 | F6: =-(IF(DAY(A6)=20,'Main Budget'!$F$19,0)) -> 0 | G6: =-(IF(DAY(A6+2)=1,'Main Budget'!$H$20,IF(DAY(A6+1)=15,'Main Budget'!$H$20,0))) -> 0 | H6: =-(IF(DAY(A6)=20,'Main Budget'!$F$20,0)) -> 0 | K6: =MAX((B6+E6+F6+J6)+I6,0) -> 100 | L6: =ROUND(IF((B6+E6+F6+J6)+I6<0,(L5+G6+H6)+(B6+E6+F6+J6)+I6,(L5+G6+H6))+N5,2) -> 100 | M6: =K6+L6 -> 200 | P6: =TEXT(A6,"dddd") -> Monday
A7: 46028 | B7: =K6 -> 100 | C7: =ROUND(L6+N6,2) -> 100 | D7: =B7+C7 -> 200 | E7: =-(IF(DAY(A7+2)=1,'Main Budget'!$H$19,IF(DAY(A7+1)=15,'Main Budget'!$H$19,0))) -> 0 | F7: =-(IF(DAY(A7)=20,'Main Budget'!$F$19,0)) -> 0 | G7: =-(IF(DAY(A7+2)=1,'Main Budget'!$H$20,IF(DAY(A7+1)=15,'Main Budget'!$H$20,0))) -> 0 | H7: =-(IF(DAY(A7)=20,'Main Budget'!$F$20,0)) -> 0 | K7: =MAX((B7+E7+F7+J7)+I7,0) -> 100 | L7: =ROUND(IF((B7+E7+F7+J7)+I7<0,(L6+G7+H7)+(B7+E7+F7+J7)+I7,(L6+G7+H7))+N6,2) -> 100 | M7: =K7+L7 -> 200 | P7: =TEXT(A7,"dddd") -> Tuesday
A8: 46029 | B8: =K7 -> 100 | C8: =ROUND(L7+N7,2) -> 100 | D8: =B8+C8 -> 200 | E8: =-(IF(DAY(A8+2)=1,'Main Budget'!$H$19,IF(DAY(A8+1)=15,'Main Budget'!$H$19,0))) -> 0 | F8: =-(IF(DAY(A8)=20,'Main Budget'!$F$19,0)) -> 0 | G8: =-(IF(DAY(A8+2)=1,'Main Budget'!$H$20,IF(DAY(A8+1)=15,'Main Budget'!$H$20,0))) -> 0 | H8: =-(IF(DAY(A8)=20,'Main Budget'!$F$20,0)) -> 0 | K8: =MAX((B8+E8+F8+J8)+I8,0) -> 100 | L8: =ROUND(IF((B8+E8+F8+J8)+I8<0,(L7+G8+H8)+(B8+E8+F8+J8)+I8,(L7+G8+H8))+N7,2) -> 100 | M8: =K8+L8 -> 200 | P8: =TEXT(A8,"dddd") -> Wednesday
A9: 46030 | B9: =K8 -> 100 | C9: =ROUND(L8+N8,2) -> 100 | D9: =B9+C9 -> 200 | E9: =-(IF(DAY(A9+2)=1,'Main Budget'!$H$19,IF(DAY(A9+1)=15,'Main Budget'!$H$19,0))) -> 0 | F9: =-(IF(DAY(A9)=20,'Main Budget'!$F$19,0)) -> 0 | G9: =-(IF(DAY(A9+2)=1,'Main Budget'!$H$20,IF(DAY(A9+1)=15,'Main Budget'!$H$20,0))) -> 0 | H9: =-(IF(DAY(A9)=20,'Main Budget'!$F$20,0)) -> 0 | K9: =MAX((B9+E9+F9+J9)+I9,0) -> 100 | L9: =ROUND(IF((B9+E9+F9+J9)+I9<0,(L8+G9+H9)+(B9+E9+F9+J9)+I9,(L8+G9+H9))+N8,2) -> 100 | M9: =K9+L9 -> 200 | P9: =TEXT(A9,"dddd") -> Thursday
A10: 46031 | B10: =K9 -> 100 | C10: =ROUND(L9+N9,2) -> 100 | D10: =B10+C10 -> 200 | E10: =-(IF(DAY(A10+2)=1,'Main Budget'!$H$19,IF(DAY(A10+1)=15,'Main Budget'!$H$19,0))) -> 0 | F10: =-(IF(DAY(A10)=20,'Main Budget'!$F$19,0)) -> 0 | G10: =-(IF(DAY(A10+2)=1,'Main Budget'!$H$20,IF(DAY(A10+1)=15,'Main Budget'!$H$20,0))) -> 0 | H10: =-(IF(DAY(A10)=20,'Main Budget'!$F$20,0)) -> 0 | K10: =MAX((B10+E10+F10+J10)+I10,0) -> 100 | L10: =ROUND(IF((B10+E10+F10+J10)+I10<0,(L9+G10+H10)+(B10+E10+F10+J10)+I10,(L9+G10+H10))+N9,2) -> 100 | M10: =K10+L10 -> 200 | P10: =TEXT(A10,"dddd") -> Friday
A11: 46032 | B11: =K10 -> 100 | C11: =ROUND(L10+N10,2) -> 100 | D11: =B11+C11 -> 200 | E11: =-(IF(DAY(A11+2)=1,'Main Budget'!$H$19,IF(DAY(A11+1)=15,'Main Budget'!$H$19,0))) -> 0 | F11: =-(IF(DAY(A11)=20,'Main Budget'!$F$19,0)) -> 0 | G11: =-(IF(DAY(A11+2)=1,'Main Budget'!$H$20,IF(DAY(A11+1)=15,'Main Budget'!$H$20,0))) -> 0 | H11: =-(IF(DAY(A11)=20,'Main Budget'!$F$20,0)) -> 0 | K11: =MAX((B11+E11+F11+J11)+I11,0) -> 100 | L11: =ROUND(IF((B11+E11+F11+J11)+I11<0,(L10+G11+H11)+(B11+E11+F11+J11)+I11,(L10+G11+H11))+N10,2) -> 100 | M11: =K11+L11 -> 200 | P11: =TEXT(A11,"dddd") -> Saturday
A12: 46033 | B12: =K11 -> 100 | C12: =ROUND(L11+N11,2) -> 100 | D12: =B12+C12 -> 200 | E12: =-(IF(DAY(A12+2)=1,'Main Budget'!$H$19,IF(DAY(A12+1)=15,'Main Budget'!$H$19,0))) -> 0 | F12: =-(IF(DAY(A12)=20,'Main Budget'!$F$19,0)) -> 0 | G12: =-(IF(DAY(A12+2)=1,'Main Budget'!$H$20,IF(DAY(A12+1)=15,'Main Budget'!$H$20,0))) -> 0 | H12: =-(IF(DAY(A12)=20,'Main Budget'!$F$20,0)) -> 0 | K12: =MAX((B12+E12+F12+J12)+I12,0) -> 100 | L12: =ROUND(IF((B12+E12+F12+J12)+I12<0,(L11+G12+H12)+(B12+E12+F12+J12)+I12,(L11+G12+H12))+N11,2) -> 100 | M12: =K12+L12 -> 200 | P12: =TEXT(A12,"dddd") -> Sunday
A13: 46034 | B13: =K12 -> 100 | C13: =ROUND(L12+N12,2) -> 100 | D13: =B13+C13 -> 200 | E13: =-(IF(DAY(A13+2)=1,'Main Budget'!$H$19,IF(DAY(A13+1)=15,'Main Budget'!$H$19,0))) -> 0 | F13: =-(IF(DAY(A13)=20,'Main Budget'!$F$19,0)) -> 0 | G13: =-(IF(DAY(A13+2)=1,'Main Budget'!$H$20,IF(DAY(A13+1)=15,'Main Budget'!$H$20,0))) -> 0 | H13: =-(IF(DAY(A13)=20,'Main Budget'!$F$20,0)) -> 0 | K13: =MAX((B13+E13+F13+J13)+I13,0) -> 100 | L13: =ROUND(IF((B13+E13+F13+J13)+I13<0,(L12+G13+H13)+(B13+E13+F13+J13)+I13,(L12+G13+H13))+N12,2) -> 100 | M13: =K13+L13 -> 200 | P13: =TEXT(A13,"dddd") -> Monday
A14: 46035 | B14: =K13 -> 100 | C14: =ROUND(L13+N13,2) -> 100 | D14: =B14+C14 -> 200 | E14: =-(IF(DAY(A14+2)=1,'Main Budget'!$H$19,IF(DAY(A14+1)=15,'Main Budget'!$H$19,0))) -> 0 | F14: =-(IF(DAY(A14)=20,'Main Budget'!$F$19,0)) -> 0 | G14: =-(IF(DAY(A14+2)=1,'Main Budget'!$H$20,IF(DAY(A14+1)=15,'Main Budget'!$H$20,0))) -> 0 | H14: =-(IF(DAY(A14)=20,'Main Budget'!$F$20,0)) -> 0 | K14: =MAX((B14+E14+F14+J14)+I14,0) -> 100 | L14: =ROUND(IF((B14+E14+F14+J14)+I14<0,(L13+G14+H14)+(B14+E14+F14+J14)+I14,(L13+G14+H14))+N13,2) -> 100 | M14: =K14+L14 -> 200 | P14: =TEXT(A14,"dddd") -> Tuesday
... A99: 46120 | B99: =K98 -> 100 | C99: =ROUND(L98+N98,2) -> 100 | D99: =B99+C99 -> 200 | E99: =-(IF(DAY(A99+2)=1,'Main Budget'!$H$19,IF(DAY(A99+1)=15,'Main Budget'!$H$19,0))) -> 0 | F99: =-(IF(DAY(A99)=20,'Main Budget'!$F$19,0)) -> 0 | G99: =-(IF(DAY(A99+2)=1,'Main Budget'!$H$20,IF(DAY(A99+1)=15,'Main Budget'!$H$20,0))) -> 0 | H99: =-(IF(DAY(A99)=20,'Main Budget'!$F$20,0)) -> 0 | K99: =MAX((B99+E99+F99+J99)+I99,0) -> 100 | L99: =ROUND(IF((B99+E99+F99+J99)+I99<0,(L98+G99+H99)+(B99+E99+F99+J99)+I99,(L98+G99+H99))+N98,2) -> 100 | M99: =K99+L99 -> 200 | P99: =TEXT(A99,"dddd") -> Wednesday
A100: 46121
A101: 46122 | K101: =MIN(K2:K100) -> 100

Sheet Bills Checking
A1: Date | B1: Beg Balance | C1: Credit | D1: Gym Credit | E1: Cell Service | F1: Gym | G1: Chase - TV | H1: Insurance Payment | I1: Other | J1: Ending Balance | L1: Other Explination | M1: Day of week
A2: 46023 | B2: 100 | C2: =IF(DAY(A2+2)=1,'Main Budget'!$G$39,IF(DAY(A2+2)=15,'Main Budget'!$G$39,0)) -> 0 | D2: =IF(OR(DAY(A2)=1,DAY(A2)=15),11.25,0) -> 11.25 | E2: =IF(DAY(A2)='Main Budget'!$J$12,('Main Budget'!$G$12),0) -> 0 | F2: =IF(DAY(A2)='Main Budget'!$J$13,('Main Budget'!$G$13)*2,0) -> 0 | H2: =IF(DAY(A2)='Main Budget'!$J$14,'Main Budget'!$G$14,0) -> 0 | J2: =B2+SUM(C2:I2) -> 111.25 | M2: =TEXT(A2,"dddd") -> Thursday
A3: 46024 | B3: =J2 -> 111.25 | C3: =IF(DAY(A3+2)=1,'Main Budget'!$G$39,IF(DAY(A3+2)=15,'Main Budget'!$G$39,0)) -> 0 | D3: =IF(OR(DAY(A3)=1,DAY(A3)=15),11.25,0) -> 0 | E3: =IF(DAY(A3)='Main Budget'!$J$12,('Main Budget'!$G$12),0) -> 0 | F3: =IF(DAY(A3)='Main Budget'!$J$13,('Main Budget'!$G$13)*2,0) -> 0 | H3: =IF(DAY(A3)='Main Budget'!$J$14,'Main Budget'!$G$14,0) -> 0 | J3: =J2+(SUM(C3:I3)) -> 111.25 | M3: =TEXT(A3,"dddd") -> Friday
A4: 46025 | B4: =J3 -> 111.25 | C4: =IF(DAY(A4+2)=1,'Main Budget'!$G$39,IF(DAY(A4+2)=15,'Main Budget'!$G$39,0)) -> 0 | D4: =IF(OR(DAY(A4)=1,DAY(A4)=15),11.25,0) -> 0 | E4: =IF(DAY(A4)='Main Budget'!$J$12,('Main Budget'!$G$12),0) -> 0 | F4: =IF(DAY(A4)='Main Budget'!$J$13,('Main Budget'!$G$13)*2,0) -> 0 | H4: =IF(DAY(A4)='Main Budget'!$J$14,'Main Budget'!$G$14,0) -> 0 | J4: =J3+(SUM(C4:I4)) -> 111.25 | M4: =TEXT(A4,"dddd") -> Saturday
A5: 46026 | B5: =J4 -> 111.25 | C5: =IF(DAY(A5+2)=1,'Main Budget'!$G$39,IF(DAY(A5+2)=15,'Main Budget'!$G$39,0)) -> 0 | D5: =IF(OR(DAY(A5)=1,DAY(A5)=15),11.25,0) -> 0 | E5: =IF(DAY(A5)='Main Budget'!$J$12,('Main Budget'!$G$12),0) -> 0 | F5: =IF(DAY(A5)='Main Budget'!$J$13,('Main Budget'!$G$13)*2,0) -> 0 | H5: =IF(DAY(A5)='Main Budget'!$J$14,'Main Budget'!$G$14,0) -> 0 | J5: =J4+(SUM(C5:I5)) -> 111.25 | M5: =TEXT(A5,"dddd") -> Sunday
A6: 46027 | B6: =J5 -> 111.25 | C6: =IF(DAY(A6+2)=1,'Main Budget'!$G$39,IF(DAY(A6+2)=15,'Main Budget'!$G$39,0)) -> 0 | D6: =IF(OR(DAY(A6)=1,DAY(A6)=15),11.25,0) -> 0 | E6: =IF(DAY(A6)='Main Budget'!$J$12,('Main Budget'!$G$12),0) -> 0 | F6: =IF(DAY(A6)='Main Budget'!$J$13,('Main Budget'!$G$13)*2,0) -> 0 | H6: =IF(DAY(A6)='Main Budget'!$J$14,'Main Budget'!$G$14,0) -> 0 | J6: =J5+(SUM(C6:I6)) -> 111.25 | M6: =TEXT(A6,"dddd") -> Monday
A7: 46028 | B7: =J6 -> 111.25 | C7: =IF(DAY(A7+2)=1,'Main Budget'!$G$39,IF(DAY(A7+2)=15,'Main Budget'!$G$39,0)) -> 0 | D7: =IF(OR(DAY(A7)=1,DAY(A7)=15),11.25,0) -> 0 | E7: =IF(DAY(A7)='Main Budget'!$J$12,('Main Budget'!$G$12),0) -> 0 | F7: =IF(DAY(A7)='Main Budget'!$J$13,('Main Budget'!$G$13)*2,0) -> 0 | H7: =IF(DAY(A7)='Main Budget'!$J$14,'Main Budget'!$G$14,0) -> 0 | J7: =J6+(SUM(C7:I7)) -> 111.25 | M7: =TEXT(A7,"dddd") -> Tuesday
A8: 46029 | B8: =J7 -> 111.25 | C8: =IF(DAY(A8+2)=1,'Main Budget'!$G$39,IF(DAY(A8+2)=15,'Main Budget'!$G$39,0)) -> 0 | D8: =IF(OR(DAY(A8)=1,DAY(A8)=15),11.25,0) -> 0 | E8: =IF(DAY(A8)='Main Budget'!$J$12,('Main Budget'!$G$12),0) -> 0 | F8: =IF(DAY(A8)='Main Budget'!$J$13,('Main Budget'!$G$13)*2,0) -> 0 | H8: =IF(DAY(A8)='Main Budget'!$J$14,'Main Budget'!$G$14,0) -> 0 | J8: =J7+(SUM(C8:I8)) -> 111.25 | M8: =TEXT(A8,"dddd") -> Wednesday
A9: 46030 | B9: =J8 -> 111.25 | C9: =IF(DAY(A9+2)=1,'Main Budget'!$G$39,IF(DAY(A9+2)=15,'Main Budget'!$G$39,0)) -> 0 | D9: =IF(OR(DAY(A9)=1,DAY(A9)=15),11.25,0) -> 0 | E9: =IF(DAY(A9)='Main Budget'!$J$12,('Main Budget'!$G$12),0) -> 0 | F9: =IF(DAY(A9)='Main Budget'!$J$13,('Main Budget'!$G$13)*2,0) -> 0 | H9: =IF(DAY(A9)='Main Budget'!$J$14,'Main Budget'!$G$14,0) -> 0 | J9: =J8+(SUM(C9:I9)) -> 111.25 | M9: =TEXT(A9,"dddd") -> Thursday
A10: 46031 | B10: =J9 -> 111.25 | C10: =IF(DAY(A10+2)=1,'Main Budget'!$G$39,IF(DAY(A10+2)=15,'Main Budget'!$G$39,0)) -> 0 | D10: =IF(OR(DAY(A10)=1,DAY(A10)=15),11.25,0) -> 0 | E10: =IF(DAY(A10)='Main Budget'!$J$12,('Main Budget'!$G$12),0) -> 0 | F10: =IF(DAY(A10)='Main Budget'!$J$13,('Main Budget'!$G$13)*2,0) -> 0 | H10: =IF(DAY(A10)='Main Budget'!$J$14,'Main Budget'!$G$14,0) -> 0 | J10: =J9+(SUM(C10:I10)) -> 111.25 | M10: =TEXT(A10,"dddd") -> Friday
A11: 46032 | B11: =J10 -> 111.25 | C11: =IF(DAY(A11+2)=1,'Main Budget'!$G$39,IF(DAY(A11+2)=15,'Main Budget'!$G$39,0)) -> 0 | D11: =IF(OR(DAY(A11)=1,DAY(A11)=15),11.25,0) -> 0 | E11: =IF(DAY(A11)='Main Budget'!$J$12,('Main Budget'!$G$12),0) -> 0 | F11: =IF(DAY(A11)='Main Budget'!$J$13,('Main Budget'!$G$13)*2,0) -> 0 | H11: =IF(DAY(A11)='Main Budget'!$J$14,'Main Budget'!$G$14,0) -> 0 | J11: =J10+(SUM(C11:I11)) -> 111.25 | M11: =TEXT(A11,"dddd") -> Saturday
A12: 46033 | B12: =J11 -> 111.25 | C12: =IF(DAY(A12+2)=1,'Main Budget'!$G$39,IF(DAY(A12+2)=15,'Main Budget'!$G$39,0)) -> 0 | D12: =IF(OR(DAY(A12)=1,DAY(A12)=15),11.25,0) -> 0 | E12: =IF(DAY(A12)='Main Budget'!$J$12,('Main Budget'!$G$12),0) -> 0 | F12: =IF(DAY(A12)='Main Budget'!$J$13,('Main Budget'!$G$13)*2,0) -> 0 | H12: =IF(DAY(A12)='Main Budget'!$J$14,'Main Budget'!$G$14,0) -> 0 | J12: =J11+(SUM(C12:I12)) -> 111.25 | M12: =TEXT(A12,"dddd") -> Sunday
A13: 46034 | B13: =J12 -> 111.25 | C13: =IF(DAY(A13+2)=1,'Main Budget'!$G$39,IF(DAY(A13+2)=15,'Main Budget'!$G$39,0)) -> 0 | D13: =IF(OR(DAY(A13)=1,DAY(A13)=15),11.25,0) -> 0 | E13: =IF(DAY(A13)='Main Budget'!$J$12,('Main Budget'!$G$12),0) -> 0 | F13: =IF(DAY(A13)='Main Budget'!$J$13,('Main Budget'!$G$13)*2,0) -> 0 | H13: =IF(DAY(A13)='Main Budget'!$J$14,'Main Budget'!$G$14,0) -> 0 | J13: =J12+(SUM(C13:I13)) -> 111.25 | M13: =TEXT(A13,"dddd") -> Monday
A14: 46035 | B14: =J13 -> 111.25 | C14: =IF(DAY(A14+2)=1,'Main Budget'!$G$39,IF(DAY(A14+2)=15,'Main Budget'!$G$39,0)) -> 0 | D14: =IF(OR(DAY(A14)=1,DAY(A14)=15),11.25,0) -> 0 | E14: =IF(DAY(A14)='Main Budget'!$J$12,('Main Budget'!$G$12),0) -> 0 | F14: =IF(DAY(A14)='Main Budget'!$J$13,('Main Budget'!$G$13)*2,0) -> 0 | H14: =IF(DAY(A14)='Main Budget'!$J$14,'Main Budget'!$G$14,0) -> 0 | J14: =J13+(SUM(C14:I14)) -> 111.25 | M14: =TEXT(A14,"dddd") -> Tuesday
... A710: 46731 | B710: =J709 -> 628.75 | C710: =IF(DAY(A710+2)=1,'Main Budget'!$G$39,IF(DAY(A710+2)=15,'Main Budget'!$G$39,0)) -> 0 | D710: =IF(OR(DAY(A710)=1,DAY(A710)=15),11.25,0) -> 0 | E710: =IF(DAY(A710)='Main Budget'!$J$12,('Main Budget'!$G$12),0) -> 0 | F710: =IF(DAY(A710)='Main Budget'!$J$13,('Main Budget'!$G$13)*2,0) -> 0 | H710: =IF(DAY(A710)='Main Budget'!$J$14,'Main Budget'!$G$14,0) -> 0 | J710: =J709+(SUM(C710:I710)) -> 628.75 | M710: =TEXT(A710,"dddd") -> Friday

Sheet Loan Amortization
A1: ="LOAN AMORTIZATION: "&B4 -> LOAN AMORTIZATION: Enter Item Name/Description
A3: LOAN DETAILS | D3: LOAN SUMMARY
A4: Purchase Description | B4: Enter Item Name/Description | D4: Total Principal | E4: =B5 -> 0
A5: Loan Amount | D5: Total Interest | E5: =SUMIF(H:H,">0",H:H) -> 0
A6: Annual Interest Rate | D6: Total Cost | E6: =E4+E5 -> 0
A7: Interest Calculation | B7: Monthly | D7: Payoff Date | E7: =MAX(I:I) -> 0
A8: Loan Term (Months) | B8: Monthly | D8: Actual Payments | E8: =COUNTIF(A:A,">0") -> 0
A9: Payments Per Year | D9: Actual Payments | E9: =COUNTIF(A:A,">0") -> 0
A10: Start Date
A11: Monthly Payment
A12: Extra Payment
A14: Payment # | B14: Beginning Balance | C14: Payment | D14: Extra Payment | E14: Total Payment | F14: Principal | G14: Days | H14: Interest | I14: Payment Date | J14: Ending Balance | K14: Cumulative Principal | L14: Cumulative Interest
A15: =IF($B$5>0,1,"") | B15: =IF(A15="","",$B$5) | C15: =IF(A15="","",IF(B15+H15<=$B$11,ROUND(B15+H15,2),ROUND($B$11,2))) | D15: =IF(A15="","",MAX(0,ROUND(MIN($B$12,B15-F15),2))) | E15: =IF(A15="","",ROUND(C15+D15,2)) | F15: =IF(A15="","",ROUND(C15-H15,2)) | G15: =IF(A15="","",IF($B$7="Daily",DAY(EOMONTH($B$10,0))-DAY($B$10)+1,"")) | H15: =IF(A15="","",IF($B$7="Daily",ROUND(B15*($B$6/365)*G15,2),ROUND(B15*($B$6/$B$9),2))) | I15: =IF(A15="","",IF($B$7="Daily",EOMONTH($B$10,0),EDATE($B$10,A15-1))) | J15: =IF(A15="","",ROUND(MAX(0,B15-F15-D15),2)) | K15: =IF(A15="","",ROUND(F15+D15,2)) | L15: =IF(A15="","",H15)
A16: =IF(OR(J15<=0,J15=""),"",A15+1) | B16: =IF(A16="","",J15) | C16: =IF(A16="","",IF(B16+H16<=$B$11,ROUND(B16+H16,2),ROUND($B$11,2))) | D16: =IF(A16="","",MAX(0,ROUND(MIN($B$12,B16-F16),2))) | E16: =IF(A16="","",ROUND(C16+D16,2)) | F16: =IF(A16="","",ROUND(C16-H16,2)) | G16: =IF(A16="","",IF($B$7="Daily",I16-I15,"")) | H16: =IF(A16="","",IF($B$7="Daily",ROUND(B16*($B$6/365)*G16,2),ROUND(B16*($B$6/$B$9),2))) | I16: =IF(A16="","",IF($B$7="Daily",EOMONTH(I15,1),EDATE($B$10,A16-1))) | J16: =IF(A16="","",ROUND(MAX(0,B16-F16-D16),2)) | K16: =IF(A16="","",ROUND(K15+F16+D16,2)) | L16: =IF(A16="","",ROUND(L15+H16,2))
A17: =IF(OR(J16<=0,J16=""),"",A16+1) | B17: =IF(A17="","",J16) | C17: =IF(A17="","",IF(B17+H17<=$B$11,ROUND(B17+H17,2),ROUND($B$11,2))) | D17: =IF(A17="","",MAX(0,ROUND(MIN($B$12,B17-F17),2))) | E17: =IF(A17="","",ROUND(C17+D17,2)) | F17: =IF(A17="","",ROUND(C17-H17,2)) | G17: =IF(A17="","",IF($B$7="Daily",I17-I16,"")) | H17: =IF(A17="","",IF($B$7="Daily",ROUND(B17*($B$6/365)*G17,2),ROUND(B17*($B$6/$B$9),2))) | I17: =IF(A17="","",IF($B$7="Daily",EOMONTH(I16,1),EDATE($B$10,A17-1))) | J17: =IF(A17="","",ROUND(MAX(0,B17-F17-D17),2)) | K17: =IF(A17="","",ROUND(K16+F17+D17,2)) | L17: =IF(A17="","",ROUND(L16+H17,2))
A18: =IF(OR(J17<=0,J17=""),"",A17+1) | B18: =IF(A18="","",J17) | C18: =IF(A18="","",IF(B18+H18<=$B$11,ROUND(B18+H18,2),ROUND($B$11,2))) | D18: =IF(A18="","",MAX(0,ROUND(MIN($B$12,B18-F18),2))) | E18: =IF(A18="","",ROUND(C18+D18,2)) | F18: =IF(A18="","",ROUND(C18-H18,2)) | G18: =IF(A18="","",IF($B$7="Daily",I18-I17,"")) | H18: =IF(A18="","",IF($B$7="Daily",ROUND(B18*($B$6/365)*G18,2),ROUND(B18*($B$6/$B$9),2))) | I18: =IF(A18="","",IF($B$7="Daily",EOMONTH(I17,1),EDATE($B$10,A18-1))) | J18: =IF(A18="","",ROUND(MAX(0,B18-F18-D18),2)) | K18: =IF(A18="","",ROUND(K17+F18+D18,2)) | L18: =IF(A18="","",ROUND(L17+H18,2))
A19: =IF(OR(J18<=0,J18=""),"",A18+1) | B19: =IF(A19="","",J18) | C19: =IF(A19="","",IF(B19+H19<=$B$11,ROUND(B19+H19,2),ROUND($B$11,2))) | D19: =IF(A19="","",MAX(0,ROUND(MIN($B$12,B19-F19),2))) | E19: =IF(A19="","",ROUND(C19+D19,2)) | F19: =IF(A19="","",ROUND(C19-H19,2)) | G19: =IF(A19="","",IF($B$7="Daily",I19-I18,"")) | H19: =IF(A19="","",IF($B$7="Daily",ROUND(B19*($B$6/365)*G19,2),ROUND(B19*($B$6/$B$9),2))) | I19: =IF(A19="","",IF($B$7="Daily",EOMONTH(I18,1),EDATE($B$10,A19-1))) | J19: =IF(A19="","",ROUND(MAX(0,B19-F19-D19),2)) | K19: =IF(A19="","",ROUND(K18+F19+D19,2)) | L19: =IF(A19="","",ROUND(L18+H19,2))
A20: =IF(OR(J19<=0,J19=""),"",A19+1) | B20: =IF(A20="","",J19) | C20: =IF(A20="","",IF(B20+H20<=$B$11,ROUND(B20+H20,2),ROUND($B$11,2))) | D20: =IF(A20="","",MAX(0,ROUND(MIN($B$12,B20-F20),2))) | E20: =IF(A20="","",ROUND(C20+D20,2)) | F20: =IF(A20="","",ROUND(C20-H20,2)) | G20: =IF(A20="","",IF($B$7="Daily",I20-I19,"")) | H20: =IF(A20="","",IF($B$7="Daily",ROUND(B20*($B$6/365)*G20,2),ROUND(B20*($B$6/$B$9),2))) | I20: =IF(A20="","",IF($B$7="Daily",EOMONTH(I19,1),EDATE($B$10,A20-1))) | J20: =IF(A20="","",ROUND(MAX(0,B20-F20-D20),2)) | K20: =IF(A20="","",ROUND(K19+F20+D20,2)) | L20: =IF(A20="","",ROUND(L19+H20,2))
A21: =IF(OR(J20<=0,J20=""),"",A20+1) | B21: =IF(A21="","",J20) | C21: =IF(A21="","",IF(B21+H21<=$B$11,ROUND(B21+H21,2),ROUND($B$11,2))) | D21: =IF(A21="","",MAX(0,ROUND(MIN($B$12,B21-F21),2))) | E21: =IF(A21="","",ROUND(C21+D21,2)) | F21: =IF(A21="","",ROUND(C21-H21,2)) | G21: =IF(A21="","",IF($B$7="Daily",I21-I20,"")) | H21: =IF(A21="","",IF($B$7="Daily",ROUND(B21*($B$6/365)*G21,2),ROUND(B21*($B$6/$B$9),2))) | I21: =IF(A21="","",IF($B$7="Daily",EOMONTH(I20,1),EDATE($B$10,A21-1))) | J21: =IF(A21="","",ROUND(MAX(0,B21-F21-D21),2)) | K21: =IF(A21="","",ROUND(K20+F21+D21,2)) | L21: =IF(A21="","",ROUND(L20+H21,2))
A22: =IF(OR(J21<=0,J21=""),"",A21+1) | B22: =IF(A22="","",J21) | C22: =IF(A22="","",IF(B22+H22<=$B$11,ROUND(B22+H22,2),ROUND($B$11,2))) | D22: =IF(A22="","",MAX(0,ROUND(MIN($B$12,B22-F22),2))) | E22: =IF(A22="","",ROUND(C22+D22,2)) | F22: =IF(A22="","",ROUND(C22-H22,2)) | G22: =IF(A22="","",IF($B$7="Daily",I22-I21,"")) | H22: =IF(A22="","",IF($B$7="Daily",ROUND(B22*($B$6/365)*G22,2),ROUND(B22*($B$6/$B$9),2))) | I22: =IF(A22="","",IF($B$7="Daily",EOMONTH(I21,1),EDATE($B$10,A22-1))) | J22: =IF(A22="","",ROUND(MAX(0,B22-F22-D22),2)) | K22: =IF(A22="","",ROUND(K21+F22+D22,2)) | L22: =IF(A22="","",ROUND(L21+H22,2))
A23: =IF(OR(J22<=0,J22=""),"",A22+1) | B23: =IF(A23="","",J22) | C23: =IF(A23="","",IF(B23+H23<=$B$11,ROUND(B23+H23,2),ROUND($B$11,2))) | D23: =IF(A23="","",MAX(0,ROUND(MIN($B$12,B23-F23),2))) | E23: =IF(A23="","",ROUND(C23+D23,2)) | F23: =IF(A23="","",ROUND(C23-H23,2)) | G23: =IF(A23="","",IF($B$7="Daily",I23-I22,"")) | H23: =IF(A23="","",IF($B$7="Daily",ROUND(B23*($B$6/365)*G23,2),ROUND(B23*($B$6/$B$9),2))) | I23: =IF(A23="","",IF($B$7="Daily",EOMONTH(I22,1),EDATE($B$10,A23-1))) | J23: =IF(A23="","",ROUND(MAX(0,B23-F23-D23),2)) | K23: =IF(A23="","",ROUND(K22+F23+D23,2)) | L23: =IF(A23="","",ROUND(L22+H23,2))
A24: =IF(OR(J23<=0,J23=""),"",A23+1) | B24: =IF(A24="","",J23) | C24: =IF(A24="","",IF(B24+H24<=$B$11,ROUND(B24+H24,2),ROUND($B$11,2))) | D24: =IF(A24="","",MAX(0,ROUND(MIN($B$12,B24-F24),2))) | E24: =IF(A24="","",ROUND(C24+D24,2)) | F24: =IF(A24="","",ROUND(C24-H24,2)) | G24: =IF(A24="","",IF($B$7="Daily",I24-I23,"")) | H24: =IF(A24="","",IF($B$7="Daily",ROUND(B24*($B$6/365)*G24,2),ROUND(B24*($B$6/$B$9),2))) | I24: =IF(A24="","",IF($B$7="Daily",EOMONTH(I23,1),EDATE($B$10,A24-1))) | J24: =IF(A24="","",ROUND(MAX(0,B24-F24-D24),2)) | K24: =IF(A24="","",ROUND(K23+F24+D24,2)) | L24: =IF(A24="","",ROUND(L23+H24,2))
A25: =IF(OR(J24<=0,J24=""),"",A24+1) | B25: =IF(A25="","",J24) | C25: =IF(A25="","",IF(B25+H25<=$B$11,ROUND(B25+H25,2),ROUND($B$11,2))) | D25: =IF(A25="","",MAX(0,ROUND(MIN($B$12,B25-F25),2))) | E25: =IF(A25="","",ROUND(C25+D25,2)) | F25: =IF(A25="","",ROUND(C25-H25,2)) | G25: =IF(A25="","",IF($B$7="Daily",I25-I24,"")) | H25: =IF(A25="","",IF($B$7="Daily",ROUND(B25*($B$6/365)*G25,2),ROUND(B25*($B$6/$B$9),2))) | I25: =IF(A25="","",IF($B$7="Daily",EOMONTH(I24,1),EDATE($B$10,A25-1))) | J25: =IF(A25="","",ROUND(MAX(0,B25-F25-D25),2)) | K25: =IF(A25="","",ROUND(K24+F25+D25,2)) | L25: =IF(A25="","",ROUND(L24+H25,2))
A26: =IF(OR(J25<=0,J25=""),"",A25+1) | B26: =IF(A26="","",J25) | C26: =IF(A26="","",IF(B26+H26<=$B$11,ROUND(B26+H26,2),ROUND($B$11,2))) | D26: =IF(A26="","",MAX(0,ROUND(MIN($B$12,B26-F26),2))) | E26: =IF(A26="","",ROUND(C26+D26,2)) | F26: =IF(A26="","",ROUND(C26-H26,2)) | G26: =IF(A26="","",IF($B$7="Daily",I26-I25,"")) | H26: =IF(A26="","",IF($B$7="Daily",ROUND(B26*($B$6/365)*G26,2),ROUND(B26*($B$6/$B$9),2))) | I26: =IF(A26="","",IF($B$7="Daily",EOMONTH(I25,1),EDATE($B$10,A26-1))) | J26: =IF(A26="","",ROUND(MAX(0,B26-F26-D26),2)) | K26: =IF(A26="","",ROUND(K25+F26+D26,2)) | L26: =IF(A26="","",ROUND(L25+H26,2))
A27: =IF(OR(J26<=0,J26=""),"",A26+1) | B27: =IF(A27="","",J26) | C27: =IF(A27="","",IF(B27+H27<=$B$11,ROUND(B27+H27,2),ROUND($B$11,2))) | D27: =IF(A27="","",MAX(0,ROUND(MIN($B$12,B27-F27),2))) | E27: =IF(A27="","",ROUND(C27+D27,2)) | F27: =IF(A27="","",ROUND(C27-H27,2)) | G27: =IF(A27="","",IF($B$7="Daily",I27-I26,"")) | H27: =IF(A27="","",IF($B$7="Daily",ROUND(B27*($B$6/365)*G27,2),ROUND(B27*($B$6/$B$9),2))) | I27: =IF(A27="","",IF($B$7="Daily",EOMONTH(I26,1),EDATE($B$10,A27-1))) | J27: =IF(A27="","",ROUND(MAX(0,B27-F27-D27),2)) | K27: =IF(A27="","",ROUND(K26+F27+D27,2)) | L27: =IF(A27="","",ROUND(L26+H27,2))
... A74: =IF(OR(J73<=0,J73=""),"",A73+1) | B74: =IF(A74="","",J73) | C74: =IF(A74="","",IF(B74+H74<=$B$11,ROUND(B74+H74,2),ROUND($B$11,2))) | D74: =IF(A74="","",MAX(0,ROUND(MIN($B$12,B74-F74),2))) | E74: =IF(A74="","",ROUND(C74+D74,2)) | F74: =IF(A74="","",ROUND(C74-H74,2)) | G74: =IF(A74="","",IF($B$7="Daily",I74-I73,"")) | H74: =IF(A74="","",IF($B$7="Daily",ROUND(B74*($B$6/365)*G74,2),ROUND(B74*($B$6/$B$9),2))) | I74: =IF(A74="","",IF($B$7="Daily",EOMONTH(I73,1),EDATE($B$10,A74-1))) | J74: =IF(A74="","",ROUND(MAX(0,B74-F74-D74),2)) | K74: =IF(A74="","",ROUND(K73+F74+D74,2)) | L74: =IF(A74="","",ROUND(L73+H74,2))
