Workbook
Name ActualNumberOfPayments: IFERROR(IF('HOA Savings'!LoanIsGood,IF('HOA Savings'!PaymentsPerYear=1,1,MATCH(0.01,'HOA Savings'!End_Bal,-1)+1)),"")
Name ActualNumberOfPayments: IFERROR(IF(LoanIsGood,IF(PaymentsPerYear=1,1,MATCH(0.01,End_Bal,-1)+1)),"")
Name ColumnTitle1: #REF!
Name ColumnTitle1: #REF!
Name End_Bal: #REF!
Name End_Bal: #REF!
Name ExtraPayments: #REF!
Name ExtraPayments: #REF!
Name InterestRate: #REF!
Name InterestRate: #REF!
Name IQ_CH: 110000
Name IQ_CQ: 5000
Name IQ_CY: 10000
Name IQ_DAILY: 500000
Name IQ_FH: 100000
Name IQ_FQ: 500
Name IQ_FY: 1000
Name IQ_LTM: 2000
Name IQ_MONTH: 15000
Name IQ_NTM: 6000
Name IQ_WEEK: 50000
Name IQ_YTD: 3000
Name LastCol: MATCH(REPT("z",255),#REF!)
Name LastCol: MATCH(REPT("z",255),#REF!)
Name LastRow: MATCH(9.99E+307,#REF!)
Name LastRow: MATCH(9.99E+307,#REF!)
Name LenderName: #REF!
Name LenderName: #REF!
Name LoanAmount: #REF!
Name LoanAmount: #REF!
Name LoanIsGood: (#REF!*#REF!*#REF!*#REF!)>0
Name LoanIsGood: (#REF!*#REF!*#REF!*#REF!)>0
Name LoanPeriod: #REF!
Name LoanPeriod: #REF!
Name LoanStartDate: #REF!
Name LoanStartDate: #REF!
Name PaymentsPerYear: #REF!
Name PaymentsPerYear: #REF!
Name PrintArea_SET: OFFSET(#REF!,,,'HOA Savings'!LastRow,'HOA Savings'!LastCol)
Name PrintArea_SET: OFFSET(#REF!,,,LastRow,LastCol)
Name roundOpt: #REF!
Name roundOpt: #REF!
Name RowTitleRegion1..E9: #REF!
Name RowTitleRegion1..E9: #REF!
Name RowTitleRegion2..I7: #REF!
Name RowTitleRegion2..I7: #REF!
Name RowTitleRegion3..E9: #REF!
Name RowTitleRegion3..E9: #REF!
Name RowTitleRegion4..H9: #REF!
Name RowTitleRegion4..H9: #REF!
Name ScheduledNumberOfPayments: #REF!
Name ScheduledNumberOfPayments: #REF!
Name ScheduledPayment: #REF!
Name ScheduledPayment: #REF!
Name TotalEarlyPayments: SUM(#REF!)
Name TotalEarlyPayments: SUM(#REF!)
Name TotalInterest: SUM(#REF!)
Name TotalInterest: SUM(#REF!)
Name valuevx: 42.314159

Sheet Main Budget
B1: Jon Kemp Personal Budget Plan: Bi-weekly
B5: Monthly Expenses
E6: Monthly | F6: Gym Portion | G6: Gym Portion Per Paycheck (Bi-Weekly) | H6: Jon Portion | I6: Jon Portion Per Pay Check (15th and Last Day of month) | J6: Account | K6: Payment Date | L6: Debit/Credit | M6: Payment Source | N6: Notes
B7: Cell Phone Service | E7: -30 | F7: 0 | G7: 0 | H7: =E7-F7 -> -30 | I7: =H7/2 -> -15 | J7: USAA Bills | K7: 15 | L7: Debit | M7: Wells Fargo Credit | N7: Auto Pay set for 17th of each month.
B8: Gym Membership | E8: -44.99 | F8: =-(11.25*2) -> -22.5 | G8: -11.25 | H8: =E8-F8 -> -22.49 | I8: =H8/2 -> -11.245 | J8: USAA Bills | K8: 17 | L8: Debit | M8: Bank of America VISA | N8: Auto Pay set for 18th of each month.
D9: Extra to Bill checking | E9: -13.84 | F9: 0 | G9: 0 | H9: =E9-F9 -> -13.84 | I9: =E9/2 -> -6.92 | L9: Credit
B10: Insurance (Vehicle) | E10: =(-622*2)/12 -> -103.66667 | F10: 0 | G10: 0 | H10: =E10-F10 -> -103.66667 | I10: =E10/2 -> -51.833333 | J10: USAA Bills | K10: Semi Annual | L10: Debit | N10: $622 Due July 1 and Jan 1
E11: =SUM(E7:E10) -> -192.49667 | F11: =SUM(F7:F10) -> -22.5 | G11: =SUM(G7:G10) -> -11.25 | H11: =SUM(H7:H10) -> -169.99667 | I11: =SUM(I7:I10) -> -84.998333
E13: Monthly | F13: Ronnie Portion | H13: Jon Portion | I13: Per Pay Check | J13: Account | K13: Payment Date | L13: Debit/Credit | M13: Payment Source | O13: Notes
B14: Emory Parc - HOA Dues | E14: =-((2350+3.95)/6) -> -392.325 | F14: =(E14/2) -> -196.1625 | H14: =E14/2 -> -196.1625 | I14: =H14/2 -> -98.08125 | J14: USAA HOA Savings | K14: Jan 8, July 8 | L14: Debit | M14: USAA HOA Savings | O14: Paid Semi Annual
B15: Emory Parc - HOA Extra Payments | E15: -50 | F15: =E15/2 -> -25 | H15: =E15/2 -> -25 | I15: =H15/2 -> -12.5 | J15: USAA HOA Savings | L15: Credit
B16: Mortgage - Extra Payments for Random Expenses | E16: =-3200-SUM(E14:E15)-SUM(E17:E22) -> -312.465 | F16: =E16/2 -> -156.2325 | H16: =E16/2 -> -156.2325 | I16: =H16/2 -> -78.11625 | J16: USAA Mortgage | L16: Credit
B17: Emory Parc - Mortgage | E17: -2036.51 | F17: =E17/2 -> -1018.255 | H17: =E17/2 -> -1018.255 | I17: =H17/2 -> -509.1275 | J17: USAA Mortgage | K17: 7 | L17: Debit | M17: Auto Pay Mortgage Checking
B18: Youtube TV Zack | E18: -36.5 | F18: =E18/2 -> -18.25 | H18: =E18/2 -> -18.25 | I18: =H18/2 -> -9.125 | J18: USAA Mortgage | K18: 9 | L18: Debit | M18: Mortgage Checking | O18: Must Pay via ZELLE to Zack
B19: Water/Sewer | E19: -70 | F19: =E19/2 -> -35 | H19: =E19/2 -> -35 | I19: =H19/2 -> -17.5 | J19: USAA Mortgage | K19: 3 | L19: Debit | M19: Mortgage Checking | O19: Must pay through USAA bill Pay
B20: Georgia Power - Electricity | E20: -175 | F20: =E20/2 -> -87.5 | H20: =E20/2 -> -87.5 | I20: =H20/2 -> -43.75 | J20: USAA Mortgage | K20: 1 | L20: Debit | M20: Mortgage Checking | O20: Auto Pay from USAA Mortgage Checking
B21: Natural Gas | E21: -76 | F21: =E21/2 -> -38 | H21: =E21/2 -> -38 | I21: =H21/2 -> -19 | J21: USAA Mortgage | K21: 26 | L21: Debit | M21: Mortgage Checking | O21: Auto Pay set for 1st of each Month
B22: Comcast Cable | E22: -51.2 | F22: =E22/2 -> -25.6 | H22: =E22/2 -> -25.6 | I22: =H22/2 -> -12.8 | J22: USAA Mortgage | K22: 12 | L22: Debit | M22: Mortgage Checking | O22: Auto Pay set for 11th of each Month
E23: =F23+H23 -> -3200 | F23: =(SUM(F14:F22)) -> -1600 | H23: =SUM(H14:H22) -> -1600 | I23: =SUM(I14:I22) -> -800
B25: Total Expenses | E25: =E23+E11 -> -3392.4967 | I25: =I23+I11 -> -884.99833
D28: Ronnie Portion | E28: Jon Portion (Per Paycheck) | F28: Gym Portion (Bi Weekly)
B29: Amount To USAA Bill Checking - 7071 | D29: 0 | E29: =-I11 -> 84.998333 | F29: 11.25
B30: Amount to USAA Mortgage Checking - 3223 | D30: =-SUM(F16:F22) -> 1378.8375 | E30: =-SUM(I16:I22) -> 689.41875 | F30: 0
B31: Amount To USAA HOA Savings - 9575 | D31: =-F14-F15 -> 221.1625 | E31: =-I14-I15 -> 110.58125 | F31: 0
D32: =SUM(D29:D31) -> 1600 | E32: =SUM(E29:E31) -> 884.99833 | F32: =SUM(F29:F31) -> 11.25

Sheet Mortgage Checking
A1: Date | B1: Total Beg Balance | C1: Regular Beg Balance | D1: Extra Beg Balance | E1: Jon Credit | F1: Ronnie Credit | G1: Jon Extra Credit | H1: Ronnie Extra Credit | I1: Mortgage | J1: Water (GA Utility) (AutoPay Checking) | K1: Electric: Georgia Power (AutoPay Checking) | L1: Natural Gas (AutoPay Checking : Energy Inc Geo) | M1: Comcast (AutoPay Checking) | N1: YouTube TV (Zelle to Zack) | O1: Other $ | P1: Regular Ending Balance | Q1: Extra Ending Balance | R1: Total End Balance | S1: Other Description
A2: 46022 | B2: 2591.06 | C2: 0 | E2: 0 | F2: 0 | I2: 0 | J2: 0 | K2: 0 | L2: 0 | M2: 0 | N2: 0 | P2: 1861.9725 | Q2: 729.085 | R2: 2591.0575
A3: 46023 | B3: =R2 -> 2591.0575 | C3: 0 | E3: 0 | F3: 0 | I3: 0 | J3: 0 | K3: -175 | L3: 0 | M3: 0 | N3: 0 | P3: 1861.9725 | Q3: 729.085 | R3: 2591.0575
A4: 46024 | B4: =R3 -> 2591.0575 | C4: 0 | E4: 0 | F4: 0 | I4: 0 | J4: 0 | K4: 0 | L4: 0 | M4: 0 | N4: 0 | P4: 1861.9725 | Q4: 729.085 | R4: 2591.0575
A5: 46025 | B5: =R4 -> 2591.0575 | C5: 0 | E5: 0 | F5: 0 | I5: 0 | J5: -78.34 | K5: 0 | L5: 0 | M5: 0 | N5: 0 | P5: 1861.9725 | Q5: 729.085 | R5: 2591.0575
A6: 46026 | B6: =R5 -> 2591.0575 | C6: 0 | E6: 0 | F6: 0 | I6: 0 | J6: 0 | K6: 0 | L6: 0 | M6: 0 | N6: 0 | P6: 1861.9725 | Q6: 729.085 | R6: 2591.0575
A7: 46027 | B7: =R6 -> 2591.0575 | C7: 0 | E7: 0 | F7: 0 | I7: 0 | J7: 0 | K7: 0 | L7: 0 | M7: 0 | N7: -36.5 | P7: 1861.9725 | Q7: 729.085 | R7: 2591.0575
A8: 46028 | B8: =R7 -> 2591.0575 | C8: 0 | E8: 0 | F8: 0 | I8: 0 | J8: 0 | K8: 0 | L8: 0 | M8: 0 | N8: 0 | P8: 1861.9725 | Q8: 729.085 | R8: 2591.0575
A9: 46029 | B9: =R8 -> 2591.0575 | C9: 0 | E9: 0 | F9: 0 | I9: -2036.51 | J9: 0 | K9: 0 | L9: 0 | M9: 0 | N9: 0 | P9: 1861.9725 | Q9: 729.085 | R9: 2591.0575
A10: 46030 | B10: =R9 -> 2591.0575 | C10: 0 | E10: 0 | F10: 0 | I10: 0 | J10: 0 | K10: 0 | L10: 0 | M10: 0 | N10: 0 | P10: 1861.9725 | Q10: 729.085 | R10: 2591.0575
A11: 46031 | B11: =R10 -> 2591.0575 | C11: 0 | E11: 0 | F11: 0 | I11: 0 | J11: 0 | K11: 0 | L11: 0 | M11: 0 | N11: 0 | P11: 1861.9725 | Q11: 729.085 | R11: 2591.0575
A12: 46032 | B12: =R11 -> 2591.0575 | C12: 0 | E12: 0 | F12: 0 | I12: 0 | J12: 0 | K12: 0 | L12: 0 | M12: 0 | N12: 0 | P12: 1861.9725 | Q12: 729.085 | R12: 2591.0575
A13: 46033 | B13: =R12 -> 2591.0575 | C13: 0 | E13: 0 | F13: 0 | I13: 0 | J13: 0 | K13: 0 | L13: 0 | M13: 0 | N13: 0 | P13: 1861.9725 | Q13: 729.085 | R13: 2591.0575
A14: 46034 | B14: =R13 -> 2591.0575 | C14: 0 | E14: 0 | F14: 0 | I14: 0 | J14: 0 | K14: 0 | L14: 0 | M14: -51.2 | N14: 0 | P14: 1861.9725 | Q14: 729.085 | R14: 2591.0575
... A20: 46040 | B20: =R19 -> 2591.0575 | C20: 0 | E20: 0 | F20: 0 | I20: 0 | J20: 0 | K20: 0 | L20: 0 | M20: 0 | N20: 0 | P20: 1861.9725 | Q20: 729.085 | R20: 2591.0575
A21: 46041 | B21: =R20 -> 2591.0575 | C21: 0 | E21: 0 | F21: 0 | I21: 0 | J21: 0 | K21: 0 | L21: 0 | M21: 0 | N21: 0 | O21: 0.02 | P21: 1861.9725 | Q21: 729.085 | R21: 2591.0575
A22: 46042 | B22: =R21 -> 2591.0575 | C22: 0 | E22: 0 | F22: 0 | I22: 0 | J22: 0 | K22: 0 | L22: 0 | M22: 0 | N22: 0 | P22: 1861.9725 | Q22: 729.085 | R22: 2591.0575
A23: 46043 | B23: =R22 -> 2591.0575 | C23: 0 | E23: 0 | F23: 0 | I23: 0 | J23: 0 | K23: 0 | L23: 0 | M23: 0 | N23: 0 | P23: 1861.9725 | Q23: 729.085 | R23: 2591.0575
A24: 46044 | B24: =R23 -> 2591.0575 | C24: 0 | E24: 0 | F24: 0 | I24: 0 | J24: 0 | K24: 0 | L24: 0 | M24: 0 | N24: 0 | P24: 1861.9725 | Q24: 729.085 | R24: 2591.0575
A25: 46045 | B25: =R24 -> 2591.0575 | C25: 0 | E25: 0 | F25: 0 | I25: 0 | J25: 0 | K25: 0 | L25: 0 | M25: 0 | N25: 0 | P25: 1861.9725 | Q25: 729.085 | R25: 2591.0575
A26: 46046 | B26: =R25 -> 2591.0575 | C26: 0 | E26: 0 | F26: 0 | I26: 0 | J26: 0 | K26: 0 | L26: 0 | M26: 0 | N26: 0 | P26: 1861.9725 | Q26: 729.085 | R26: 2591.0575
A27: 46047 | B27: =R26 -> 2591.0575 | C27: 0 | E27: 0 | F27: 0 | I27: 0 | J27: 0 | K27: 0 | L27: 0 | M27: 0 | N27: 0 | P27: 1861.9725 | Q27: 729.085 | R27: 2591.0575
A28: 46048 | B28: =R27 -> 2591.0575 | C28: 0 | E28: 0 | F28: 0 | I28: 0 | J28: 0 | K28: 0 | L28: -57.89 | M28: 0 | N28: 0 | P28: 1861.9725 | Q28: 729.085 | R28: 2591.0575
A29: 46049 | B29: =R28 -> 2591.0575 | C29: 0 | E29: 0 | F29: 1378 | I29: 0 | J29: 0 | K29: 0 | L29: 0 | M29: 0 | N29: 0 | P29: 1861.9725 | Q29: 729.085 | R29: 2591.0575
A30: 46050 | B30: =R29 -> 2591.0575 | C30: 0 | E30: 0 | F30: 0 | I30: 0 | J30: 0 | K30: 0 | L30: 0 | M30: 0 | N30: 0 | P30: 1861.9725 | Q30: 729.085 | R30: 2591.0575
A31: 46051 | B31: =R30 -> 2591.0575 | C31: 0 | E31: 0 | F31: 0 | I31: 0 | J31: 0 | K31: 0 | L31: 0 | M31: 0 | N31: 0 | P31: 1861.9725 | Q31: 729.085 | R31: 2591.0575
A32: 46052 | B32: =R31 -> 2591.0575 | C32: 0 | E32: 689 | F32: 0 | I32: 0 | J32: 0 | K32: 0 | L32: 0 | M32: 0 | N32: 0 | P32: 1861.9725 | Q32: 729.085 | R32: 2591.0575
A33: 46053 | B33: =R32 -> 2591.0575 | C33: 0 | E33: 0 | F33: 0 | I33: 0 | J33: 0 | K33: 0 | L33: 0 | M33: 0 | N33: 0 | P33: 1861.9725 | Q33: 729.085 | R33: 2591.0575
A34: 46054 | B34: =R33 -> 2591.0575 | C34: 0 | E34: 0 | F34: 0 | I34: 0 | J34: 0 | K34: -175 | L34: 0 | M34: 0 | N34: 0 | P34: 1861.9725 | Q34: 729.085 | R34: 2591.0575
A35: 46055 | B35: =R34 -> 2591.0575 | C35: 2328.4625 | D35: 1300 | E35: 0 | F35: 0 | I35: 0 | J35: 0 | K35: 0 | L35: 0 | M35: 0 | N35: 0 | P35: 2328.4625 | Q35: 1300 | R35: 3628.4625
A36: 46056 | B36: =R35 -> 3628.4625 | C36: =P35 -> 2328.4625 | D36: =Q35 -> 1300 | E36: 0 | F36: 0 | G36: 0 | H36: 0 | I36: 0 | J36: -81.97 | K36: 0 | L36: 0 | M36: 0 | N36: 0 | P36: =C36+(SUM(I36:N36)+(SUM(E36:F36))) -> 2246.4925 | Q36: =D36+G36+H36+O36 -> 1300 | R36: =P36+Q36 -> 3546.4925
A37: 46057 | B37: =R36 -> 3546.4925 | C37: =P36 -> 2246.4925 | D37: =Q36 -> 1300 | E37: 0 | F37: 0 | G37: 0 | H37: 0 | I37: 0 | J37: 0 | K37: 0 | L37: 0 | M37: 0 | N37: 0 | P37: =C37+(SUM(I37:N37)+(SUM(E37:F37))) -> 2246.4925 | Q37: =D37+G37+H37+O37 -> 1300 | R37: =P37+Q37 -> 3546.4925
A38: 46058 | B38: =R37 -> 3546.4925 | C38: =P37 -> 2246.4925 | D38: =Q37 -> 1300 | E38: 0 | F38: 0 | G38: 0 | H38: 0 | I38: 0 | J38: 0 | K38: 0 | L38: 0 | M38: 0 | N38: 0 | P38: =C38+(SUM(I38:N38)+(SUM(E38:F38))) -> 2246.4925 | Q38: =D38+G38+H38+O38 -> 1300 | R38: =P38+Q38 -> 3546.4925
A39: 46059 | B39: =R38 -> 3546.4925 | C39: =P38 -> 2246.4925 | D39: =Q38 -> 1300 | E39: 0 | F39: 0 | G39: 0 | H39: 0 | I39: 0 | J39: 0 | K39: 0 | L39: 0 | M39: 0 | N39: 0 | P39: =C39+(SUM(I39:N39)+(SUM(E39:F39))) -> 2246.4925 | Q39: =D39+G39+H39+O39 -> 1300 | R39: =P39+Q39 -> 3546.4925
A40: 46060 | B40: =R39 -> 3546.4925 | C40: =P39 -> 2246.4925 | D40: =Q39 -> 1300 | E40: 0 | F40: 0 | G40: 0 | H40: 0 | I40: -2036.51 | J40: 0 | K40: 0 | L40: 0 | M40: 0 | N40: 0 | P40: =C40+(SUM(I40:N40)+(SUM(E40:F40))) -> 209.9825 | Q40: =D40+G40+H40+O40 -> 1300 | R40: =P40+Q40 -> 1509.9825
A41: 46061 | B41: =R40 -> 1509.9825 | C41: =P40 -> 209.9825 | D41: =Q40 -> 1300 | E41: 0 | F41: 0 | G41: 0 | H41: 0 | I41: 0 | J41: 0 | K41: 0 | L41: 0 | M41: 0 | N41: 0 | P41: =C41+(SUM(I41:N41)+(SUM(E41:F41))) -> 209.9825 | Q41: =D41+G41+H41+O41 -> 1300 | R41: =P41+Q41 -> 1509.9825
A42: 46062 | B42: =R41 -> 1509.9825 | C42: =P41 -> 209.9825 | D42: =Q41 -> 1300 | E42: 0 | F42: 0 | G42: 0 | H42: 0 | I42: 0 | J42: 0 | K42: 0 | L42: 0 | M42: 0 | N42: 0 | P42: =C42+(SUM(I42:N42)+(SUM(E42:F42))) -> 209.9825 | Q42: =D42+G42+H42+O42 -> 1300 | R42: =P42+Q42 -> 1509.9825
A43: 46063 | B43: =R42 -> 1509.9825 | C43: =P42 -> 209.9825 | D43: =Q42 -> 1300 | E43: 0 | F43: 0 | G43: 0 | H43: 0 | I43: 0 | J43: 0 | K43: 0 | L43: 0 | M43: 0 | N43: 0 | P43: =C43+(SUM(I43:N43)+(SUM(E43:F43))) -> 209.9825 | Q43: =D43+G43+H43+O43 -> 1300 | R43: =P43+Q43 -> 1509.9825
A44: 46064 | B44: =R43 -> 1509.9825 | C44: =P43 -> 209.9825 | D44: =Q43 -> 1300 | E44: 0 | F44: 0 | G44: 0 | H44: 0 | I44: 0 | J44: 0 | K44: 0 | L44: 0 | M44: 0 | N44: 0 | P44: =C44+(SUM(I44:N44)+(SUM(E44:F44))) -> 209.9825 | Q44: =D44+G44+H44+O44 -> 1300 | R44: =P44+Q44 -> 1509.9825
A45: 46065 | B45: =R44 -> 1509.9825 | C45: =P44 -> 209.9825 | D45: =Q44 -> 1300 | E45: 0 | F45: 0 | G45: 0 | H45: 0 | I45: 0 | J45: 0 | K45: 0 | L45: 0 | M45: -51.2 | N45: 0 | P45: =C45+(SUM(I45:N45)+(SUM(E45:F45))) -> 158.7825 | Q45: =D45+G45+H45+O45 -> 1300 | R45: =P45+Q45 -> 1458.7825
...

Sheet HOA Savings
E1: Credits | I1: Outgoing Payments (Debits)
A2: Date | B2: Total Beg Balance | C2: Regular Beg Balance | D2: Extra Beg Balance | E2: Jon Credit | F2: Ronnie Credit | G2: Jon Extra Credit | H2: Ronnie Extra Credit | I2: HOA Payment | K2: Other $ (Credit or Debit) | L2: Regular Ending Balance | M2: Extra Ending Balance | N2: Total Ending Balance | O2: Other Explination
A3: 46022 | B3: 2791.0332 | C3: 2177.21 | D3: 613.82317 | E3: 0 | F3: 0 | G3: 0 | H3: 0 | L3: 2177.21 | M3: 613.82317 | N3: 2791.0332
A4: 46023 | B4: 2791.0332 | C4: 2177.21 | D4: 613.82317 | E4: 0 | F4: 197 | G4: 0 | H4: 25 | L4: 2374.21 | M4: 638.82317 | N4: 3013.0332
A5: 46024 | B5: 3013.0332 | C5: 2374.21 | D5: 638.82317 | E5: 0 | F5: 0 | G5: 0 | H5: 0 | L5: 2374.21 | M5: 638.82317 | N5: 3013.0332
A6: 46025 | B6: 3013.0332 | C6: 2374.21 | D6: 638.82317 | E6: 0 | F6: 0 | G6: 0 | H6: 0 | K6: 0.02 | L6: 2374.23 | M6: 638.82317 | N6: 3013.0532
A7: 46026 | B7: 3013.0532 | C7: 2374.23 | D7: 638.82317 | E7: 0 | F7: 0 | G7: 0 | H7: 0 | L7: 2374.23 | M7: 638.82317 | N7: 3013.0532
A8: 46027 | B8: 3013.0532 | C8: 2374.23 | D8: 638.82317 | E8: 0 | F8: 0 | G8: 0 | H8: 0 | L8: 2374.23 | M8: 638.82317 | N8: 3013.0532
A9: 46028 | B9: 3013.0532 | C9: 2374.23 | D9: 638.82317 | E9: 0 | F9: 0 | G9: 0 | H9: 0 | L9: 2374.23 | M9: 638.82317 | N9: 3013.0532
A10: 46029 | B10: 3013.0532 | C10: 2374.23 | D10: 638.82317 | E10: 0 | F10: 0 | G10: 0 | H10: 0 | I10: -2353.95 | L10: 20.28 | M10: 638.82317 | N10: 659.10317
A11: 46030 | B11: 659.10317 | C11: 20.28 | D11: 638.82317 | E11: 0 | F11: 0 | G11: 0 | H11: 0 | L11: 20.28 | M11: 638.82317 | N11: 659.10317
A12: 46031 | B12: 659.10317 | C12: 20.28 | D12: 638.82317 | E12: 0 | F12: 0 | G12: 0 | H12: 0 | L12: 20.28 | M12: 638.82317 | N12: 659.10317
A13: 46032 | B13: 659.10317 | C13: 20.28 | D13: 638.82317 | E13: 0 | F13: 0 | G13: 0 | H13: 0 | L13: 20.28 | M13: 638.82317 | N13: 659.10317
A14: 46033 | B14: 659.10317 | C14: 20.28 | D14: 638.82317 | E14: 0 | F14: 0 | G14: 0 | H14: 0 | L14: 20.28 | M14: 638.82317 | N14: 659.10317
A15: 46034 | B15: 659.10317 | C15: 20.28 | D15: 638.82317 | E15: 0 | F15: 0 | G15: 0 | H15: 0 | L15: 20.28 | M15: 638.82317 | N15: 659.10317
A16: 46035 | B16: 659.10317 | C16: 20.28 | D16: 638.82317 | E16: 0 | F16: 0 | G16: 0 | H16: 0 | L16: 20.28 | M16: 638.82317 | N16: 659.10317
A17: 46036 | B17: 659.10317 | C17: 20.28 | D17: 638.82317 | E17: 98.5 | F17: 0 | G17: 12.5 | H17: 0 | L17: 118.78 | M17: 651.32317 | N17: 770.10317
A18: 46037 | B18: 770.10317 | C18: 118.78 | D18: 651.32317 | E18: 0 | F18: 0 | G18: 0 | H18: 0 | L18: 118.78 | M18: 651.32317 | N18: 770.10317
A19: 46038 | B19: 770.10317 | C19: 118.78 | D19: 651.32317 | E19: 0 | F19: 0 | G19: 0 | H19: 0 | L19: 118.78 | M19: 651.32317 | N19: 770.10317
A20: 46039 | B20: 770.10317 | C20: 118.78 | D20: 651.32317 | E20: 0 | F20: 0 | G20: 0 | H20: 0 | L20: 118.78 | M20: 651.32317 | N20: 770.10317
A21: 46040 | B21: 770.10317 | C21: 118.78 | D21: 651.32317 | E21: 0 | F21: 0 | G21: 0 | H21: 0 | L21: 118.78 | M21: 651.32317 | N21: 770.10317
A22: 46041 | B22: 770.10317 | C22: 118.78 | D22: 651.32317 | E22: 0 | F22: 0 | G22: 0 | H22: 0 | L22: 118.78 | M22: 651.32317 | N22: 770.10317
... A32: 46051 | B32: 770.10317 | C32: 118.78 | D32: 651.32317 | E32: 0 | F32: 0 | G32: 0 | H32: 0 | L32: 118.78 | M32: 651.32317 | N32: 770.10317
A33: 46052 | B33: 770.10317 | C33: 118.78 | D33: 651.32317 | E33: 98.5 | F33: 0 | G33: 12.5 | H33: 0 | K33: 0.01 | L33: 217.29 | M33: 663.82317 | N33: 881.11317
A34: 46053 | B34: 881.11317 | C34: 217.29 | D34: 663.82317 | E34: 0 | F34: 0 | G34: 0 | H34: 0 | L34: 217.29 | M34: 663.82317 | N34: 881.11317
A35: 46054 | B35: 881.11317 | C35: 217.29 | D35: 663.82317 | E35: 0 | F35: 197 | G35: 0 | H35: 25 | L35: 414.29 | M35: 688.82317 | N35: 1103.1132
A36: 46055 | B36: 1103.1132 | C36: 414.29 | D36: 688.82317 | E36: 0 | F36: 0 | G36: 0 | H36: 0 | L36: 414.29 | M36: 688.82317 | N36: 1103.1132
A37: 46056 | B37: 1103.1132 | C37: 414.29 | D37: 688.82317 | E37: 0 | F37: 0 | G37: 0 | H37: 0 | L37: 414.29 | M37: 688.82317 | N37: 1103.1132
A38: 46057 | B38: 1103.1132 | C38: 414.29 | D38: 688.82317 | E38: 0 | F38: 0 | G38: 0 | H38: 0 | L38: 414.29 | M38: 688.82317 | N38: 1103.1132
A39: 46058 | B39: 1103.1132 | C39: 414.29 | D39: 688.82317 | E39: 0 | F39: 0 | G39: 0 | H39: 0 | L39: 414.29 | M39: 688.82317 | N39: 1103.1132
A40: 46059 | B40: 1103.1132 | C40: 414.29 | D40: 688.82317 | E40: 0 | F40: 0 | G40: 0 | H40: 0 | L40: 414.29 | M40: 688.82317 | N40: 1103.1132
A41: 46060 | B41: 1103.1132 | C41: 414.29 | D41: 688.82317 | E41: 0 | F41: 0 | G41: 0 | H41: 0 | L41: 414.29 | M41: 688.82317 | N41: 1103.1132
A42: 46061 | B42: 1103.1132 | C42: 414.29 | D42: 688.82317 | E42: 0 | F42: 0 | G42: 0 | H42: 0 | L42: 414.29 | M42: 688.82317 | N42: 1103.1132
A43: 46062 | B43: 1103.1132 | C43: 414.29 | D43: 688.82317 | E43: 0 | F43: 0 | G43: 0 | H43: 0 | L43: 414.29 | M43: 688.82317 | N43: 1103.1132
A44: 46063 | B44: 1103.1132 | C44: 414.29 | D44: 688.82317 | E44: 0 | F44: 0 | G44: 0 | H44: 0 | L44: 414.29 | M44: 688.82317 | N44: 1103.1132
A45: 46064 | B45: 1103.1132 | C45: 414.29 | D45: 688.82317 | E45: 0 | F45: 0 | G45: 0 | H45: 0 | L45: 414.29 | M45: 688.82317 | N45: 1103.1132
... A100: 46119 | B100: 1991.1132 | C100: 1202.29 | D100: 788.82317 | E100: 0 | F100: 0 | G100: 0 | H100: 0 | L100: 1202.29 | M100: 788.82317 | N100: 1991.1132
A101: 46120 | B101: 1991.1132 | C101: 1202.29 | D101: 788.82317 | E101: 0 | F101: 0 | G101: 0 | H101: 0 | K101: 0.02 | L101: 1202.31 | M101: 788.82317 | N101: 1991.1332
A102: 46121 | B102: 1991.1332 | C102: 1202.31 | D102: 788.82317 | E102: 0 | F102: 0 | G102: 0 | H102: 0 | L102: 1202.31 | M102: 788.82317 | N102: 1991.1332
A103: 46122 | B103: 1991.1332 | C103: 1202.31 | D103: 788.82317 | E103: 0 | F103: 0 | G103: 0 | H103: 0 | L103: 1202.31 | M103: 788.82317 | N103: 1991.1332
...

Sheet Bills Checking
E1: Credits | G1: Outgoing Payments (Debits)
A2: Date | B2: Total Beg Balance | C2: Regular Beg Balance | D2: Extra Beg Balance | E2: Jon Credit | F2: Gym Credit | G2: Cell Service | H2: Gym | I2: Insurance Payment | J2: Other $ (Credit or Debit) | K2: Regular Ending Balance | L2: Extra Ending Balance | M2: Total Ending Balance | N2: Other Explination
A3: 46022 | B3: 204.1 | C3: =B3 -> 204.1 | D3: 0 | E3: 0 | F3: 0 | G3: 0 | H3: 0 | K3: 204.1 | L3: 0 | M3: =K3+L3 -> 204.1
A4: 46023 | B4: 204.1 | C4: =K3 -> 204.1 | D4: 0 | E4: 0 | F4: 11.25 | G4: 0 | H4: 0 | K4: 215.35 | L4: 0 | M4: =K4+L4 -> 215.35
A5: 46024 | B5: 215.35 | C5: =K4 -> 215.35 | D5: 0 | E5: 0 | F5: 0 | G5: 0 | H5: 0 | K5: 215.35 | L5: 0 | M5: =K5+L5 -> 215.35
A6: 46025 | B6: 215.35 | C6: =K5 -> 215.35 | D6: 0 | E6: 0 | F6: 0 | G6: 0 | H6: 0 | K6: 215.35 | L6: 0 | M6: =K6+L6 -> 215.35
A7: 46026 | B7: 215.35 | C7: =K6 -> 215.35 | D7: 0 | E7: 0 | F7: 0 | G7: 0 | H7: 0 | K7: 215.35 | L7: 0 | M7: =K7+L7 -> 215.35
A8: 46027 | B8: 215.35 | C8: =K7 -> 215.35 | D8: 0 | E8: 0 | F8: 0 | G8: 0 | H8: 0 | K8: 215.35 | L8: 0 | M8: =K8+L8 -> 215.35
A9: 46028 | B9: 215.35 | C9: =K8 -> 215.35 | D9: 0 | E9: 0 | F9: 0 | G9: 0 | H9: 0 | K9: 215.35 | L9: 0 | M9: =K9+L9 -> 215.35
A10: 46029 | B10: 215.35 | C10: =K9 -> 215.35 | D10: 0 | E10: 0 | F10: 0 | G10: 0 | H10: 0 | K10: 215.35 | L10: 0 | M10: =K10+L10 -> 215.35
A11: 46030 | B11: 215.35 | C11: =K10 -> 215.35 | D11: 0 | E11: 0 | F11: 0 | G11: 0 | H11: 0 | K11: 215.35 | L11: 0 | M11: =K11+L11 -> 215.35
A12: 46031 | B12: 215.35 | C12: =K11 -> 215.35 | D12: 0 | E12: 0 | F12: 0 | G12: 0 | H12: 0 | K12: 215.35 | L12: 0 | M12: =K12+L12 -> 215.35
A13: 46032 | B13: 215.35 | C13: =K12 -> 215.35 | D13: 0 | E13: 0 | F13: 0 | G13: 0 | H13: 0 | K13: 215.35 | L13: 0 | M13: =K13+L13 -> 215.35
A14: 46033 | B14: 215.35 | C14: =K13 -> 215.35 | D14: 0 | E14: 0 | F14: 0 | G14: 0 | H14: 0 | K14: 215.35 | L14: 0 | M14: =K14+L14 -> 215.35
A15: 46034 | B15: 215.35 | C15: =K14 -> 215.35 | D15: 0 | E15: 0 | F15: 0 | G15: 0 | H15: 0 | K15: 215.35 | L15: 0 | M15: =K15+L15 -> 215.35
... A178: 46197 | B178: 824.16 | C178: =K177 -> 824.16 | D178: 0 | E178: 0 | F178: 0 | G178: 0 | H178: 0 | K178: 824.16 | L178: 0 | M178: =K178+L178 -> 824.16
A179: 46198 | B179: 824.16 | C179: =K178 -> 824.16 | D179: 0 | E179: 0 | F179: 0 | G179: 0 | H179: 0 | I179: -622 | K179: 202.16 | L179: 0 | M179: =K179+L179 -> 202.16 | N179: Car Insurance
A180: 46199 | B180: 202.16 | C180: =K179 -> 202.16 | D180: 0 | E180: 0 | F180: 0 | G180: 0 | H180: 0 | K180: 202.16 | L180: 0 | M180: =K180+L180 -> 202.16
A181: 46200 | B181: 202.16 | C181: =K180 -> 202.16 | D181: 0 | E181: 0 | F181: 0 | G181: 0 | H181: 0 | K181: 202.16 | L181: 0 | M181: =K181+L181 -> 202.16
A182: 46201 | B182: 202.16 | C182: =K181 -> 202.16 | D182: 0 | E182: 0 | F182: 0 | G182: 0 | H182: 0 | K182: 202.16 | L182: 0 | M182: =K182+L182 -> 202.16
A183: 46202 | B183: 202.16 | C183: =K182 -> 202.16 | D183: 0 | E183: 85 | F183: 0 | G183: 0 | H183: 0 | K183: 287.16 | L183: 0 | M183: =K183+L183 -> 287.16
A184: 46203 | B184: 287.16 | C184: =K183 -> 287.16 | D184: 0 | E184: 0 | F184: 0 | G184: 0 | H184: 0 | K184: 287.16 | L184: 0 | M184: =K184+L184 -> 287.16
A185: 46204 | B185: 287.16 | C185: =K184 -> 287.16 | D185: 0 | E185: 0 | F185: 11.25 | G185: 0 | H185: 0 | J185: 500 | K185: 798.41 | L185: 0 | M185: =K185+L185 -> 798.41 | N185: Pay for Auction
A186: 46205 | B186: 798.41 | C186: =K185 -> 798.41 | D186: 0 | E186: 0 | F186: 0 | G186: 0 | H186: 0 | J186: -491.01 | K186: 307.4 | L186: 0 | M186: =K186+L186 -> 307.4 | N186: Prestine Auction
A187: 46206 | B187: 307.4 | C187: =K186 -> 307.4 | D187: 0 | E187: 0 | F187: 0 | G187: 0 | H187: 0 | K187: 307.4 | L187: 0 | M187: =K187+L187 -> 307.4
A188: 46207 | B188: 307.4 | C188: =K187 -> 307.4 | D188: 0 | E188: 0 | F188: 0 | G188: 0 | H188: 0 | K188: 307.4 | L188: 0 | M188: =K188+L188 -> 307.4
A189: 46208 | B189: 307.4 | C189: =K188 -> 307.4 | D189: 0 | E189: 0 | F189: 0 | G189: 0 | H189: 0 | K189: 307.4 | L189: 0 | M189: =K189+L189 -> 307.4
A190: 46209 | B190: 307.4 | C190: =K189 -> 307.4 | D190: 0 | E190: 0 | F190: 0 | G190: 0 | H190: 0 | K190: 307.4 | L190: 0 | M190: =K190+L190 -> 307.4
A191: 46210 | B191: 307.4 | C191: =K190 -> 307.4 | D191: 0 | E191: 0 | F191: 0 | G191: 0 | H191: 0 | K191: 307.4 | L191: 0 | M191: =K191+L191 -> 307.4
A192: 46211 | B192: 307.4 | C192: =K191 -> 307.4 | D192: 0 | E192: 0 | F192: 0 | G192: 0 | H192: 0 | K192: 307.4 | L192: 0 | M192: =K192+L192 -> 307.4
A193: 46212 | B193: 307.4 | C193: =K192 -> 307.4 | D193: 0 | E193: 0 | F193: 0 | G193: 0 | H193: 0 | J193: -216.63 | K193: 90.77 | L193: 0 | M193: =K193+L193 -> 90.77 | N193: Prestine Auction
A194: 46213 | B194: 90.77 | C194: =K193 -> 90.77 | D194: 0 | E194: 0 | F194: 0 | G194: 0 | H194: 0 | K194: 90.77 | L194: 0 | M194: =K194+L194 -> 90.77
A195: 46214 | B195: 90.77 | C195: =K194 -> 90.77 | D195: 0 | E195: 0 | F195: 0 | G195: 0 | H195: 0 | K195: 90.77 | L195: 0 | M195: =K195+L195 -> 90.77
A196: 46215 | B196: 90.77 | C196: =K195 -> 90.77 | D196: 0 | E196: 0 | F196: 0 | G196: 0 | H196: 0 | K196: 90.77 | L196: =D196+IF(E196>0,'Main Budget'!$I$9,0) -> 0 | M196: =K196+L196 -> 90.77
A197: 46216 | B197: =M196 -> 90.77 | C197: =K196 -> 90.77 | D197: =L196 -> 0 | E197: =IF(DAY(A197+2)=1,'Main Budget'!$E$29,IF(DAY(A197+2)=15,'Main Budget'!$E$29,0)) -> 84.998333 | F197: 0 | G197: 0 | H197: 0 | K197: =C197+SUM(E197:J197)-IF(E197>0,-'Main Budget'!$I$9,0) -> 168.84833 | L197: =D197+IF(E197>0,-'Main Budget'!$I$9,0) -> 6.92 | M197: =K197+L197 -> 175.76833
A198: 46217 | B198: =M197 -> 175.76833 | C198: =K197 -> 168.84833 | D198: =L197 -> 6.92 | E198: =IF(DAY(A198+2)=1,'Main Budget'!$E$29,IF(DAY(A198+2)=15,'Main Budget'!$E$29,0)) -> 0 | F198: 11.25 | G198: 0 | H198: 0 | K198: =K197+SUM(E198:J198)-IF(E198>0,-'Main Budget'!$I$9,0) -> 180.09833 | L198: =D198+IF(E198>0,-'Main Budget'!$I$9,0) -> 6.92 | M198: =K198+L198 -> 187.01833
A199: 46218 | B199: =M198 -> 187.01833 | C199: =K198 -> 180.09833 | D199: =L198 -> 6.92 | E199: =IF(DAY(A199+2)=1,'Main Budget'!$E$29,IF(DAY(A199+2)=15,'Main Budget'!$E$29,0)) -> 0 | F199: 0 | G199: 0 | H199: 0 | K199: =K198+SUM(E199:J199)-IF(E199>0,-'Main Budget'!$I$9,0) -> 180.09833 | L199: =D199+IF(E199>0,-'Main Budget'!$I$9,0) -> 6.92 | M199: =K199+L199 -> 187.01833
A200: 46219 | B200: =M199 -> 187.01833 | C200: =K199 -> 180.09833 | D200: =L199 -> 6.92 | E200: =IF(DAY(A200+2)=1,'Main Budget'!$E$29,IF(DAY(A200+2)=15,'Main Budget'!$E$29,0)) -> 0 | F200: 0 | G200: -30 | H200: 0 | K200: =K199+SUM(E200:J200)-IF(E200>0,-'Main Budget'!$I$9,0) -> 150.09833 | L200: =D200+IF(E200>0,-'Main Budget'!$I$9,0) -> 6.92 | M200: =K200+L200 -> 157.01833
A201: 46220 | B201: =M200 -> 157.01833 | C201: =K200 -> 150.09833 | D201: =L200 -> 6.92 | E201: =IF(DAY(A201+2)=1,'Main Budget'!$E$29,IF(DAY(A201+2)=15,'Main Budget'!$E$29,0)) -> 0 | F201: 0 | G201: 0 | H201: -44.99 | K201: =K200+SUM(E201:J201)-IF(E201>0,-'Main Budget'!$I$9,0) -> 105.10833 | L201: =D201+IF(E201>0,-'Main Budget'!$I$9,0) -> 6.92 | M201: =K201+L201 -> 112.02833
A202: 46221 | B202: =M201 -> 112.02833 | C202: =K201 -> 105.10833 | D202: =L201 -> 6.92 | E202: =IF(DAY(A202+2)=1,'Main Budget'!$E$29,IF(DAY(A202+2)=15,'Main Budget'!$E$29,0)) -> 0 | F202: =IF(OR(DAY(A202)=1,DAY(A202)=14),11.25,0) -> 0 | G202: =IF(DAY(A202)='Main Budget'!$K$7,('Main Budget'!$E$7),0) -> 0 | H202: =IF(DAY(A202)='Main Budget'!$K$8,('Main Budget'!$E$8)*2,0) -> 0 | K202: =K201+SUM(E202:J202)-IF(E202>0,-'Main Budget'!$I$9,0) -> 105.10833 | L202: =D202+IF(E202>0,-'Main Budget'!$I$9,0) -> 6.92 | M202: =K202+L202 -> 112.02833
...
