Workbook
Name PlatformFees: 'Fee Reference'!$A$4:$C$15
Name PlatformList: 'Fee Reference'!$A$4:$A$15

Sheet Dashboard
B2: PRESTINE AUCTION — COLLECTION TRACKER
B3: Last Refreshed: | C3: =NOW() -> 46232.57
B5: Total Items | E5: Total Invested | H5: Items Sold | K5: Realized Profit
B6: =COUNTA(Inventory!A2:A35) -> 34 | E6: =Inventory!N36 -> 1067.14 | H6: =COUNTIF(Inventory!B2:B35,"Sold") -> 0 | K6: =SUM('Sales Log'!P4:P303) -> 0
B8: Items Listed | E8: Capital Tied Up | H8: Sell-Through Rate | K8: Blended ROI %
B9: =COUNTIF(Inventory!B2:B35,"Listed") -> 16 | E9: =SUMIF(Inventory!B2:B35,"<>Sold",Inventory!N2:N35) -> 1067.14 | H9: =IFERROR(COUNTIF(Inventory!B2:B35,"Sold")/COUNTA(Inventory!A2:A35),0) -> 0 | K9: =IFERROR(SUM('Sales Log'!P4:P303)/SUMIF('Sales Log'!F4:F303,">0",'Sales Log'!O4:O303),0) -> 0
B11: Gross Revenue | E11: Avg Days on Market | H11: Avg Cost / Item | K11: Highest Item Cost
B12: =SUM('Sales Log'!F4:F303) -> 0 | E12: =IFERROR(AVERAGEIF(Inventory!AE2:AE35,"<>",Inventory!AG2:AG35),0) -> 11.8125 | H12: =IFERROR(Inventory!N36/COUNTA(Inventory!A2:A35),0) -> 31.386471 | K12: =MAX(Inventory!N2:N35) -> 72.346756
B14: COST BREAKDOWN | H14: PROFIT SNAPSHOT
B15: Base Item Cost | E15: =SUM(Inventory!E2:E35) -> 974.59 | H15: Realized Gross Revenue | K15: =SUM('Sales Log'!F4:F303) -> 0
B16: Discounts Saved | E16: =SUM(Inventory!I2:I35) -> 221 | H16: Total Fees Paid | K16: =SUM('Sales Log'!K4:K303)+SUM('Sales Log'!L4:L303)+SUM('Sales Log'!M4:M303) -> 0
B17: Shipping | E17: =SUM(Inventory!K2:K35) -> 218.78 | H17: COGS (Items Sold) | K17: =SUMIF('Sales Log'!F4:F303,">0",'Sales Log'!O4:O303) -> 0
B18: Tax | E18: =SUM(Inventory!M2:M35) -> 94.77 | H18: Realized Net Profit | J18: {=SUMPRODUCT((Inventory!$B$2:$B$35<>"Sold")*(Inventory!$B$2:$B$35<>"Kept for Self")*IFERROR(Inventory!$U$2:$U$35-Inventory!$U$2:$U$35*(Inventory!$P$2:$P$35+Inventory!$S$2:$S$35)-Inventory!$Q$2:$Q$35-Inventory!$R$2:$R$35-Inventory!$N$2:$N$35,0))} -> 859.07233 | K18: =SUM('Sales Log'!P4:P303) -> 0
B19: Net Total Landed Cost | E19: =SUM(Inventory!N2:N35) -> 1067.14 | H19: Unrealized Potential Profit | K19: {=SUMPRODUCT((Inventory!$B$2:$B$35<>"Sold")*(Inventory!$B$2:$B$35<>"Kept for Self")*IFERROR(Inventory!$U$2:$U$35-Inventory!$U$2:$U$35*(Inventory!$P$2:$P$35+Inventory!$S$2:$S$35)-Inventory!$Q$2:$Q$35-Inventory!$R$2:$R$35-Inventory!$N$2:$N$35,0))} -> 859.07233
B21: TOP 5 MOST EXPENSIVE ITEMS (BY LANDED COST) | H21: BEST-PERFORMING CATEGORIES (BY REALIZED PROFIT)
B22: Rank | C22: Item Name | E22: Category | F22: True Cost | H22: Rank | I22: Category | K22: Profit
B23: 1 | C23: =INDEX(Inventory!$A$2:$A$35,MATCH(LARGE(Inventory!$N$2:$N$35,1),Inventory!$N$2:$N$35,0)) -> Charlie Sheen, Tom Berenger & Corbin Bernsen Signed Jersey (Beckett) | E23: =INDEX(Inventory!$Y$2:$Y$35,MATCH(LARGE(Inventory!$N$2:$N$35,1),Inventory!$N$2:$N$35,0)) -> Jersey | F23: =LARGE(Inventory!$N$2:$N$35,1) -> 72.346756 | H23: 1 | I23: =IFERROR(INDEX(Categories!$A$5:$A$13,MATCH(LARGE(Categories!$G$5:$G$13,1),Categories!$G$5:$G$13,0)),"—") -> Jersey | K23: =IFERROR(LARGE(Categories!$G$5:$G$13,1),0) -> 0
B24: 2 | C24: =INDEX(Inventory!$A$2:$A$35,MATCH(LARGE(Inventory!$N$2:$N$35,2),Inventory!$N$2:$N$35,0)) -> Ari Lehman Signed "Friday the 13th" Jason Voorhees Mask Inscribed "Jason 1" (Beckett) | E24: =INDEX(Inventory!$Y$2:$Y$35,MATCH(LARGE(Inventory!$N$2:$N$35,2),Inventory!$N$2:$N$35,0)) -> Mask | F24: =LARGE(Inventory!$N$2:$N$35,2) -> 55.90334 | H24: 2 | I24: =IFERROR(INDEX(Categories!$A$5:$A$13,MATCH(LARGE(Categories!$G$5:$G$13,2),Categories!$G$5:$G$13,0)),"—") -> Jersey | K24: =IFERROR(LARGE(Categories!$G$5:$G$13,2),0) -> 0
B25: 3 | C25: =INDEX(Inventory!$A$2:$A$35,MATCH(LARGE(Inventory!$N$2:$N$35,3),Inventory!$N$2:$N$35,0)) -> Steve Spurrier Signed Florida Gators 8x10 Photo Inscribed "Go Gators" (ACOA) | E25: =INDEX(Inventory!$Y$2:$Y$35,MATCH(LARGE(Inventory!$N$2:$N$35,3),Inventory!$N$2:$N$35,0)) -> Photo | F25: =LARGE(Inventory!$N$2:$N$35,3) -> 54.934251 | H25: 3 | I25: =IFERROR(INDEX(Categories!$A$5:$A$13,MATCH(LARGE(Categories!$G$5:$G$13,3),Categories!$G$5:$G$13,0)),"—") -> Jersey | K25: =IFERROR(LARGE(Categories!$G$5:$G$13,3),0) -> 0
B26: 4 | C26: =INDEX(Inventory!$A$2:$A$35,MATCH(LARGE(Inventory!$N$2:$N$35,4),Inventory!$N$2:$N$35,0)) -> Chad Smith Signed 16" Drum Stick (Beckett) | E26: =INDEX(Inventory!$Y$2:$Y$35,MATCH(LARGE(Inventory!$N$2:$N$35,4),Inventory!$N$2:$N$35,0)) -> Drum Stick | F26: =LARGE(Inventory!$N$2:$N$35,4) -> 47.480319 | H26: 4 | I26: =IFERROR(INDEX(Categories!$A$5:$A$13,MATCH(LARGE(Categories!$G$5:$G$13,4),Categories!$G$5:$G$13,0)),"—") -> Jersey | K26: =IFERROR(LARGE(Categories!$G$5:$G$13,4),0) -> 0
B27: 5 | C27: =INDEX(Inventory!$A$2:$A$35,MATCH(LARGE(Inventory!$N$2:$N$35,5),Inventory!$N$2:$N$35,0)) -> Shawn Kemp Signed Jersey (JSA) | E27: =INDEX(Inventory!$Y$2:$Y$35,MATCH(LARGE(Inventory!$N$2:$N$35,5),Inventory!$N$2:$N$35,0)) -> Jersey | F27: =LARGE(Inventory!$N$2:$N$35,5) -> 44.722672 | H27: 5 | I27: =IFERROR(INDEX(Categories!$A$5:$A$13,MATCH(LARGE(Categories!$G$5:$G$13,5),Categories!$G$5:$G$13,0)),"—") -> Jersey | K27: =IFERROR(LARGE(Categories!$G$5:$G$13,5),0) -> 0
B30: QUICK NAVIGATION
B31: ▶ True Cost | D31: ▶ Sales Log | F31: ▶ Pricing Intelligence
B32: 💡 Click sheet tabs at bottom of Excel to navigate, or use Ctrl+Page Down / Ctrl+Page Up

Sheet Inventory
A1: Item Name | B1: Status | C1: Invoice ID | D1: Unit Price | E1: Item Base Total | F1: Invoice Base Total | G1: Proration Weight | H1: Invoice Total Discount | I1: Prorated Discount | J1: Invoice Total Shipping | K1: Prorated Shipping | L1: Invoice Total Tax | M1: Prorated Tax | N1: True Total Cost | O1: Platform | P1: Platform Fee % | Q1: Platform Flat Fee | R1: Est. Shipping Cost | S1: Boost % | T1: Min Sell Price | U1: Suggested List Price | V1: Current List Price | W1: Actual Sell Price | X1: Profit/Loss | Y1: Category | Z1: Sport / Genre | AA1: Athlete / Person | AB1: Authenticator | AC1: Cert # | AD1: Date Acquired | AE1: Date Listed | AF1: Date Sold | AG1: Days on Market | AH1: eBay Sold Comps | AI1: ROI % (Actual) | AJ1: Margin % (Target) | AK1: Notes | AL1: Best Listing Window
A2: Shawn Kemp Signed 1990-91 Hoops #279 RC (JSA) | B2: Kept for Self | C2: 4809173 | D2: 17.01 | E2: =D2 -> 17.01 | F2: =SUMIF(C:C, C2, E:E) -> 140.13 | G2: =E2/F2 -> 0.12138728 | H2: 45 | I2: =H2*G2 -> 5.4624277 | J2: 25.77 | K2: =J2*G2 -> 3.1281503 | L2: 13.01 | M2: =L2*G2 -> 1.5792486 | N2: =E2-I2+K2+M2 -> 16.254971 | O2: eBay | P2: =IFERROR(VLOOKUP(O2,PlatformFees,2,FALSE()),0) -> 0.136 | Q2: =IFERROR(VLOOKUP(O2,PlatformFees,3,FALSE()),0) -> 0.4 | R2: 6.5 | S2: 0 | T2: =(N2+R2+Q2)/(1-(P2+S2)) -> 26.799735 | U2: =MAX(MAX(T2*1.5, T2+15), IFERROR(VLOOKUP(A2,'Pricing Intelligence'!A:J,10,FALSE),0)) -> 51.33 | V2: 0 | W2: =IFERROR(_xlfn.XLOOKUP(A2,'Sales Log'!$C$4:$C$303,'Sales Log'!$F$4:$F$303,0),0) -> 0 | X2: =IF(W2=0,0,W2-(W2*(P2+S2))-Q2-R2-N2) -> 0 | Y2: =IFERROR(IF(ISNUMBER(SEARCH("Jersey",A2)),"Jersey",IF(ISNUMBER(SEARCH("Photo",A2)),"Photo",IF(ISNUMBER(SEARCH("Baseball Bat",A2)),"Bat",IF(ISNUMBER(SEARCH("Bat",A2)),"Bat",IF(ISNUMBER(SEARCH("Baseball",A2)),"Baseball",IF(ISNUMBER(SEARCH("Football",A2)),"Football",IF(ISNUMBER(SEARCH("Mask",A2)),"Mask",IF(ISNUMBER(SEARCH("Drum",A2)),"Drum Stick",IF(ISNUMBER(SEARCH("Card",A2)),"Card",IF(ISNUMBER(SEARCH("RC",A2)),"Card","Other")))))))))),"Other") -> Card | Z2: Basketball | AA2: =IFERROR(TRIM(LEFT(A2,FIND(" Signed",A2)-1)),LEFT(A2,20)) -> Shawn Kemp | AB2: =IF(ISNUMBER(SEARCH("(Beckett)",A2)),"Beckett",IF(ISNUMBER(SEARCH("(JSA)",A2)),"JSA",IF(ISNUMBER(SEARCH("(PSA)",A2)),"PSA",IF(ISNUMBER(SEARCH("(ACOA)",A2)),"ACOA",IF(ISNUMBER(SEARCH("(Schwartz)",A2)),"Schwartz","Unlabeled"))))) -> JSA | AD2: 46197 | AG2: =IF(AE2="","",IF(AF2="",TODAY()-AE2,AF2-AE2)) | AH2: =HYPERLINK("https://www.ebay.com/sch/i.html?_nkw="&SUBSTITUTE(SUBSTITUTE(A2," ","+"),"""","")&"&LH_Sold=1&LH_Complete=1","View Sold Comps") -> View Sold Comps | AI2: =IF(OR(N2=0,W2=0),"",X2/N2) | AJ2: =IF(U2=0,"",(U2-U2*P2-Q2-R2-N2)/U2) -> 0.41289984 | AL2: =IF(B2="Kept for Self","—",IF(Z2="Baseball","Apr – Oct (MLB Season)",IF(Z2="Football","Aug – Feb (NFL Season)",IF(Z2="Basketball","Oct – Jun (NBA Season)",IF(OR(Z2="Movie",Z2="TV"),IF(ISNUMBER(SEARCH("Friday the 13th",A2)),"Sep – Oct (Halloween)","Year-Round"),IF(Z2="Music","Year-Round","Year-Round")))))) -> —
A3: Mark Henn Signed "The Lion King" 8x10 Photo (Beckett) | B3: Listed | C3: 4809173 | D3: 17.82 | E3: =D3 -> 17.82 | F3: =SUMIF(C:C, C3, E:E) -> 140.13 | G3: =E3/F3 -> 0.12716763 | H3: 45 | I3: =H3*G3 -> 5.7225434 | J3: 25.77 | K3: =J3*G3 -> 3.2771098 | L3: 13.01 | M3: =L3*G3 -> 1.6544509 | N3: =E3-I3+K3+M3 -> 17.029017 | O3: eBay | P3: =IFERROR(VLOOKUP(O3,PlatformFees,2,FALSE()),0) -> 0.136 | Q3: =IFERROR(VLOOKUP(O3,PlatformFees,3,FALSE()),0) -> 0.4 | R3: 6.5 | S3: 0.05 | T3: =(N3+R3+Q3)/(1-(P3+S3)) -> 29.396827 | U3: =MAX(MAX(T3*1.5, T3+15), IFERROR(VLOOKUP(A3,'Pricing Intelligence'!A:J,10,FALSE),0)) -> 44.396827 | V3: 51.29 | W3: =IFERROR(_xlfn.XLOOKUP(A3,'Sales Log'!$C$4:$C$303,'Sales Log'!$F$4:$F$303,0),0) -> 0 | X3: =IF(W3=0,0,W3-(W3*(P3+S3))-Q3-R3-N3) -> 0 | Y3: =IFERROR(IF(ISNUMBER(SEARCH("Jersey",A3)),"Jersey",IF(ISNUMBER(SEARCH("Photo",A3)),"Photo",IF(ISNUMBER(SEARCH("Baseball Bat",A3)),"Bat",IF(ISNUMBER(SEARCH("Bat",A3)),"Bat",IF(ISNUMBER(SEARCH("Baseball",A3)),"Baseball",IF(ISNUMBER(SEARCH("Football",A3)),"Football",IF(ISNUMBER(SEARCH("Mask",A3)),"Mask",IF(ISNUMBER(SEARCH("Drum",A3)),"Drum Stick",IF(ISNUMBER(SEARCH("Card",A3)),"Card",IF(ISNUMBER(SEARCH("RC",A3)),"Card","Other")))))))))),"Other") -> Photo | Z3: Movie | AA3: =IFERROR(TRIM(LEFT(A3,FIND(" Signed",A3)-1)),LEFT(A3,20)) -> Mark Henn | AB3: =IF(ISNUMBER(SEARCH("(Beckett)",A3)),"Beckett",IF(ISNUMBER(SEARCH("(JSA)",A3)),"JSA",IF(ISNUMBER(SEARCH("(PSA)",A3)),"PSA",IF(ISNUMBER(SEARCH("(ACOA)",A3)),"ACOA",IF(ISNUMBER(SEARCH("(Schwartz)",A3)),"Schwartz","Unlabeled"))))) -> Beckett | AD3: 46197 | AE3: 46211 | AG3: =IF(AE3="","",IF(AF3="",TODAY()-AE3,AF3-AE3)) -> 21 | AH3: =HYPERLINK("https://www.ebay.com/sch/i.html?_nkw="&SUBSTITUTE(SUBSTITUTE(A3," ","+"),"""","")&"&LH_Sold=1&LH_Complete=1","View Sold Comps") -> View Sold Comps | AI3: =IF(OR(N3=0,W3=0),"",X3/N3) | AJ3: =IF(U3=0,"",(U3-U3*P3-Q3-R3-N3)/U3) -> 0.32501965 | AL3: =IF(B3="Kept for Self","—",IF(Z3="Baseball","Apr – Oct (MLB Season)",IF(Z3="Football","Aug – Feb (NFL Season)",IF(Z3="Basketball","Oct – Jun (NBA Season)",IF(OR(Z3="Movie",Z3="TV"),IF(ISNUMBER(SEARCH("Friday the 13th",A3)),"Sep – Oct (Halloween)","Year-Round"),IF(Z3="Music","Year-Round","Year-Round")))))) -> Year-Round
A4: Ari Lehman Signed "Friday the 13th" Jason Voorhees Mask Inscribed "Jason 1" (Beckett) | B4: Listed | C4: 4809173 | D4: 58.5 | E4: =D4 -> 58.5 | F4: =SUMIF(C:C, C4, E:E) -> 140.13 | G4: =E4/F4 -> 0.41746949 | H4: 45 | I4: =H4*G4 -> 18.786127 | J4: 25.77 | K4: =J4*G4 -> 10.758189 | L4: 13.01 | M4: =L4*G4 -> 5.4312781 | N4: =E4-I4+K4+M4 -> 55.90334 | O4: eBay | P4: =IFERROR(VLOOKUP(O4,PlatformFees,2,FALSE()),0) -> 0.136 | Q4: =IFERROR(VLOOKUP(O4,PlatformFees,3,FALSE()),0) -> 0.4 | R4: 6.5 | S4: 0.02 | T4: =(N4+R4+Q4)/(1-(P4+S4)) -> 74.41154 | U4: =MAX(MAX(T4*1.5, T4+15), IFERROR(VLOOKUP(A4,'Pricing Intelligence'!A:J,10,FALSE),0)) -> 111.61731 | V4: 39 | W4: =IFERROR(_xlfn.XLOOKUP(A4,'Sales Log'!$C$4:$C$303,'Sales Log'!$F$4:$F$303,0),0) -> 0 | X4: =IF(W4=0,0,W4-(W4*(P4+S4))-Q4-R4-N4) -> 0 | Y4: =IFERROR(IF(ISNUMBER(SEARCH("Jersey",A4)),"Jersey",IF(ISNUMBER(SEARCH("Photo",A4)),"Photo",IF(ISNUMBER(SEARCH("Baseball Bat",A4)),"Bat",IF(ISNUMBER(SEARCH("Bat",A4)),"Bat",IF(ISNUMBER(SEARCH("Baseball",A4)),"Baseball",IF(ISNUMBER(SEARCH("Football",A4)),"Football",IF(ISNUMBER(SEARCH("Mask",A4)),"Mask",IF(ISNUMBER(SEARCH("Drum",A4)),"Drum Stick",IF(ISNUMBER(SEARCH("Card",A4)),"Card",IF(ISNUMBER(SEARCH("RC",A4)),"Card","Other")))))))))),"Other") -> Mask | Z4: Movie | AA4: =IFERROR(TRIM(LEFT(A4,FIND(" Signed",A4)-1)),LEFT(A4,20)) -> Ari Lehman | AB4: =IF(ISNUMBER(SEARCH("(Beckett)",A4)),"Beckett",IF(ISNUMBER(SEARCH("(JSA)",A4)),"JSA",IF(ISNUMBER(SEARCH("(PSA)",A4)),"PSA",IF(ISNUMBER(SEARCH("(ACOA)",A4)),"ACOA",IF(ISNUMBER(SEARCH("(Schwartz)",A4)),"Schwartz","Unlabeled"))))) -> Beckett | AD4: 46197 | AE4: 46211 | AG4: =IF(AE4="","",IF(AF4="",TODAY()-AE4,AF4-AE4)) -> 21 | AH4: =HYPERLINK("https://www.ebay.com/sch/i.html?_nkw="&SUBSTITUTE(SUBSTITUTE(A4," ","+"),"""","")&"&LH_Sold=1&LH_Complete=1","View Sold Comps") -> View Sold Comps | AI4: =IF(OR(N4=0,W4=0),"",X4/N4) | AJ4: =IF(U4=0,"",(U4-U4*P4-Q4-R4-N4)/U4) -> 0.30133333 | AL4: =IF(B4="Kept for Self","—",IF(Z4="Baseball","Apr – Oct (MLB Season)",IF(Z4="Football","Aug – Feb (NFL Season)",IF(Z4="Basketball","Oct – Jun (NBA Season)",IF(OR(Z4="Movie",Z4="TV"),IF(ISNUMBER(SEARCH("Friday the 13th",A4)),"Sep – Oct (Halloween)","Year-Round"),IF(Z4="Music","Year-Round","Year-Round")))))) -> Sep – Oct (Halloween)
A5: Shawn Kemp Signed Jersey (JSA) | B5: Kept for Self | C5: 4809173 | D5: 46.8 | E5: =D5 -> 46.8 | F5: =SUMIF(C:C, C5, E:E) -> 140.13 | G5: =E5/F5 -> 0.33397559 | H5: 45 | I5: =H5*G5 -> 15.028902 | J5: 25.77 | K5: =J5*G5 -> 8.6065511 | L5: 13.01 | M5: =L5*G5 -> 4.3450225 | N5: =E5-I5+K5+M5 -> 44.722672 | O5: eBay | P5: =IFERROR(VLOOKUP(O5,PlatformFees,2,FALSE()),0) -> 0.136 | Q5: =IFERROR(VLOOKUP(O5,PlatformFees,3,FALSE()),0) -> 0.4 | R5: 6.5 | S5: 0 | T5: =(N5+R5+Q5)/(1-(P5+S5)) -> 59.748463 | U5: =MAX(MAX(T5*1.5, T5+15), IFERROR(VLOOKUP(A5,'Pricing Intelligence'!A:J,10,FALSE),0)) -> 89.622694 | V5: 0 | W5: =IFERROR(_xlfn.XLOOKUP(A5,'Sales Log'!$C$4:$C$303,'Sales Log'!$F$4:$F$303,0),0) -> 0 | X5: =IF(W5=0,0,W5-(W5*(P5+S5))-Q5-R5-N5) -> 0 | Y5: =IFERROR(IF(ISNUMBER(SEARCH("Jersey",A5)),"Jersey",IF(ISNUMBER(SEARCH("Photo",A5)),"Photo",IF(ISNUMBER(SEARCH("Baseball Bat",A5)),"Bat",IF(ISNUMBER(SEARCH("Bat",A5)),"Bat",IF(ISNUMBER(SEARCH("Baseball",A5)),"Baseball",IF(ISNUMBER(SEARCH("Football",A5)),"Football",IF(ISNUMBER(SEARCH("Mask",A5)),"Mask",IF(ISNUMBER(SEARCH("Drum",A5)),"Drum Stick",IF(ISNUMBER(SEARCH("Card",A5)),"Card",IF(ISNUMBER(SEARCH("RC",A5)),"Card","Other")))))))))),"Other") -> Jersey | Z5: Basketball | AA5: =IFERROR(TRIM(LEFT(A5,FIND(" Signed",A5)-1)),LEFT(A5,20)) -> Shawn Kemp | AB5: =IF(ISNUMBER(SEARCH("(Beckett)",A5)),"Beckett",IF(ISNUMBER(SEARCH("(JSA)",A5)),"JSA",IF(ISNUMBER(SEARCH("(PSA)",A5)),"PSA",IF(ISNUMBER(SEARCH("(ACOA)",A5)),"ACOA",IF(ISNUMBER(SEARCH("(Schwartz)",A5)),"Schwartz","Unlabeled"))))) -> JSA | AD5: 46197 | AG5: =IF(AE5="","",IF(AF5="",TODAY()-AE5,AF5-AE5)) | AH5: =HYPERLINK("https://www.ebay.com/sch/i.html?_nkw="&SUBSTITUTE(SUBSTITUTE(A5," ","+"),"""","")&"&LH_Sold=1&LH_Complete=1","View Sold Comps") -> View Sold Comps | AI5: =IF(OR(N5=0,W5=0),"",X5/N5) | AJ5: =IF(U5=0,"",(U5-U5*P5-Q5-R5-N5)/U5) -> 0.288 | AL5: =IF(B5="Kept for Self","—",IF(Z5="Baseball","Apr – Oct (MLB Season)",IF(Z5="Football","Aug – Feb (NFL Season)",IF(Z5="Basketball","Oct – Jun (NBA Season)",IF(OR(Z5="Movie",Z5="TV"),IF(ISNUMBER(SEARCH("Friday the 13th",A5)),"Sep – Oct (Halloween)","Year-Round"),IF(Z5="Music","Year-Round","Year-Round")))))) -> —
A6: Cheech Marin & Tommy Chong Signed "The Simpsons" 8x10 Photo (JSA) | B6: Available | C6: 4814462 | D6: 26.43 | E6: =D6 -> 26.43 | F6: =SUMIF(C:C, C6, E:E) -> 84.15 | G6: =E6/F6 -> 0.314082 | H6: 45 | I6: =H6*G6 -> 14.13369 | J6: 5.77 | K6: =J6*G6 -> 1.8122531 | L6: 7.09 | M6: =L6*G6 -> 2.2268414 | N6: =E6-I6+K6+M6 -> 16.335405 | O6: eBay | P6: =IFERROR(VLOOKUP(O6,PlatformFees,2,FALSE()),0) -> 0.136 | Q6: =IFERROR(VLOOKUP(O6,PlatformFees,3,FALSE()),0) -> 0.4 | R6: 6.5 | S6: 0 | T6: =(N6+R6+Q6)/(1-(P6+S6)) -> 26.892829 | U6: =MAX(MAX(T6*1.5, T6+15), IFERROR(VLOOKUP(A6,'Pricing Intelligence'!A:J,10,FALSE),0)) -> 59.983333 | V6: 0 | W6: =IFERROR(_xlfn.XLOOKUP(A6,'Sales Log'!$C$4:$C$303,'Sales Log'!$F$4:$F$303,0),0) -> 0 | X6: =IF(W6=0,0,W6-(W6*(P6+S6))-Q6-R6-N6) -> 0 | Y6: =IFERROR(IF(ISNUMBER(SEARCH("Jersey",A6)),"Jersey",IF(ISNUMBER(SEARCH("Photo",A6)),"Photo",IF(ISNUMBER(SEARCH("Baseball Bat",A6)),"Bat",IF(ISNUMBER(SEARCH("Bat",A6)),"Bat",IF(ISNUMBER(SEARCH("Baseball",A6)),"Baseball",IF(ISNUMBER(SEARCH("Football",A6)),"Football",IF(ISNUMBER(SEARCH("Mask",A6)),"Mask",IF(ISNUMBER(SEARCH("Drum",A6)),"Drum Stick",IF(ISNUMBER(SEARCH("Card",A6)),"Card",IF(ISNUMBER(SEARCH("RC",A6)),"Card","Other")))))))))),"Other") -> Photo | Z6: TV | AA6: =IFERROR(TRIM(LEFT(A6,FIND(" Signed",A6)-1)),LEFT(A6,20)) -> Cheech Marin & Tommy Chong | AB6: =IF(ISNUMBER(SEARCH("(Beckett)",A6)),"Beckett",IF(ISNUMBER(SEARCH("(JSA)",A6)),"JSA",IF(ISNUMBER(SEARCH("(PSA)",A6)),"PSA",IF(ISNUMBER(SEARCH("(ACOA)",A6)),"ACOA",IF(ISNUMBER(SEARCH("(Schwartz)",A6)),"Schwartz","Unlabeled"))))) -> JSA | AD6: 46199 | AG6: =IF(AE6="","",IF(AF6="",TODAY()-AE6,AF6-AE6)) | AH6: =HYPERLINK("https://www.ebay.com/sch/i.html?_nkw="&SUBSTITUTE(SUBSTITUTE(A6," ","+"),"""","")&"&LH_Sold=1&LH_Complete=1","View Sold Comps") -> View Sold Comps | AI6: =IF(OR(N6=0,W6=0),"",X6/N6) | AJ6: =IF(U6=0,"",(U6-U6*P6-Q6-R6-N6)/U6) -> 0.47663565 | AL6: =IF(B6="Kept for Self","—",IF(Z6="Baseball","Apr – Oct (MLB Season)",IF(Z6="Football","Aug – Feb (NFL Season)",IF(Z6="Basketball","Oct – Jun (NBA Season)",IF(OR(Z6="Movie",Z6="TV"),IF(ISNUMBER(SEARCH("Friday the 13th",A6)),"Sep – Oct (Halloween)","Year-Round"),IF(Z6="Music","Year-Round","Year-Round")))))) -> Year-Round
A7: Chris Cooper Signed "Cars 3" 8x10 Photo Inscribed "AKA 'Smokey'" & "Best Wishes" (ACOA) | B7: Listed | C7: 4814462 | D7: 13.51 | E7: =D7 -> 13.51 | F7: =SUMIF(C:C, C7, E:E) -> 84.15 | G7: =E7/F7 -> 0.16054664 | H7: 45 | I7: =H7*G7 -> 7.2245989 | J7: 5.77 | K7: =J7*G7 -> 0.92635413 | L7: 7.09 | M7: =L7*G7 -> 1.1382757 | N7: =E7-I7+K7+M7 -> 8.3500309 | O7: eBay | P7: =IFERROR(VLOOKUP(O7,PlatformFees,2,FALSE()),0) -> 0.136 | Q7: =IFERROR(VLOOKUP(O7,PlatformFees,3,FALSE()),0) -> 0.4 | R7: 6.5 | S7: 0.05 | T7: =(N7+R7+Q7)/(1-(P7+S7)) -> 18.734682 | U7: =MAX(MAX(T7*1.5, T7+15), IFERROR(VLOOKUP(A7,'Pricing Intelligence'!A:J,10,FALSE),0)) -> 33.734682 | V7: 24.99 | W7: =IFERROR(_xlfn.XLOOKUP(A7,'Sales Log'!$C$4:$C$303,'Sales Log'!$F$4:$F$303,0),0) -> 0 | X7: =IF(W7=0,0,W7-(W7*(P7+S7))-Q7-R7-N7) -> 0 | Y7: =IFERROR(IF(ISNUMBER(SEARCH("Jersey",A7)),"Jersey",IF(ISNUMBER(SEARCH("Photo",A7)),"Photo",IF(ISNUMBER(SEARCH("Baseball Bat",A7)),"Bat",IF(ISNUMBER(SEARCH("Bat",A7)),"Bat",IF(ISNUMBER(SEARCH("Baseball",A7)),"Baseball",IF(ISNUMBER(SEARCH("Football",A7)),"Football",IF(ISNUMBER(SEARCH("Mask",A7)),"Mask",IF(ISNUMBER(SEARCH("Drum",A7)),"Drum Stick",IF(ISNUMBER(SEARCH("Card",A7)),"Card",IF(ISNUMBER(SEARCH("RC",A7)),"Card","Other")))))))))),"Other") -> Photo | Z7: Movie | AA7: =IFERROR(TRIM(LEFT(A7,FIND(" Signed",A7)-1)),LEFT(A7,20)) -> Chris Cooper | AB7: =IF(ISNUMBER(SEARCH("(Beckett)",A7)),"Beckett",IF(ISNUMBER(SEARCH("(JSA)",A7)),"JSA",IF(ISNUMBER(SEARCH("(PSA)",A7)),"PSA",IF(ISNUMBER(SEARCH("(ACOA)",A7)),"ACOA",IF(ISNUMBER(SEARCH("(Schwartz)",A7)),"Schwartz","Unlabeled"))))) -> ACOA | AD7: 46199 | AE7: 46211 | AG7: =IF(AE7="","",IF(AF7="",TODAY()-AE7,AF7-AE7)) -> 21 | AH7: =HYPERLINK("https://www.ebay.com/sch/i.html?_nkw="&SUBSTITUTE(SUBSTITUTE(A7," ","+"),"""","")&"&LH_Sold=1&LH_Complete=1","View Sold Comps") -> View Sold Comps | AI7: =IF(OR(N7=0,W7=0),"",X7/N7) | AJ7: =IF(U7=0,"",(U7-U7*P7-Q7-R7-N7)/U7) -> 0.41194205 | AL7: =IF(B7="Kept for Self","—",IF(Z7="Baseball","Apr – Oct (MLB Season)",IF(Z7="Football","Aug – Feb (NFL Season)",IF(Z7="Basketball","Oct – Jun (NBA Season)",IF(OR(Z7="Movie",Z7="TV"),IF(ISNUMBER(SEARCH("Friday the 13th",A7)),"Sep – Oct (Halloween)","Year-Round"),IF(Z7="Music","Year-Round","Year-Round")))))) -> Year-Round
A8: Frank Thomas Signed OML Baseball (JSA) | B8: Listed | C8: 4814462 | D8: 44.21 | E8: =D8 -> 44.21 | F8: =SUMIF(C:C, C8, E:E) -> 84.15 | G8: =E8/F8 -> 0.52537136 | H8: 45 | I8: =H8*G8 -> 23.641711 | J8: 5.77 | K8: =J8*G8 -> 3.0313928 | L8: 7.09 | M8: =L8*G8 -> 3.7248829 | N8: =E8-I8+K8+M8 -> 27.324564 | O8: eBay | P8: =IFERROR(VLOOKUP(O8,PlatformFees,2,FALSE()),0) -> 0.136 | Q8: =IFERROR(VLOOKUP(O8,PlatformFees,3,FALSE()),0) -> 0.4 | R8: 6.5 | S8: 0 | T8: =(N8+R8+Q8)/(1-(P8+S8)) -> 39.611764 | U8: =MAX(MAX(T8*1.5, T8+15), IFERROR(VLOOKUP(A8,'Pricing Intelligence'!A:J,10,FALSE),0)) -> 59.417647 | V8: 45 | W8: =IFERROR(_xlfn.XLOOKUP(A8,'Sales Log'!$C$4:$C$303,'Sales Log'!$F$4:$F$303,0),0) -> 0 | X8: =IF(W8=0,0,W8-(W8*(P8+S8))-Q8-R8-N8) -> 0 | Y8: =IFERROR(IF(ISNUMBER(SEARCH("Jersey",A8)),"Jersey",IF(ISNUMBER(SEARCH("Photo",A8)),"Photo",IF(ISNUMBER(SEARCH("Baseball Bat",A8)),"Bat",IF(ISNUMBER(SEARCH("Bat",A8)),"Bat",IF(ISNUMBER(SEARCH("Baseball",A8)),"Baseball",IF(ISNUMBER(SEARCH("Football",A8)),"Football",IF(ISNUMBER(SEARCH("Mask",A8)),"Mask",IF(ISNUMBER(SEARCH("Drum",A8)),"Drum Stick",IF(ISNUMBER(SEARCH("Card",A8)),"Card",IF(ISNUMBER(SEARCH("RC",A8)),"Card","Other")))))))))),"Other") -> Baseball | Z8: Baseball | AA8: =IFERROR(TRIM(LEFT(A8,FIND(" Signed",A8)-1)),LEFT(A8,20)) -> Frank Thomas | AB8: =IF(ISNUMBER(SEARCH("(Beckett)",A8)),"Beckett",IF(ISNUMBER(SEARCH("(JSA)",A8)),"JSA",IF(ISNUMBER(SEARCH("(PSA)",A8)),"PSA",IF(ISNUMBER(SEARCH("(ACOA)",A8)),"ACOA",IF(ISNUMBER(SEARCH("(Schwartz)",A8)),"Schwartz","Unlabeled"))))) -> JSA | AD8: 46199 | AE8: 46226 | AG8: =IF(AE8="","",IF(AF8="",TODAY()-AE8,AF8-AE8)) -> 6 | AH8: =HYPERLINK("https://www.ebay.com/sch/i.html?_nkw="&SUBSTITUTE(SUBSTITUTE(A8," ","+"),"""","")&"&LH_Sold=1&LH_Complete=1","View Sold Comps") -> View Sold Comps | AI8: =IF(OR(N8=0,W8=0),"",X8/N8) | AJ8: =IF(U8=0,"",(U8-U8*P8-Q8-R8-N8)/U8) -> 0.288 | AL8: =IF(B8="Kept for Self","—",IF(Z8="Baseball","Apr – Oct (MLB Season)",IF(Z8="Football","Aug – Feb (NFL Season)",IF(Z8="Basketball","Oct – Jun (NBA Season)",IF(OR(Z8="Movie",Z8="TV"),IF(ISNUMBER(SEARCH("Friday the 13th",A8)),"Sep – Oct (Halloween)","Year-Round"),IF(Z8="Music","Year-Round","Year-Round")))))) -> Apr – Oct (MLB Season)
A9: Jimbo Covert Signed NFL Football Inscribed "SB XX Champs" (JSA) | B9: Listed | C9: 4814637 | D9: 32.25 | E9: =D9 -> 32.25 | F9: =SUMIF(C:C, C9, E:E) -> 32.25 | G9: =E9/F9 -> 1 | H9: 20 | I9: =H9*G9 -> 20 | J9: 19.37 | K9: =J9*G9 -> 19.37 | L9: 4.06 | M9: =L9*G9 -> 4.06 | N9: =E9-I9+K9+M9 -> 35.68 | O9: eBay | P9: =IFERROR(VLOOKUP(O9,PlatformFees,2,FALSE()),0) -> 0.136 | Q9: =IFERROR(VLOOKUP(O9,PlatformFees,3,FALSE()),0) -> 0.4 | R9: 6.5 | S9: 0.03 | T9: =(N9+R9+Q9)/(1-(P9+S9)) -> 51.055156 | U9: =MAX(MAX(T9*1.5, T9+15), IFERROR(VLOOKUP(A9,'Pricing Intelligence'!A:J,10,FALSE),0)) -> 111 | V9: 129 | W9: =IFERROR(_xlfn.XLOOKUP(A9,'Sales Log'!$C$4:$C$303,'Sales Log'!$F$4:$F$303,0),0) -> 0 | X9: =IF(W9=0,0,W9-(W9*(P9+S9))-Q9-R9-N9) -> 0 | Y9: =IFERROR(IF(ISNUMBER(SEARCH("Jersey",A9)),"Jersey",IF(ISNUMBER(SEARCH("Photo",A9)),"Photo",IF(ISNUMBER(SEARCH("Baseball Bat",A9)),"Bat",IF(ISNUMBER(SEARCH("Bat",A9)),"Bat",IF(ISNUMBER(SEARCH("Baseball",A9)),"Baseball",IF(ISNUMBER(SEARCH("Football",A9)),"Football",IF(ISNUMBER(SEARCH("Mask",A9)),"Mask",IF(ISNUMBER(SEARCH("Drum",A9)),"Drum Stick",IF(ISNUMBER(SEARCH("Card",A9)),"Card",IF(ISNUMBER(SEARCH("RC",A9)),"Card","Other")))))))))),"Other") -> Football | Z9: Football | AA9: =IFERROR(TRIM(LEFT(A9,FIND(" Signed",A9)-1)),LEFT(A9,20)) -> Jimbo Covert | AB9: =IF(ISNUMBER(SEARCH("(Beckett)",A9)),"Beckett",IF(ISNUMBER(SEARCH("(JSA)",A9)),"JSA",IF(ISNUMBER(SEARCH("(PSA)",A9)),"PSA",IF(ISNUMBER(SEARCH("(ACOA)",A9)),"ACOA",IF(ISNUMBER(SEARCH("(Schwartz)",A9)),"Schwartz","Unlabeled"))))) -> JSA | AD9: 46199 | AE9: 46211 | AG9: =IF(AE9="","",IF(AF9="",TODAY()-AE9,AF9-AE9)) -> 21 | AH9: =HYPERLINK("https://www.ebay.com/sch/i.html?_nkw="&SUBSTITUTE(SUBSTITUTE(A9," ","+"),"""","")&"&LH_Sold=1&LH_Complete=1","View Sold Comps") -> View Sold Comps | AI9: =IF(OR(N9=0,W9=0),"",X9/N9) | AJ9: =IF(U9=0,"",(U9-U9*P9-Q9-R9-N9)/U9) -> 0.4803964 | AL9: =IF(B9="Kept for Self","—",IF(Z9="Baseball","Apr – Oct (MLB Season)",IF(Z9="Football","Aug – Feb (NFL Season)",IF(Z9="Basketball","Oct – Jun (NBA Season)",IF(OR(Z9="Movie",Z9="TV"),IF(ISNUMBER(SEARCH("Friday the 13th",A9)),"Sep – Oct (Halloween)","Year-Round"),IF(Z9="Music","Year-Round","Year-Round")))))) -> Aug – Feb (NFL Season)
A10: Moisés Ballesteros Signed OML Baseball (Beckett) | B10: Listed | C10: 4824728 | D10: 24.57 | E10: =D10 -> 24.57 | F10: =SUMIF(C:C, C10, E:E) -> 384.34 | G10: =E10/F10 -> 0.063927772 | H10: 31 | I10: =H10*G10 -> 1.9817609 | J10: 99 | K10: =J10*G10 -> 6.3288495 | L10: 38.67 | M10: =L10*G10 -> 2.472087 | N10: =E10-I10+K10+M10 -> 31.389175 | O10: eBay | P10: =IFERROR(VLOOKUP(O10,PlatformFees,2,FALSE()),0) -> 0.136 | Q10: =IFERROR(VLOOKUP(O10,PlatformFees,3,FALSE()),0) -> 0.4 | R10: 6.5 | S10: 0 | T10: =(N10+R10+Q10)/(1-(P10+S10)) -> 44.316175 | U10: =MAX(MAX(T10*1.5, T10+15), IFERROR(VLOOKUP(A10,'Pricing Intelligence'!A:J,10,FALSE),0)) -> 66.474263 | V10: 65.99 | W10: =IFERROR(_xlfn.XLOOKUP(A10,'Sales Log'!$C$4:$C$303,'Sales Log'!$F$4:$F$303,0),0) -> 0 | X10: =IF(W10=0,0,W10-(W10*(P10+S10))-Q10-R10-N10) -> 0 | Y10: =IFERROR(IF(ISNUMBER(SEARCH("Jersey",A10)),"Jersey",IF(ISNUMBER(SEARCH("Photo",A10)),"Photo",IF(ISNUMBER(SEARCH("Baseball Bat",A10)),"Bat",IF(ISNUMBER(SEARCH("Bat",A10)),"Bat",IF(ISNUMBER(SEARCH("Baseball",A10)),"Baseball",IF(ISNUMBER(SEARCH("Football",A10)),"Football",IF(ISNUMBER(SEARCH("Mask",A10)),"Mask",IF(ISNUMBER(SEARCH("Drum",A10)),"Drum Stick",IF(ISNUMBER(SEARCH("Card",A10)),"Card",IF(ISNUMBER(SEARCH("RC",A10)),"Card","Other")))))))))),"Other") -> Baseball | Z10: Baseball | AA10: =IFERROR(TRIM(LEFT(A10,FIND(" Signed",A10)-1)),LEFT(A10,20)) -> Moisés Ballesteros | AB10: =IF(ISNUMBER(SEARCH("(Beckett)",A10)),"Beckett",IF(ISNUMBER(SEARCH("(JSA)",A10)),"JSA",IF(ISNUMBER(SEARCH("(PSA)",A10)),"PSA",IF(ISNUMBER(SEARCH("(ACOA)",A10)),"ACOA",IF(ISNUMBER(SEARCH("(Schwartz)",A10)),"Schwartz","Unlabeled"))))) -> Beckett | AD10: 46204 | AE10: 46226 | AG10: =IF(AE10="","",IF(AF10="",TODAY()-AE10,AF10-AE10)) -> 6 | AH10: =HYPERLINK("https://www.ebay.com/sch/i.html?_nkw="&SUBSTITUTE(SUBSTITUTE(A10," ","+"),"""","")&"&LH_Sold=1&LH_Complete=1","View Sold Comps") -> View Sold Comps | AI10: =IF(OR(N10=0,W10=0),"",X10/N10) | AJ10: =IF(U10=0,"",(U10-U10*P10-Q10-R10-N10)/U10) -> 0.288 | AL10: =IF(B10="Kept for Self","—",IF(Z10="Baseball","Apr – Oct (MLB Season)",IF(Z10="Football","Aug – Feb (NFL Season)",IF(Z10="Basketball","Oct – Jun (NBA Season)",IF(OR(Z10="Movie",Z10="TV"),IF(ISNUMBER(SEARCH("Friday the 13th",A10)),"Sep – Oct (Halloween)","Year-Round"),IF(Z10="Music","Year-Round","Year-Round")))))) -> Apr – Oct (MLB Season)
A11: Moisés Ballesteros Signed Jersey Inscribed "Mo Baller" (Beckett) | B11: Listed | C11: 4824728 | D11: 24.57 | E11: =D11 -> 24.57 | F11: =SUMIF(C:C, C11, E:E) -> 384.34 | G11: =E11/F11 -> 0.063927772 | H11: 31 | I11: =H11*G11 -> 1.9817609 | J11: 99 | K11: =J11*G11 -> 6.3288495 | L11: 38.67 | M11: =L11*G11 -> 2.472087 | N11: =E11-I11+K11+M11 -> 31.389175 | O11: eBay | P11: =IFERROR(VLOOKUP(O11,PlatformFees,2,FALSE()),0) -> 0.136 | Q11: =IFERROR(VLOOKUP(O11,PlatformFees,3,FALSE()),0) -> 0.4 | R11: 6.5 | S11: 0 | T11: =(N11+R11+Q11)/(1-(P11+S11)) -> 44.316175 | U11: =MAX(MAX(T11*1.5, T11+15), IFERROR(VLOOKUP(A11,'Pricing Intelligence'!A:J,10,FALSE),0)) -> 99.5 | V11: 125 | W11: =IFERROR(_xlfn.XLOOKUP(A11,'Sales Log'!$C$4:$C$303,'Sales Log'!$F$4:$F$303,0),0) -> 0 | X11: =IF(W11=0,0,W11-(W11*(P11+S11))-Q11-R11-N11) -> 0 | Y11: =IFERROR(IF(ISNUMBER(SEARCH("Jersey",A11)),"Jersey",IF(ISNUMBER(SEARCH("Photo",A11)),"Photo",IF(ISNUMBER(SEARCH("Baseball Bat",A11)),"Bat",IF(ISNUMBER(SEARCH("Bat",A11)),"Bat",IF(ISNUMBER(SEARCH("Baseball",A11)),"Baseball",IF(ISNUMBER(SEARCH("Football",A11)),"Football",IF(ISNUMBER(SEARCH("Mask",A11)),"Mask",IF(ISNUMBER(SEARCH("Drum",A11)),"Drum Stick",IF(ISNUMBER(SEARCH("Card",A11)),"Card",IF(ISNUMBER(SEARCH("RC",A11)),"Card","Other")))))))))),"Other") -> Jersey | Z11: Baseball | AA11: =IFERROR(TRIM(LEFT(A11,FIND(" Signed",A11)-1)),LEFT(A11,20)) -> Moisés Ballesteros | AB11: =IF(ISNUMBER(SEARCH("(Beckett)",A11)),"Beckett",IF(ISNUMBER(SEARCH("(JSA)",A11)),"JSA",IF(ISNUMBER(SEARCH("(PSA)",A11)),"PSA",IF(ISNUMBER(SEARCH("(ACOA)",A11)),"ACOA",IF(ISNUMBER(SEARCH("(Schwartz)",A11)),"Schwartz","Unlabeled"))))) -> Beckett | AD11: 46204 | AE11: 46226 | AG11: =IF(AE11="","",IF(AF11="",TODAY()-AE11,AF11-AE11)) -> 6 | AH11: =HYPERLINK("https://www.ebay.com/sch/i.html?_nkw="&SUBSTITUTE(SUBSTITUTE(A11," ","+"),"""","")&"&LH_Sold=1&LH_Complete=1","View Sold Comps") -> View Sold Comps | AI11: =IF(OR(N11=0,W11=0),"",X11/N11) | AJ11: =IF(U11=0,"",(U11-U11*P11-Q11-R11-N11)/U11) -> 0.47918417 | AL11: =IF(B11="Kept for Self","—",IF(Z11="Baseball","Apr – Oct (MLB Season)",IF(Z11="Football","Aug – Feb (NFL Season)",IF(Z11="Basketball","Oct – Jun (NBA Season)",IF(OR(Z11="Movie",Z11="TV"),IF(ISNUMBER(SEARCH("Friday the 13th",A11)),"Sep – Oct (Halloween)","Year-Round"),IF(Z11="Music","Year-Round","Year-Round")))))) -> Apr – Oct (MLB Season)
A12: Moisés Ballesteros Signed Louisville Slugger Baseball Bat (Beckett) | B12: Available | C12: 4824728 | D12: 24.57 | E12: =D12 -> 24.57 | F12: =SUMIF(C:C, C12, E:E) -> 384.34 | G12: =E12/F12 -> 0.063927772 | H12: 31 | I12: =H12*G12 -> 1.9817609 | J12: 99 | K12: =J12*G12 -> 6.3288495 | L12: 38.67 | M12: =L12*G12 -> 2.472087 | N12: =E12-I12+K12+M12 -> 31.389175 | O12: eBay | P12: =IFERROR(VLOOKUP(O12,PlatformFees,2,FALSE()),0) -> 0.136 | Q12: =IFERROR(VLOOKUP(O12,PlatformFees,3,FALSE()),0) -> 0.4 | R12: 6.5 | S12: 0 | T12: =(N12+R12+Q12)/(1-(P12+S12)) -> 44.316175 | U12: =MAX(MAX(T12*1.5, T12+15), IFERROR(VLOOKUP(A12,'Pricing Intelligence'!A:J,10,FALSE),0)) -> 122.99333 | V12: 0 | W12: =IFERROR(_xlfn.XLOOKUP(A12,'Sales Log'!$C$4:$C$303,'Sales Log'!$F$4:$F$303,0),0) -> 0 | X12: =IF(W12=0,0,W12-(W12*(P12+S12))-Q12-R12-N12) -> 0 | Y12: =IFERROR(IF(ISNUMBER(SEARCH("Jersey",A12)),"Jersey",IF(ISNUMBER(SEARCH("Photo",A12)),"Photo",IF(ISNUMBER(SEARCH("Baseball Bat",A12)),"Bat",IF(ISNUMBER(SEARCH("Bat",A12)),"Bat",IF(ISNUMBER(SEARCH("Baseball",A12)),"Baseball",IF(ISNUMBER(SEARCH("Football",A12)),"Football",IF(ISNUMBER(SEARCH("Mask",A12)),"Mask",IF(ISNUMBER(SEARCH("Drum",A12)),"Drum Stick",IF(ISNUMBER(SEARCH("Card",A12)),"Card",IF(ISNUMBER(SEARCH("RC",A12)),"Card","Other")))))))))),"Other") -> Bat | Z12: Baseball | AA12: =IFERROR(TRIM(LEFT(A12,FIND(" Signed",A12)-1)),LEFT(A12,20)) -> Moisés Ballesteros | AB12: =IF(ISNUMBER(SEARCH("(Beckett)",A12)),"Beckett",IF(ISNUMBER(SEARCH("(JSA)",A12)),"JSA",IF(ISNUMBER(SEARCH("(PSA)",A12)),"PSA",IF(ISNUMBER(SEARCH("(ACOA)",A12)),"ACOA",IF(ISNUMBER(SEARCH("(Schwartz)",A12)),"Schwartz","Unlabeled"))))) -> Beckett | AD12: 46204 | AG12: =IF(AE12="","",IF(AF12="",TODAY()-AE12,AF12-AE12)) | AH12: =HYPERLINK("https://www.ebay.com/sch/i.html?_nkw="&SUBSTITUTE(SUBSTITUTE(A12," ","+"),"""","")&"&LH_Sold=1&LH_Complete=1","View Sold Comps") -> View Sold Comps | AI12: =IF(OR(N12=0,W12=0),"",X12/N12) | AJ12: =IF(U12=0,"",(U12-U12*P12-Q12-R12-N12)/U12) -> 0.55268902 | AL12: =IF(B12="Kept for Self","—",IF(Z12="Baseball","Apr – Oct (MLB Season)",IF(Z12="Football","Aug – Feb (NFL Season)",IF(Z12="Basketball","Oct – Jun (NBA Season)",IF(OR(Z12="Movie",Z12="TV"),IF(ISNUMBER(SEARCH("Friday the 13th",A12)),"Sep – Oct (Halloween)","Year-Round"),IF(Z12="Music","Year-Round","Year-Round")))))) -> Apr – Oct (MLB Season)
A13: Moisés Ballesteros Signed Jersey (Beckett) | B13: Listed | C13: 4824728 | D13: 24.57 | E13: =D13 -> 24.57 | F13: =SUMIF(C:C, C13, E:E) -> 384.34 | G13: =E13/F13 -> 0.063927772 | H13: 31 | I13: =H13*G13 -> 1.9817609 | J13: 99 | K13: =J13*G13 -> 6.3288495 | L13: 38.67 | M13: =L13*G13 -> 2.472087 | N13: =E13-I13+K13+M13 -> 31.389175 | O13: eBay | P13: =IFERROR(VLOOKUP(O13,PlatformFees,2,FALSE()),0) -> 0.136 | Q13: =IFERROR(VLOOKUP(O13,PlatformFees,3,FALSE()),0) -> 0.4 | R13: 6.5 | S13: 0 | T13: =(N13+R13+Q13)/(1-(P13+S13)) -> 44.316175 | U13: =MAX(MAX(T13*1.5, T13+15), IFERROR(VLOOKUP(A13,'Pricing Intelligence'!A:J,10,FALSE),0)) -> 99.5 | V13: 109.99 | W13: =IFERROR(_xlfn.XLOOKUP(A13,'Sales Log'!$C$4:$C$303,'Sales Log'!$F$4:$F$303,0),0) -> 0 | X13: =IF(W13=0,0,W13-(W13*(P13+S13))-Q13-R13-N13) -> 0 | Y13: =IFERROR(IF(ISNUMBER(SEARCH("Jersey",A13)),"Jersey",IF(ISNUMBER(SEARCH("Photo",A13)),"Photo",IF(ISNUMBER(SEARCH("Baseball Bat",A13)),"Bat",IF(ISNUMBER(SEARCH("Bat",A13)),"Bat",IF(ISNUMBER(SEARCH("Baseball",A13)),"Baseball",IF(ISNUMBER(SEARCH("Football",A13)),"Football",IF(ISNUMBER(SEARCH("Mask",A13)),"Mask",IF(ISNUMBER(SEARCH("Drum",A13)),"Drum Stick",IF(ISNUMBER(SEARCH("Card",A13)),"Card",IF(ISNUMBER(SEARCH("RC",A13)),"Card","Other")))))))))),"Other") -> Jersey | Z13: Baseball | AA13: =IFERROR(TRIM(LEFT(A13,FIND(" Signed",A13)-1)),LEFT(A13,20)) -> Moisés Ballesteros | AB13: =IF(ISNUMBER(SEARCH("(Beckett)",A13)),"Beckett",IF(ISNUMBER(SEARCH("(JSA)",A13)),"JSA",IF(ISNUMBER(SEARCH("(PSA)",A13)),"PSA",IF(ISNUMBER(SEARCH("(ACOA)",A13)),"ACOA",IF(ISNUMBER(SEARCH("(Schwartz)",A13)),"Schwartz","Unlabeled"))))) -> Beckett | AD13: 46204 | AE13: 46226 | AG13: =IF(AE13="","",IF(AF13="",TODAY()-AE13,AF13-AE13)) -> 6 | AH13: =HYPERLINK("https://www.ebay.com/sch/i.html?_nkw="&SUBSTITUTE(SUBSTITUTE(A13," ","+"),"""","")&"&LH_Sold=1&LH_Complete=1","View Sold Comps") -> View Sold Comps | AI13: =IF(OR(N13=0,W13=0),"",X13/N13) | AJ13: =IF(U13=0,"",(U13-U13*P13-Q13-R13-N13)/U13) -> 0.47918417 | AL13: =IF(B13="Kept for Self","—",IF(Z13="Baseball","Apr – Oct (MLB Season)",IF(Z13="Football","Aug – Feb (NFL Season)",IF(Z13="Basketball","Oct – Jun (NBA Season)",IF(OR(Z13="Movie",Z13="TV"),IF(ISNUMBER(SEARCH("Friday the 13th",A13)),"Sep – Oct (Halloween)","Year-Round"),IF(Z13="Music","Year-Round","Year-Round")))))) -> Apr – Oct (MLB Season)
A14: Sammy Sosa Signed Louisville Slugger Baseball Bat (Beckett) | B14: Available | C14: 4824728 | D14: 30.72 | E14: =D14 -> 30.72 | F14: =SUMIF(C:C, C14, E:E) -> 384.34 | G14: =E14/F14 -> 0.079929229 | H14: 31 | I14: =H14*G14 -> 2.4778061 | J14: 99 | K14: =J14*G14 -> 7.9129937 | L14: 38.67 | M14: =L14*G14 -> 3.0908633 | N14: =E14-I14+K14+M14 -> 39.246051 | O14: eBay | P14: =IFERROR(VLOOKUP(O14,PlatformFees,2,FALSE()),0) -> 0.136 | Q14: =IFERROR(VLOOKUP(O14,PlatformFees,3,FALSE()),0) -> 0.4 | R14: 6.5 | S14: 0 | T14: =(N14+R14+Q14)/(1-(P14+S14)) -> 53.409781 | U14: =MAX(MAX(T14*1.5, T14+15), IFERROR(VLOOKUP(A14,'Pricing Intelligence'!A:J,10,FALSE),0)) -> 106.66667 | V14: 0 | W14: =IFERROR(_xlfn.XLOOKUP(A14,'Sales Log'!$C$4:$C$303,'Sales Log'!$F$4:$F$303,0),0) -> 0 | X14: =IF(W14=0,0,W14-(W14*(P14+S14))-Q14-R14-N14) -> 0 | Y14: =IFERROR(IF(ISNUMBER(SEARCH("Jersey",A14)),"Jersey",IF(ISNUMBER(SEARCH("Photo",A14)),"Photo",IF(ISNUMBER(SEARCH("Baseball Bat",A14)),"Bat",IF(ISNUMBER(SEARCH("Bat",A14)),"Bat",IF(ISNUMBER(SEARCH("Baseball",A14)),"Baseball",IF(ISNUMBER(SEARCH("Football",A14)),"Football",IF(ISNUMBER(SEARCH("Mask",A14)),"Mask",IF(ISNUMBER(SEARCH("Drum",A14)),"Drum Stick",IF(ISNUMBER(SEARCH("Card",A14)),"Card",IF(ISNUMBER(SEARCH("RC",A14)),"Card","Other")))))))))),"Other") -> Bat | Z14: Baseball | AA14: =IFERROR(TRIM(LEFT(A14,FIND(" Signed",A14)-1)),LEFT(A14,20)) -> Sammy Sosa | AB14: =IF(ISNUMBER(SEARCH("(Beckett)",A14)),"Beckett",IF(ISNUMBER(SEARCH("(JSA)",A14)),"JSA",IF(ISNUMBER(SEARCH("(PSA)",A14)),"PSA",IF(ISNUMBER(SEARCH("(ACOA)",A14)),"ACOA",IF(ISNUMBER(SEARCH("(Schwartz)",A14)),"Schwartz","Unlabeled"))))) -> Beckett | AD14: 46204 | AG14: =IF(AE14="","",IF(AF14="",TODAY()-AE14,AF14-AE14)) | AH14: =HYPERLINK("https://www.ebay.com/sch/i.html?_nkw="&SUBSTITUTE(SUBSTITUTE(A14," ","+"),"""","")&"&LH_Sold=1&LH_Complete=1","View Sold Comps") -> View Sold Comps | AI14: =IF(OR(N14=0,W14=0),"",X14/N14) | AJ14: =IF(U14=0,"",(U14-U14*P14-Q14-R14-N14)/U14) -> 0.43138077 | AL14: =IF(B14="Kept for Self","—",IF(Z14="Baseball","Apr – Oct (MLB Season)",IF(Z14="Football","Aug – Feb (NFL Season)",IF(Z14="Basketball","Oct – Jun (NBA Season)",IF(OR(Z14="Movie",Z14="TV"),IF(ISNUMBER(SEARCH("Friday the 13th",A14)),"Sep – Oct (Halloween)","Year-Round"),IF(Z14="Music","Year-Round","Year-Round")))))) -> Apr – Oct (MLB Season)
A15: Sammy Sosa Signed Louisville Slugger Baseball Bat (JSA) | B15: Available | C15: 4824728 | D15: 30.72 | E15: =D15 -> 30.72 | F15: =SUMIF(C:C, C15, E:E) -> 384.34 | G15: =E15/F15 -> 0.079929229 | H15: 31 | I15: =H15*G15 -> 2.4778061 | J15: 99 | K15: =J15*G15 -> 7.9129937 | L15: 38.67 | M15: =L15*G15 -> 3.0908633 | N15: =E15-I15+K15+M15 -> 39.246051 | O15: eBay | P15: =IFERROR(VLOOKUP(O15,PlatformFees,2,FALSE()),0) -> 0.136 | Q15: =IFERROR(VLOOKUP(O15,PlatformFees,3,FALSE()),0) -> 0.4 | R15: 6.5 | S15: 0 | T15: =(N15+R15+Q15)/(1-(P15+S15)) -> 53.409781 | U15: =MAX(MAX(T15*1.5, T15+15), IFERROR(VLOOKUP(A15,'Pricing Intelligence'!A:J,10,FALSE),0)) -> 108 | V15: 0 | W15: =IFERROR(_xlfn.XLOOKUP(A15,'Sales Log'!$C$4:$C$303,'Sales Log'!$F$4:$F$303,0),0) -> 0 | X15: =IF(W15=0,0,W15-(W15*(P15+S15))-Q15-R15-N15) -> 0 | Y15: =IFERROR(IF(ISNUMBER(SEARCH("Jersey",A15)),"Jersey",IF(ISNUMBER(SEARCH("Photo",A15)),"Photo",IF(ISNUMBER(SEARCH("Baseball Bat",A15)),"Bat",IF(ISNUMBER(SEARCH("Bat",A15)),"Bat",IF(ISNUMBER(SEARCH("Baseball",A15)),"Baseball",IF(ISNUMBER(SEARCH("Football",A15)),"Football",IF(ISNUMBER(SEARCH("Mask",A15)),"Mask",IF(ISNUMBER(SEARCH("Drum",A15)),"Drum Stick",IF(ISNUMBER(SEARCH("Card",A15)),"Card",IF(ISNUMBER(SEARCH("RC",A15)),"Card","Other")))))))))),"Other") -> Bat | Z15: Baseball | AA15: =IFERROR(TRIM(LEFT(A15,FIND(" Signed",A15)-1)),LEFT(A15,20)) -> Sammy Sosa | AB15: =IF(ISNUMBER(SEARCH("(Beckett)",A15)),"Beckett",IF(ISNUMBER(SEARCH("(JSA)",A15)),"JSA",IF(ISNUMBER(SEARCH("(PSA)",A15)),"PSA",IF(ISNUMBER(SEARCH("(ACOA)",A15)),"ACOA",IF(ISNUMBER(SEARCH("(Schwartz)",A15)),"Schwartz","Unlabeled"))))) -> JSA | AD15: 46204 | AG15: =IF(AE15="","",IF(AF15="",TODAY()-AE15,AF15-AE15)) | AH15: =HYPERLINK("https://www.ebay.com/sch/i.html?_nkw="&SUBSTITUTE(SUBSTITUTE(A15," ","+"),"""","")&"&LH_Sold=1&LH_Complete=1","View Sold Comps") -> View Sold Comps | AI15: =IF(OR(N15=0,W15=0),"",X15/N15) | AJ15: =IF(U15=0,"",(U15-U15*P15-Q15-R15-N15)/U15) -> 0.43672175 | AL15: =IF(B15="Kept for Self","—",IF(Z15="Baseball","Apr – Oct (MLB Season)",IF(Z15="Football","Aug – Feb (NFL Season)",IF(Z15="Basketball","Oct – Jun (NBA Season)",IF(OR(Z15="Movie",Z15="TV"),IF(ISNUMBER(SEARCH("Friday the 13th",A15)),"Sep – Oct (Halloween)","Year-Round"),IF(Z15="Music","Year-Round","Year-Round")))))) -> Apr – Oct (MLB Season)
A16: Sammy Sosa Signed Jersey (JSA) | B16: Listed | C16: 4824728 | D16: 26.48 | E16: =D16 -> 26.48 | F16: =SUMIF(C:C, C16, E:E) -> 384.34 | G16: =E16/F16 -> 0.06889733 | H16: 31 | I16: =H16*G16 -> 2.1358172 | J16: 99 | K16: =J16*G16 -> 6.8208357 | L16: 38.67 | M16: =L16*G16 -> 2.6642598 | N16: =E16-I16+K16+M16 -> 33.829278 | O16: eBay | P16: =IFERROR(VLOOKUP(O16,PlatformFees,2,FALSE()),0) -> 0.136 | Q16: =IFERROR(VLOOKUP(O16,PlatformFees,3,FALSE()),0) -> 0.4 | R16: 6.5 | S16: 0 | T16: =(N16+R16+Q16)/(1-(P16+S16)) -> 47.140368 | U16: =MAX(MAX(T16*1.5, T16+15), IFERROR(VLOOKUP(A16,'Pricing Intelligence'!A:J,10,FALSE),0)) -> 70.710553 | V16: 63 | W16: =IFERROR(_xlfn.XLOOKUP(A16,'Sales Log'!$C$4:$C$303,'Sales Log'!$F$4:$F$303,0),0) -> 0 | X16: =IF(W16=0,0,W16-(W16*(P16+S16))-Q16-R16-N16) -> 0 | Y16: =IFERROR(IF(ISNUMBER(SEARCH("Jersey",A16)),"Jersey",IF(ISNUMBER(SEARCH("Photo",A16)),"Photo",IF(ISNUMBER(SEARCH("Baseball Bat",A16)),"Bat",IF(ISNUMBER(SEARCH("Bat",A16)),"Bat",IF(ISNUMBER(SEARCH("Baseball",A16)),"Baseball",IF(ISNUMBER(SEARCH("Football",A16)),"Football",IF(ISNUMBER(SEARCH("Mask",A16)),"Mask",IF(ISNUMBER(SEARCH("Drum",A16)),"Drum Stick",IF(ISNUMBER(SEARCH("Card",A16)),"Card",IF(ISNUMBER(SEARCH("RC",A16)),"Card","Other")))))))))),"Other") -> Jersey | Z16: Baseball | AA16: =IFERROR(TRIM(LEFT(A16,FIND(" Signed",A16)-1)),LEFT(A16,20)) -> Sammy Sosa | AB16: =IF(ISNUMBER(SEARCH("(Beckett)",A16)),"Beckett",IF(ISNUMBER(SEARCH("(JSA)",A16)),"JSA",IF(ISNUMBER(SEARCH("(PSA)",A16)),"PSA",IF(ISNUMBER(SEARCH("(ACOA)",A16)),"ACOA",IF(ISNUMBER(SEARCH("(Schwartz)",A16)),"Schwartz","Unlabeled"))))) -> JSA | AD16: 46204 | AE16: 46226 | AG16: =IF(AE16="","",IF(AF16="",TODAY()-AE16,AF16-AE16)) -> 6 | AH16: =HYPERLINK("https://www.ebay.com/sch/i.html?_nkw="&SUBSTITUTE(SUBSTITUTE(A16," ","+"),"""","")&"&LH_Sold=1&LH_Complete=1","View Sold Comps") -> View Sold Comps | AI16: =IF(OR(N16=0,W16=0),"",X16/N16) | AJ16: =IF(U16=0,"",(U16-U16*P16-Q16-R16-N16)/U16) -> 0.288 | AL16: =IF(B16="Kept for Self","—",IF(Z16="Baseball","Apr – Oct (MLB Season)",IF(Z16="Football","Aug – Feb (NFL Season)",IF(Z16="Basketball","Oct – Jun (NBA Season)",IF(OR(Z16="Movie",Z16="TV"),IF(ISNUMBER(SEARCH("Friday the 13th",A16)),"Sep – Oct (Halloween)","Year-Round"),IF(Z16="Music","Year-Round","Year-Round")))))) -> Apr – Oct (MLB Season)
A17: Sammy Sosa Signed Jersey (JSA) | B17: Listed | C17: 4824728 | D17: 34.21 | E17: =D17 -> 34.21 | F17: =SUMIF(C:C, C17, E:E) -> 384.34 | G17: =E17/F17 -> 0.089009731 | H17: 31 | I17: =H17*G17 -> 2.7593017 | J17: 99 | K17: =J17*G17 -> 8.8119634 | L17: 38.67 | M17: =L17*G17 -> 3.4420063 | N17: =E17-I17+K17+M17 -> 43.704668 | O17: eBay | P17: =IFERROR(VLOOKUP(O17,PlatformFees,2,FALSE()),0) -> 0.136 | Q17: =IFERROR(VLOOKUP(O17,PlatformFees,3,FALSE()),0) -> 0.4 | R17: 6.5 | S17: 0 | T17: =(N17+R17+Q17)/(1-(P17+S17)) -> 58.570218 | U17: =MAX(MAX(T17*1.5, T17+15), IFERROR(VLOOKUP(A17,'Pricing Intelligence'!A:J,10,FALSE),0)) -> 87.855326 | V17: 63 | W17: =IFERROR(_xlfn.XLOOKUP(A17,'Sales Log'!$C$4:$C$303,'Sales Log'!$F$4:$F$303,0),0) -> 0 | X17: =IF(W17=0,0,W17-(W17*(P17+S17))-Q17-R17-N17) -> 0 | Y17: =IFERROR(IF(ISNUMBER(SEARCH("Jersey",A17)),"Jersey",IF(ISNUMBER(SEARCH("Photo",A17)),"Photo",IF(ISNUMBER(SEARCH("Baseball Bat",A17)),"Bat",IF(ISNUMBER(SEARCH("Bat",A17)),"Bat",IF(ISNUMBER(SEARCH("Baseball",A17)),"Baseball",IF(ISNUMBER(SEARCH("Football",A17)),"Football",IF(ISNUMBER(SEARCH("Mask",A17)),"Mask",IF(ISNUMBER(SEARCH("Drum",A17)),"Drum Stick",IF(ISNUMBER(SEARCH("Card",A17)),"Card",IF(ISNUMBER(SEARCH("RC",A17)),"Card","Other")))))))))),"Other") -> Jersey | Z17: Baseball | AA17: =IFERROR(TRIM(LEFT(A17,FIND(" Signed",A17)-1)),LEFT(A17,20)) -> Sammy Sosa | AB17: =IF(ISNUMBER(SEARCH("(Beckett)",A17)),"Beckett",IF(ISNUMBER(SEARCH("(JSA)",A17)),"JSA",IF(ISNUMBER(SEARCH("(PSA)",A17)),"PSA",IF(ISNUMBER(SEARCH("(ACOA)",A17)),"ACOA",IF(ISNUMBER(SEARCH("(Schwartz)",A17)),"Schwartz","Unlabeled"))))) -> JSA | AD17: 46204 | AE17: 46226 | AG17: =IF(AE17="","",IF(AF17="",TODAY()-AE17,AF17-AE17)) -> 6 | AH17: =HYPERLINK("https://www.ebay.com/sch/i.html?_nkw="&SUBSTITUTE(SUBSTITUTE(A17," ","+"),"""","")&"&LH_Sold=1&LH_Complete=1","View Sold Comps") -> View Sold Comps | AI17: =IF(OR(N17=0,W17=0),"",X17/N17) | AJ17: =IF(U17=0,"",(U17-U17*P17-Q17-R17-N17)/U17) -> 0.288 | AL17: =IF(B17="Kept for Self","—",IF(Z17="Baseball","Apr – Oct (MLB Season)",IF(Z17="Football","Aug – Feb (NFL Season)",IF(Z17="Basketball","Oct – Jun (NBA Season)",IF(OR(Z17="Movie",Z17="TV"),IF(ISNUMBER(SEARCH("Friday the 13th",A17)),"Sep – Oct (Halloween)","Year-Round"),IF(Z17="Music","Year-Round","Year-Round")))))) -> Apr – Oct (MLB Season)
A18: Sammy Sosa Signed Louisville Slugger Baseball Bat (Beckett) | B18: Available | C18: 4824728 | D18: 34.25 | E18: =D18 -> 34.25 | F18: =SUMIF(C:C, C18, E:E) -> 384.34 | G18: =E18/F18 -> 0.089113805 | H18: 31 | I18: =H18*G18 -> 2.762528 | J18: 99 | K18: =J18*G18 -> 8.8222667 | L18: 38.67 | M18: =L18*G18 -> 3.4460309 | N18: =E18-I18+K18+M18 -> 43.75577 | O18: eBay | P18: =IFERROR(VLOOKUP(O18,PlatformFees,2,FALSE()),0) -> 0.136 | Q18: =IFERROR(VLOOKUP(O18,PlatformFees,3,FALSE()),0) -> 0.4 | R18: 6.5 | S18: 0 | T18: =(N18+R18+Q18)/(1-(P18+S18)) -> 58.629363 | U18: =MAX(MAX(T18*1.5, T18+15), IFERROR(VLOOKUP(A18,'Pricing Intelligence'!A:J,10,FALSE),0)) -> 106.66667 | V18: 0 | W18: =IFERROR(_xlfn.XLOOKUP(A18,'Sales Log'!$C$4:$C$303,'Sales Log'!$F$4:$F$303,0),0) -> 0 | X18: =IF(W18=0,0,W18-(W18*(P18+S18))-Q18-R18-N18) -> 0 | Y18: =IFERROR(IF(ISNUMBER(SEARCH("Jersey",A18)),"Jersey",IF(ISNUMBER(SEARCH("Photo",A18)),"Photo",IF(ISNUMBER(SEARCH("Baseball Bat",A18)),"Bat",IF(ISNUMBER(SEARCH("Bat",A18)),"Bat",IF(ISNUMBER(SEARCH("Baseball",A18)),"Baseball",IF(ISNUMBER(SEARCH("Football",A18)),"Football",IF(ISNUMBER(SEARCH("Mask",A18)),"Mask",IF(ISNUMBER(SEARCH("Drum",A18)),"Drum Stick",IF(ISNUMBER(SEARCH("Card",A18)),"Card",IF(ISNUMBER(SEARCH("RC",A18)),"Card","Other")))))))))),"Other") -> Bat | Z18: Baseball | AA18: =IFERROR(TRIM(LEFT(A18,FIND(" Signed",A18)-1)),LEFT(A18,20)) -> Sammy Sosa | AB18: =IF(ISNUMBER(SEARCH("(Beckett)",A18)),"Beckett",IF(ISNUMBER(SEARCH("(JSA)",A18)),"JSA",IF(ISNUMBER(SEARCH("(PSA)",A18)),"PSA",IF(ISNUMBER(SEARCH("(ACOA)",A18)),"ACOA",IF(ISNUMBER(SEARCH("(Schwartz)",A18)),"Schwartz","Unlabeled"))))) -> Beckett | AD18: 46204 | AG18: =IF(AE18="","",IF(AF18="",TODAY()-AE18,AF18-AE18)) | AH18: =HYPERLINK("https://www.ebay.com/sch/i.html?_nkw="&SUBSTITUTE(SUBSTITUTE(A18," ","+"),"""","")&"&LH_Sold=1&LH_Complete=1","View Sold Comps") -> View Sold Comps | AI18: =IF(OR(N18=0,W18=0),"",X18/N18) | AJ18: =IF(U18=0,"",(U18-U18*P18-Q18-R18-N18)/U18) -> 0.38910216 | AL18: =IF(B18="Kept for Self","—",IF(Z18="Baseball","Apr – Oct (MLB Season)",IF(Z18="Football","Aug – Feb (NFL Season)",IF(Z18="Basketball","Oct – Jun (NBA Season)",IF(OR(Z18="Movie",Z18="TV"),IF(ISNUMBER(SEARCH("Friday the 13th",A18)),"Sep – Oct (Halloween)","Year-Round"),IF(Z18="Music","Year-Round","Year-Round")))))) -> Apr – Oct (MLB Season)
A19: Donte DiVincenzo Signed Jersey (Beckett) | B19: Available | C19: 4824728 | D19: 18.43 | E19: =D19 -> 18.43 | F19: =SUMIF(C:C, C19, E:E) -> 384.34 | G19: =E19/F19 -> 0.047952334 | H19: 31 | I19: =H19*G19 -> 1.4865224 | J19: 99 | K19: =J19*G19 -> 4.7472811 | L19: 38.67 | M19: =L19*G19 -> 1.8543168 | N19: =E19-I19+K19+M19 -> 23.545075 | O19: eBay | P19: =IFERROR(VLOOKUP(O19,PlatformFees,2,FALSE()),0) -> 0.136 | Q19: =IFERROR(VLOOKUP(O19,PlatformFees,3,FALSE()),0) -> 0.4 | R19: 6.5 | S19: 0 | T19: =(N19+R19+Q19)/(1-(P19+S19)) -> 35.237356 | U19: =MAX(MAX(T19*1.5, T19+15), IFERROR(VLOOKUP(A19,'Pricing Intelligence'!A:J,10,FALSE),0)) -> 52.856034 | V19: 0 | W19: =IFERROR(_xlfn.XLOOKUP(A19,'Sales Log'!$C$4:$C$303,'Sales Log'!$F$4:$F$303,0),0) -> 0 | X19: =IF(W19=0,0,W19-(W19*(P19+S19))-Q19-R19-N19) -> 0 | Y19: =IFERROR(IF(ISNUMBER(SEARCH("Jersey",A19)),"Jersey",IF(ISNUMBER(SEARCH("Photo",A19)),"Photo",IF(ISNUMBER(SEARCH("Baseball Bat",A19)),"Bat",IF(ISNUMBER(SEARCH("Bat",A19)),"Bat",IF(ISNUMBER(SEARCH("Baseball",A19)),"Baseball",IF(ISNUMBER(SEARCH("Football",A19)),"Football",IF(ISNUMBER(SEARCH("Mask",A19)),"Mask",IF(ISNUMBER(SEARCH("Drum",A19)),"Drum Stick",IF(ISNUMBER(SEARCH("Card",A19)),"Card",IF(ISNUMBER(SEARCH("RC",A19)),"Card","Other")))))))))),"Other") -> Jersey | Z19: Basketball | AA19: =IFERROR(TRIM(LEFT(A19,FIND(" Signed",A19)-1)),LEFT(A19,20)) -> Donte DiVincenzo | AB19: =IF(ISNUMBER(SEARCH("(Beckett)",A19)),"Beckett",IF(ISNUMBER(SEARCH("(JSA)",A19)),"JSA",IF(ISNUMBER(SEARCH("(PSA)",A19)),"PSA",IF(ISNUMBER(SEARCH("(ACOA)",A19)),"ACOA",IF(ISNUMBER(SEARCH("(Schwartz)",A19)),"Schwartz","Unlabeled"))))) -> Beckett | AD19: 46204 | AG19: =IF(AE19="","",IF(AF19="",TODAY()-AE19,AF19-AE19)) | AH19: =HYPERLINK("https://www.ebay.com/sch/i.html?_nkw="&SUBSTITUTE(SUBSTITUTE(A19," ","+"),"""","")&"&LH_Sold=1&LH_Complete=1","View Sold Comps") -> View Sold Comps | AI19: =IF(OR(N19=0,W19=0),"",X19/N19) | AJ19: =IF(U19=0,"",(U19-U19*P19-Q19-R19-N19)/U19) -> 0.288 | AL19: =IF(B19="Kept for Self","—",IF(Z19="Baseball","Apr – Oct (MLB Season)",IF(Z19="Football","Aug – Feb (NFL Season)",IF(Z19="Basketball","Oct – Jun (NBA Season)",IF(OR(Z19="Movie",Z19="TV"),IF(ISNUMBER(SEARCH("Friday the 13th",A19)),"Sep – Oct (Halloween)","Year-Round"),IF(Z19="Music","Year-Round","Year-Round")))))) -> Oct – Jun (NBA Season)
A20: Derek Harper Signed Jersey (JSA) | B20: Available | C20: 4824728 | D20: 24.57 | E20: =D20 -> 24.57 | F20: =SUMIF(C:C, C20, E:E) -> 384.34 | G20: =E20/F20 -> 0.063927772 | H20: 31 | I20: =H20*G20 -> 1.9817609 | J20: 99 | K20: =J20*G20 -> 6.3288495 | L20: 38.67 | M20: =L20*G20 -> 2.472087 | N20: =E20-I20+K20+M20 -> 31.389175 | O20: eBay | P20: =IFERROR(VLOOKUP(O20,PlatformFees,2,FALSE()),0) -> 0.136 | Q20: =IFERROR(VLOOKUP(O20,PlatformFees,3,FALSE()),0) -> 0.4 | R20: 6.5 | S20: 0 | T20: =(N20+R20+Q20)/(1-(P20+S20)) -> 44.316175 | U20: =MAX(MAX(T20*1.5, T20+15), IFERROR(VLOOKUP(A20,'Pricing Intelligence'!A:J,10,FALSE),0)) -> 66.474263 | V20: 0 | W20: =IFERROR(_xlfn.XLOOKUP(A20,'Sales Log'!$C$4:$C$303,'Sales Log'!$F$4:$F$303,0),0) -> 0 | X20: =IF(W20=0,0,W20-(W20*(P20+S20))-Q20-R20-N20) -> 0 | Y20: =IFERROR(IF(ISNUMBER(SEARCH("Jersey",A20)),"Jersey",IF(ISNUMBER(SEARCH("Photo",A20)),"Photo",IF(ISNUMBER(SEARCH("Baseball Bat",A20)),"Bat",IF(ISNUMBER(SEARCH("Bat",A20)),"Bat",IF(ISNUMBER(SEARCH("Baseball",A20)),"Baseball",IF(ISNUMBER(SEARCH("Football",A20)),"Football",IF(ISNUMBER(SEARCH("Mask",A20)),"Mask",IF(ISNUMBER(SEARCH("Drum",A20)),"Drum Stick",IF(ISNUMBER(SEARCH("Card",A20)),"Card",IF(ISNUMBER(SEARCH("RC",A20)),"Card","Other")))))))))),"Other") -> Jersey | Z20: Basketball | AA20: =IFERROR(TRIM(LEFT(A20,FIND(" Signed",A20)-1)),LEFT(A20,20)) -> Derek Harper | AB20: =IF(ISNUMBER(SEARCH("(Beckett)",A20)),"Beckett",IF(ISNUMBER(SEARCH("(JSA)",A20)),"JSA",IF(ISNUMBER(SEARCH("(PSA)",A20)),"PSA",IF(ISNUMBER(SEARCH("(ACOA)",A20)),"ACOA",IF(ISNUMBER(SEARCH("(Schwartz)",A20)),"Schwartz","Unlabeled"))))) -> JSA | AD20: 46204 | AG20: =IF(AE20="","",IF(AF20="",TODAY()-AE20,AF20-AE20)) | AH20: =HYPERLINK("https://www.ebay.com/sch/i.html?_nkw="&SUBSTITUTE(SUBSTITUTE(A20," ","+"),"""","")&"&LH_Sold=1&LH_Complete=1","View Sold Comps") -> View Sold Comps | AI20: =IF(OR(N20=0,W20=0),"",X20/N20) | AJ20: =IF(U20=0,"",(U20-U20*P20-Q20-R20-N20)/U20) -> 0.288 | AL20: =IF(B20="Kept for Self","—",IF(Z20="Baseball","Apr – Oct (MLB Season)",IF(Z20="Football","Aug – Feb (NFL Season)",IF(Z20="Basketball","Oct – Jun (NBA Season)",IF(OR(Z20="Movie",Z20="TV"),IF(ISNUMBER(SEARCH("Friday the 13th",A20)),"Sep – Oct (Halloween)","Year-Round"),IF(Z20="Music","Year-Round","Year-Round")))))) -> Oct – Jun (NBA Season)
A21: Jamal Anderson Signed Jersey (JSA) | B21: Available | C21: 4824728 | D21: 19.11 | E21: =D21 -> 19.11 | F21: =SUMIF(C:C, C21, E:E) -> 384.34 | G21: =E21/F21 -> 0.049721601 | H21: 31 | I21: =H21*G21 -> 1.5413696 | J21: 99 | K21: =J21*G21 -> 4.9224385 | L21: 38.67 | M21: =L21*G21 -> 1.9227343 | N21: =E21-I21+K21+M21 -> 24.413803 | O21: eBay | P21: =IFERROR(VLOOKUP(O21,PlatformFees,2,FALSE()),0) -> 0.136 | Q21: =IFERROR(VLOOKUP(O21,PlatformFees,3,FALSE()),0) -> 0.4 | R21: 6.5 | S21: 0 | T21: =(N21+R21+Q21)/(1-(P21+S21)) -> 36.242828 | U21: =MAX(MAX(T21*1.5, T21+15), IFERROR(VLOOKUP(A21,'Pricing Intelligence'!A:J,10,FALSE),0)) -> 54.364242 | V21: 0 | W21: =IFERROR(_xlfn.XLOOKUP(A21,'Sales Log'!$C$4:$C$303,'Sales Log'!$F$4:$F$303,0),0) -> 0 | X21: =IF(W21=0,0,W21-(W21*(P21+S21))-Q21-R21-N21) -> 0 | Y21: =IFERROR(IF(ISNUMBER(SEARCH("Jersey",A21)),"Jersey",IF(ISNUMBER(SEARCH("Photo",A21)),"Photo",IF(ISNUMBER(SEARCH("Baseball Bat",A21)),"Bat",IF(ISNUMBER(SEARCH("Bat",A21)),"Bat",IF(ISNUMBER(SEARCH("Baseball",A21)),"Baseball",IF(ISNUMBER(SEARCH("Football",A21)),"Football",IF(ISNUMBER(SEARCH("Mask",A21)),"Mask",IF(ISNUMBER(SEARCH("Drum",A21)),"Drum Stick",IF(ISNUMBER(SEARCH("Card",A21)),"Card",IF(ISNUMBER(SEARCH("RC",A21)),"Card","Other")))))))))),"Other") -> Jersey | Z21: Football | AA21: =IFERROR(TRIM(LEFT(A21,FIND(" Signed",A21)-1)),LEFT(A21,20)) -> Jamal Anderson | AB21: =IF(ISNUMBER(SEARCH("(Beckett)",A21)),"Beckett",IF(ISNUMBER(SEARCH("(JSA)",A21)),"JSA",IF(ISNUMBER(SEARCH("(PSA)",A21)),"PSA",IF(ISNUMBER(SEARCH("(ACOA)",A21)),"ACOA",IF(ISNUMBER(SEARCH("(Schwartz)",A21)),"Schwartz","Unlabeled"))))) -> JSA | AD21: 46204 | AG21: =IF(AE21="","",IF(AF21="",TODAY()-AE21,AF21-AE21)) | AH21: =HYPERLINK("https://www.ebay.com/sch/i.html?_nkw="&SUBSTITUTE(SUBSTITUTE(A21," ","+"),"""","")&"&LH_Sold=1&LH_Complete=1","View Sold Comps") -> View Sold Comps | AI21: =IF(OR(N21=0,W21=0),"",X21/N21) | AJ21: =IF(U21=0,"",(U21-U21*P21-Q21-R21-N21)/U21) -> 0.288 | AL21: =IF(B21="Kept for Self","—",IF(Z21="Baseball","Apr – Oct (MLB Season)",IF(Z21="Football","Aug – Feb (NFL Season)",IF(Z21="Basketball","Oct – Jun (NBA Season)",IF(OR(Z21="Movie",Z21="TV"),IF(ISNUMBER(SEARCH("Friday the 13th",A21)),"Sep – Oct (Halloween)","Year-Round"),IF(Z21="Music","Year-Round","Year-Round")))))) -> Aug – Feb (NFL Season)
A22: Kyle Tucker Signed Jersey (JSA) | B22: Listed | C22: 4824728 | D22: 24.57 | E22: =D22 -> 24.57 | F22: =SUMIF(C:C, C22, E:E) -> 384.34 | G22: =E22/F22 -> 0.063927772 | H22: 31 | I22: =H22*G22 -> 1.9817609 | J22: 99 | K22: =J22*G22 -> 6.3288495 | L22: 38.67 | M22: =L22*G22 -> 2.472087 | N22: =E22-I22+K22+M22 -> 31.389175 | O22: eBay | P22: =IFERROR(VLOOKUP(O22,PlatformFees,2,FALSE()),0) -> 0.136 | Q22: =IFERROR(VLOOKUP(O22,PlatformFees,3,FALSE()),0) -> 0.4 | R22: 6.5 | S22: 0 | T22: =(N22+R22+Q22)/(1-(P22+S22)) -> 44.316175 | U22: =MAX(MAX(T22*1.5, T22+15), IFERROR(VLOOKUP(A22,'Pricing Intelligence'!A:J,10,FALSE),0)) -> 66.474263 | V22: 125 | W22: =IFERROR(_xlfn.XLOOKUP(A22,'Sales Log'!$C$4:$C$303,'Sales Log'!$F$4:$F$303,0),0) -> 0 | X22: =IF(W22=0,0,W22-(W22*(P22+S22))-Q22-R22-N22) -> 0 | Y22: =IFERROR(IF(ISNUMBER(SEARCH("Jersey",A22)),"Jersey",IF(ISNUMBER(SEARCH("Photo",A22)),"Photo",IF(ISNUMBER(SEARCH("Baseball Bat",A22)),"Bat",IF(ISNUMBER(SEARCH("Bat",A22)),"Bat",IF(ISNUMBER(SEARCH("Baseball",A22)),"Baseball",IF(ISNUMBER(SEARCH("Football",A22)),"Football",IF(ISNUMBER(SEARCH("Mask",A22)),"Mask",IF(ISNUMBER(SEARCH("Drum",A22)),"Drum Stick",IF(ISNUMBER(SEARCH("Card",A22)),"Card",IF(ISNUMBER(SEARCH("RC",A22)),"Card","Other")))))))))),"Other") -> Jersey | Z22: Baseball | AA22: =IFERROR(TRIM(LEFT(A22,FIND(" Signed",A22)-1)),LEFT(A22,20)) -> Kyle Tucker | AB22: =IF(ISNUMBER(SEARCH("(Beckett)",A22)),"Beckett",IF(ISNUMBER(SEARCH("(JSA)",A22)),"JSA",IF(ISNUMBER(SEARCH("(PSA)",A22)),"PSA",IF(ISNUMBER(SEARCH("(ACOA)",A22)),"ACOA",IF(ISNUMBER(SEARCH("(Schwartz)",A22)),"Schwartz","Unlabeled"))))) -> JSA | AD22: 46204 | AE22: 46226 | AG22: =IF(AE22="","",IF(AF22="",TODAY()-AE22,AF22-AE22)) -> 6 | AH22: =HYPERLINK("https://www.ebay.com/sch/i.html?_nkw="&SUBSTITUTE(SUBSTITUTE(A22," ","+"),"""","")&"&LH_Sold=1&LH_Complete=1","View Sold Comps") -> View Sold Comps | AI22: =IF(OR(N22=0,W22=0),"",X22/N22) | AJ22: =IF(U22=0,"",(U22-U22*P22-Q22-R22-N22)/U22) -> 0.288 | AL22: =IF(B22="Kept for Self","—",IF(Z22="Baseball","Apr – Oct (MLB Season)",IF(Z22="Football","Aug – Feb (NFL Season)",IF(Z22="Basketball","Oct – Jun (NBA Season)",IF(OR(Z22="Movie",Z22="TV"),IF(ISNUMBER(SEARCH("Friday the 13th",A22)),"Sep – Oct (Halloween)","Year-Round"),IF(Z22="Music","Year-Round","Year-Round")))))) -> Apr – Oct (MLB Season)
A23: Steve Spurrier Signed Florida Gators 8x10 Photo Inscribed "Go Gators" (ACOA) | B23: Available | C23: 4824728 | D23: 43 | E23: =D23 -> 43 | F23: =SUMIF(C:C, C23, E:E) -> 384.34 | G23: =E23/F23 -> 0.11188011 | H23: 31 | I23: =H23*G23 -> 3.4682833 | J23: 99 | K23: =J23*G23 -> 11.076131 | L23: 38.67 | M23: =L23*G23 -> 4.3264037 | N23: =E23-I23+K23+M23 -> 54.934251 | O23: eBay | P23: =IFERROR(VLOOKUP(O23,PlatformFees,2,FALSE()),0) -> 0.136 | Q23: =IFERROR(VLOOKUP(O23,PlatformFees,3,FALSE()),0) -> 0.4 | R23: 6.5 | S23: 0 | T23: =(N23+R23+Q23)/(1-(P23+S23)) -> 71.56742 | U23: =MAX(MAX(T23*1.5, T23+15), IFERROR(VLOOKUP(A23,'Pricing Intelligence'!A:J,10,FALSE),0)) -> 107.35113 | V23: 0 | W23: =IFERROR(_xlfn.XLOOKUP(A23,'Sales Log'!$C$4:$C$303,'Sales Log'!$F$4:$F$303,0),0) -> 0 | X23: =IF(W23=0,0,W23-(W23*(P23+S23))-Q23-R23-N23) -> 0 | Y23: =IFERROR(IF(ISNUMBER(SEARCH("Jersey",A23)),"Jersey",IF(ISNUMBER(SEARCH("Photo",A23)),"Photo",IF(ISNUMBER(SEARCH("Baseball Bat",A23)),"Bat",IF(ISNUMBER(SEARCH("Bat",A23)),"Bat",IF(ISNUMBER(SEARCH("Baseball",A23)),"Baseball",IF(ISNUMBER(SEARCH("Football",A23)),"Football",IF(ISNUMBER(SEARCH("Mask",A23)),"Mask",IF(ISNUMBER(SEARCH("Drum",A23)),"Drum Stick",IF(ISNUMBER(SEARCH("Card",A23)),"Card",IF(ISNUMBER(SEARCH("RC",A23)),"Card","Other")))))))))),"Other") -> Photo | Z23: Football | AA23: =IFERROR(TRIM(LEFT(A23,FIND(" Signed",A23)-1)),LEFT(A23,20)) -> Steve Spurrier | AB23: =IF(ISNUMBER(SEARCH("(Beckett)",A23)),"Beckett",IF(ISNUMBER(SEARCH("(JSA)",A23)),"JSA",IF(ISNUMBER(SEARCH("(PSA)",A23)),"PSA",IF(ISNUMBER(SEARCH("(ACOA)",A23)),"ACOA",IF(ISNUMBER(SEARCH("(Schwartz)",A23)),"Schwartz","Unlabeled"))))) -> ACOA | AD23: 46204 | AG23: =IF(AE23="","",IF(AF23="",TODAY()-AE23,AF23-AE23)) | AH23: =HYPERLINK("https://www.ebay.com/sch/i.html?_nkw="&SUBSTITUTE(SUBSTITUTE(A23," ","+"),"""","")&"&LH_Sold=1&LH_Complete=1","View Sold Comps") -> View Sold Comps | AI23: =IF(OR(N23=0,W23=0),"",X23/N23) | AJ23: =IF(U23=0,"",(U23-U23*P23-Q23-R23-N23)/U23) -> 0.288 | AL23: =IF(B23="Kept for Self","—",IF(Z23="Baseball","Apr – Oct (MLB Season)",IF(Z23="Football","Aug – Feb (NFL Season)",IF(Z23="Basketball","Oct – Jun (NBA Season)",IF(OR(Z23="Movie",Z23="TV"),IF(ISNUMBER(SEARCH("Friday the 13th",A23)),"Sep – Oct (Halloween)","Year-Round"),IF(Z23="Music","Year-Round","Year-Round")))))) -> Aug – Feb (NFL Season)
A24: Joe Johnson Signed Jersey (Beckett) | B24: Available | C24: 4824988 | D24: 18.46 | E24: =D24 -> 18.46 | F24: =SUMIF(C:C, C24, E:E) -> 18.46 | G24: =E24/F24 -> 1 | H24: 20 | I24: =H24*G24 -> 20 | J24: 4.11 | K24: =J24*G24 -> 4.11 | L24: 1.8 | M24: =L24*G24 -> 1.8 | N24: =E24-I24+K24+M24 -> 4.37 | O24: eBay | P24: =IFERROR(VLOOKUP(O24,PlatformFees,2,FALSE()),0) -> 0.136 | Q24: =IFERROR(VLOOKUP(O24,PlatformFees,3,FALSE()),0) -> 0.4 | R24: 6.5 | S24: 0 | T24: =(N24+R24+Q24)/(1-(P24+S24)) -> 13.043981 | U24: =MAX(MAX(T24*1.5, T24+15), IFERROR(VLOOKUP(A24,'Pricing Intelligence'!A:J,10,FALSE),0)) -> 28.043981 | V24: 0 | W24: =IFERROR(_xlfn.XLOOKUP(A24,'Sales Log'!$C$4:$C$303,'Sales Log'!$F$4:$F$303,0),0) -> 0 | X24: =IF(W24=0,0,W24-(W24*(P24+S24))-Q24-R24-N24) -> 0 | Y24: =IFERROR(IF(ISNUMBER(SEARCH("Jersey",A24)),"Jersey",IF(ISNUMBER(SEARCH("Photo",A24)),"Photo",IF(ISNUMBER(SEARCH("Baseball Bat",A24)),"Bat",IF(ISNUMBER(SEARCH("Bat",A24)),"Bat",IF(ISNUMBER(SEARCH("Baseball",A24)),"Baseball",IF(ISNUMBER(SEARCH("Football",A24)),"Football",IF(ISNUMBER(SEARCH("Mask",A24)),"Mask",IF(ISNUMBER(SEARCH("Drum",A24)),"Drum Stick",IF(ISNUMBER(SEARCH("Card",A24)),"Card",IF(ISNUMBER(SEARCH("RC",A24)),"Card","Other")))))))))),"Other") -> Jersey | Z24: Basketball | AA24: =IFERROR(TRIM(LEFT(A24,FIND(" Signed",A24)-1)),LEFT(A24,20)) -> Joe Johnson | AB24: =IF(ISNUMBER(SEARCH("(Beckett)",A24)),"Beckett",IF(ISNUMBER(SEARCH("(JSA)",A24)),"JSA",IF(ISNUMBER(SEARCH("(PSA)",A24)),"PSA",IF(ISNUMBER(SEARCH("(ACOA)",A24)),"ACOA",IF(ISNUMBER(SEARCH("(Schwartz)",A24)),"Schwartz","Unlabeled"))))) -> Beckett | AD24: 46204 | AG24: =IF(AE24="","",IF(AF24="",TODAY()-AE24,AF24-AE24)) | AH24: =HYPERLINK("https://www.ebay.com/sch/i.html?_nkw="&SUBSTITUTE(SUBSTITUTE(A24," ","+"),"""","")&"&LH_Sold=1&LH_Complete=1","View Sold Comps") -> View Sold Comps | AI24: =IF(OR(N24=0,W24=0),"",X24/N24) | AJ24: =IF(U24=0,"",(U24-U24*P24-Q24-R24-N24)/U24) -> 0.46213124 | AL24: =IF(B24="Kept for Self","—",IF(Z24="Baseball","Apr – Oct (MLB Season)",IF(Z24="Football","Aug – Feb (NFL Season)",IF(Z24="Basketball","Oct – Jun (NBA Season)",IF(OR(Z24="Movie",Z24="TV"),IF(ISNUMBER(SEARCH("Friday the 13th",A24)),"Sep – Oct (Halloween)","Year-Round"),IF(Z24="Music","Year-Round","Year-Round")))))) -> Oct – Jun (NBA Season)
